<?xml version="1.0" ?>
<!-- Izzy URDF -->
<!-- written by M9 Martijn Habers 19/04/2024 -->

<robot name ="Izzy">
	<!-- Robot Link Definitions -->

	<!-- Empty base link included because KDL cannot parse a URDF which has base_link with inertia  -->
	<link name="base_link">
	</link>
	<link name="backpack">
		<inertial>
         <origin rpy="0 0 0" xyz="0.200 -0.026 0.294"/>
         <mass value="64.559"/>
         <inertia ixx="3.9893" iyy="3.7436" izz="1.5564" ixy="0.0529" ixz="-0.3975" iyz="0.0803"/>
		</inertial>
		<visual>
			<geometry>
				<mesh filename="package://march_description/meshes/march9/backpack.stl" scale="1 1 1"/>
			</geometry>
			<material name="">
				<color rgba="0.8 0.8 0.8 1.0"/>
			</material>
		</visual>
		<collision>
			<geometry>
				<mesh filename="package://march_description/meshes/march9/backpack.stl" scale="1 1 1"/>
			</geometry>
		</collision>
	</link>
	<link name="L_hip">
		<inertial>
         <origin rpy="0 0 0" xyz="0.130 0.174 0.000"/>
         <mass value="3.684"/>
         <inertia ixx="0.0146" iyy="0.0255" izz="0.0321" ixy="-0.0106" ixz="0.0000" iyz="0.0000"/>
		</inertial>
		<visual>
			<geometry>
				<mesh filename="package://march_description/meshes/march9/L_Hip.stl" scale="1 1 1"/>
			</geometry>
			<material name="">
				<color rgba="0.8 0.8 0.8 1.0"/>
			</material>
		</visual>
		<collision>
			<geometry>
				<mesh filename="package://march_description/meshes/march9/L_Hip.stl" scale="1 1 1"/>
			</geometry>
		</collision>
	</link>
	<link name="L_camera">
	</link>
	<link name="L_UL">
		<inertial>
         <origin rpy="0 0 0" xyz="0.003 -0.140 -0.243"/>
         <mass value="12.791"/>
         <inertia ixx="0.4303" iyy="0.3727" izz="0.1035" ixy="0.0057" ixz="0.0317" iyz="-0.0947"/>
		</inertial>
		<visual>
			<geometry>
				<mesh filename="package://march_description/meshes/march9/L_UpperLeg.stl" scale="1 1 1"/>
			</geometry>
			<material name="">
				<color rgba="0.8 0.8 0.8 1.0"/>
			</material>
		</visual>
		<collision>
			<geometry>
				<mesh filename="package://march_description/meshes/march9/L_UpperLeg.stl"  scale="1 1 1"/>
			</geometry>
		</collision>
	</link>
	<link name="L_LL">
		<inertial>
         <origin rpy="0 0 0" xyz="-0.029 -0.043 -0.278"/>
         <mass value="5.796"/>
         <inertia ixx="0.1082" iyy="0.1066" izz="0.0294" ixy="0.0054" ixz="-0.0138" iyz="0.0050"/>
		</inertial>
		<visual>
			<geometry>
				<mesh filename="package://march_description/meshes/march9/L_LowerLeg.stl" scale="1 1 1"/>
			</geometry>
			<material name="">
				<color rgba="0.8 0.8 0.8 1.0"/>
			</material>
		</visual>
		<collision>
			<geometry>
				<mesh filename="package://march_description/meshes/march9/L_LowerLeg.stl" scale="1 1 1"/>
			</geometry>
		</collision>
	</link>
   	<link name="L_ankle">
      <inertial>
         <origin rpy="0 0 0" xyz="0.070 0.043 -0.002"/>
         <mass value="0.683"/>
         <inertia ixx="0.0011" iyy="0.0043" izz="0.0047" ixy="-0.0010" ixz="-0.0006" iyz="-0.0003"/>
      </inertial>
      <visual>
         <geometry>
            <mesh filename="package://march_description/meshes/march9/L_Ankle.stl" scale="1 1 1"/>
         </geometry>
         <material name="">
            <color rgba="0.8 0.8 0.8 1.0"/>
         </material>
      </visual>
      <collision>
         <geometry>
            <mesh filename="package://march_description/meshes/march9/L_Ankle.stl" scale="1 1 1"/>
         </geometry>
      </collision>
	</link>
	<link name="L_foot">
		<inertial>
         <origin rpy="0 0 0" xyz="0.117 -0.002 -0.031"/>
         <mass value="2.128"/>
         <inertia ixx="0.0042" iyy="0.0220" izz="0.0217" ixy="0.0003" ixz="0.0008" iyz="0.0001"/>
		</inertial>
		<visual>
			<geometry>
				<mesh filename="package://march_description/meshes/march9/L_Sole.stl" scale="1 1 1"/>
			</geometry>
			<material name="">
				<color rgba="0.8 0.8 0.8 1.0"/>
			</material>
		</visual>
		<collision>
			<geometry>
				<mesh filename="package://march_description/meshes/march9/L_Sole.stl" scale="1 1 1"/>
			</geometry>
		</collision>
	</link>
	<link name="L_toe">
	</link>
	<link name="L_heel">
	</link>
	<link name="L_sole">
	</link>
	<link name="R_hip">
      <inertial>
         <origin rpy="0 0 0" xyz="0.130 -0.174 0.000"/>
         <mass value="3.684"/>
         <inertia ixx="0.0146" iyy="0.0255" izz="0.0321" ixy="0.0106" ixz="0.0000" iyz="0.0000"/>
      </inertial>
		<visual>
			<geometry>
				<mesh filename="package://march_description/meshes/march9/L_Hip.stl" scale="1 -1 1"/>
			</geometry>
			<material name="">
				<color rgba="0.8 0.8 0.8 1.0"/>
			</material>
		</visual>
		<collision>
			<geometry>
				<mesh filename="package://march_description/meshes/march9/L_Hip.stl" scale="1 -1 1"/>
			</geometry>
		</collision>
	</link>
	<link name="R_camera">
	</link>
	<link name="R_UL">
		<inertial>
         <origin rpy="0 0 0" xyz="0.003 0.140 -0.243"/>
         <mass value="12.791"/>
         <inertia ixx="0.4303" iyy="0.3727" izz="0.1035" ixy="-0.0057" ixz="0.0317" iyz="0.0947"/>
		</inertial>
		<visual>
			<geometry>
				<mesh filename="package://march_description/meshes/march9/L_UpperLeg.stl" scale="1 -1 1"/>
			</geometry>
			<material name="">
				<color rgba="0.8 0.8 0.8 1.0"/>
			</material>
		</visual>
		<collision>
			<geometry>
				<mesh filename="package://march_description/meshes/march9/L_UpperLeg.stl" scale="1 -1 1"/>
			</geometry>
		</collision>
	</link>
	<link name="R_LL">
		<inertial>
         <origin rpy="0 0 0" xyz="-0.029 0.043 -0.278"/>
         <mass value="5.796"/>
         <inertia ixx="0.1082" iyy="0.1066" izz="0.0294" ixy="-0.0054" ixz="-0.0138" iyz="-0.0050"/>
		</inertial>
		<visual>
			<geometry>
				<mesh filename="package://march_description/meshes/march9/L_LowerLeg.stl" scale="1 -1 1"/>
			</geometry>
			<material name="">
				<color rgba="0.8 0.8 0.8 1.0"/>
			</material>
		</visual>
		<collision>
			<geometry>
				<mesh filename="package://march_description/meshes/march9/L_LowerLeg.stl" scale="1 -1 1"/>
			</geometry>
		</collision>
	</link>
   	<link name="R_ankle">
      <inertial>
         <origin rpy="0 0 0" xyz="0.070 -0.043 -0.002"/>
         <mass value="0.683"/>
         <inertia ixx="0.0011" iyy="0.0043" izz="0.0047" ixy="0.0010" ixz="-0.0006" iyz="0.0003"/>
      </inertial>
      <visual>
         <geometry>
            <mesh filename="package://march_description/meshes/march9/L_Ankle.stl" scale="1 -1 1"/>
         </geometry>
         <material name="">
            <color rgba="0.8 0.8 0.8 1.0"/>
         </material>
      </visual>
      <collision>
         <geometry>
            <mesh filename="package://march_description/meshes/march9/L_Ankle.stl" scale="1 -1 1"/>
         </geometry>
      </collision>
   	</link>
	<link name="R_foot">
		<inertial>
         <origin rpy="0 0 0" xyz="0.117 0.002 -0.031"/>
         <mass value="2.128"/>
         <inertia ixx="0.0042" iyy="0.0220" izz="0.0217" ixy="-0.0003" ixz="0.0008" iyz="-0.0001"/>
		</inertial>
		<visual>
			<geometry>
				<mesh filename="package://march_description/meshes/march9/L_Sole.stl" scale="1 -1 1"/>
			</geometry>
			<material name="">
				<color rgba="0.8 0.8 0.8 1.0"/>
			</material>
		</visual>
		<collision>
			<geometry>
				<mesh filename="package://march_description/meshes/march9/L_Sole.stl" scale="1 -1 1"/>
			</geometry>
		</collision>
	</link>
	<link name="R_toe">
	</link>
	<link name="R_heel">
	</link>
	<link name="R_sole">
	</link>

	<!-- Robot Joint Definitions -->

	<joint name="base_link_to_backpack" type="fixed">
		<origin rpy="0 0 0" xyz="0 0 0"/>
		<parent link="base_link"/>
		<child link="backpack"/>
	</joint>
	<joint name="left_hip_aa" type="revolute">
		<origin rpy="0 0 0" xyz="0.021 0.081 0.028"/>
		<axis xyz="-1 0 0"/>
		<parent link="backpack"/>
		<child link="L_hip"/>
		<limit effort="280" lower="-0.349066" upper="0.174533" velocity="2.6"/>
	</joint>
	<joint name="left_hip_fe" type="revolute">
		<origin rpy="0 0 0.0" xyz="0.169 0.176 0.000"/>
		<axis xyz="0 -1 0"/>
		<parent link="L_hip"/>
		<child link="L_UL"/>
		<limit effort="250" lower="-0.349066" upper="2.00713" velocity="3.94"/>
	</joint>
	<joint name="L_UL_to_L_camera" type="fixed">
		<origin rpy="0 0.6970 0" xyz="0.0801 0.0019 -0.1424"/>
		<parent link="L_UL"/>
		<child link="L_camera"/>
	</joint>
	<joint name="left_knee" type="revolute">
		<origin rpy="0 0 0" xyz="0.000 -0.077 -0.463"/>
		<axis xyz="0 1 0"/>
		<parent link="L_UL"/>
		<child link="L_LL"/>
		<limit effort="250" lower="0" upper="2.18166" velocity="3.94"/>
	</joint>
	<joint name="left_ankle_dpf" type="revolute">
		<origin rpy="0 0 0" xyz="0.000 -0.016 -0.469"/>
		<axis xyz="0 -1 0"/>
		<parent link="L_LL"/>
		<child link="L_ankle"/>
		<limit effort="179" lower="-0.488692" upper="0.349066" velocity="4.1"/>
	</joint>
   	<joint name="left_ankle_ie" type="revolute">
		<origin rpy="0 0 0" xyz="-0.093 -0.061 -0.025"/>
		<axis xyz="1 0 0"/>
		<parent link="L_ankle"/>
		<child link="L_foot"/>
		<limit effort="179" lower="-0.157079633" upper="0.157079633" velocity="4.1"/>
	</joint>
	<joint name="L_foot_to_L_heel" type="fixed">
		<origin rpy="0 0 0" xyz="-0.015 0.0 -0.08"/>
		<parent link="L_foot"/>
		<child link="L_heel"/>
	</joint>
	<joint name="L_foot_to_L_sole" type="fixed">
		<origin rpy="0 0 0" xyz="0.151 0.0 -0.080"/>
		<parent link="L_foot"/>
		<child link="L_sole"/>
	</joint>
	<joint name="L_foot_to_L_toe" type="fixed">
		<origin rpy="0 0 0" xyz="0.317 0.0 -0.080"/>
		<parent link="L_foot"/>
		<child link="L_toe"/>
	</joint>
	<joint name="right_hip_aa" type="revolute">
		<origin rpy="0 0 0" xyz="0.021 -0.081 0.028"/>
		<axis xyz="1 0 0"/>
		<parent link="backpack"/>
		<child link="R_hip"/>
		<limit effort="280" lower="-0.349066" upper="0.174533" velocity="2.6"/>
	</joint>
	<joint name="right_hip_fe" type="revolute">
		<origin rpy="0 0 0.0" xyz="0.169 -0.176 0.000"/>
		<axis xyz="0 -1 0"/>
		<parent link="R_hip"/>
		<child link="R_UL"/>
		<limit effort="250" lower="-0.349066" upper="2.00713" velocity="3.94"/>
	</joint>
	<joint name="R_UL_to_R_camera" type="fixed">
		<origin rpy="0 0.6970 0" xyz="0.0801 -0.0019 -0.1424"/>
		<parent link="R_UL"/>
		<child link="R_camera"/>
	</joint>
	<joint name="right_knee" type="revolute">
		<origin rpy="0 0 0" xyz="0.000 0.077 -0.463"/>
		<axis xyz="0 1 0"/>
		<parent link="R_UL"/>
		<child link="R_LL"/>
		<limit effort="250" lower="0" upper="2.18166" velocity="3.94"/>
	</joint>
	<joint name="right_ankle_dpf" type="revolute">
		<origin rpy="0 0 0" xyz="0.000 0.016 -0.469"/>
		<axis xyz="0 -1 0"/>
		<parent link="R_LL"/>
		<child link="R_ankle"/>
		<limit effort="179" lower="-0.488692" upper="0.349066" velocity="4.1"/>
	</joint> 
   	<joint name="right_ankle_ie" type="revolute">
		<origin rpy="0 0 0" xyz="-0.093 0.061 -0.025"/>
		<axis xyz="-1 0 0"/>
		<parent link="R_ankle"/>
		<child link="R_foot"/>
		<limit effort="179" lower="-0.157079633" upper="0.157079633" velocity="4.1"/>
	</joint>
	<joint name="R_foot_to_R_heel" type="fixed">
		<origin rpy="0 0 0" xyz="-0.015 0.0 -0.08"/>
		<parent link="R_foot"/>
		<child link="R_heel"/>
	</joint>
	<joint name="R_foot_to_R_sole" type="fixed">
		<origin rpy="0 0 0" xyz="0.151 0.0 -0.080"/>
		<parent link="R_foot"/>
		<child link="R_sole"/>
	</joint>
	<joint name="R_foot_to_R_toe" type="fixed">
		<origin rpy="0 0 0" xyz="0.317 0.0 -0.080"/>
		<parent link="R_foot"/>
		<child link="R_toe"/>
	</joint>
	

	<!-- Robot Transmission Definitions -->

	<transmission name="L_HAATransmission">
            <joint name="left_hip_aa"/>
            <actuator>
                    <mechanicalReduction>25</mechanicalReduction>
                    <motorInertia>5.4</motorInertia>
            </actuator>
  	</transmission>
  	<transmission name="L_HFETransmission">
            <joint name="left_hip_fe"/>
            <actuator>
                    <mechanicalReduction>16</mechanicalReduction>
                    <motorInertia>6.0</motorInertia>
            </actuator>
  	</transmission>
  	<transmission name="L_KFETransmission">
            <joint name="left_knee"/>
            <actuator>
                    <mechanicalReduction>16</mechanicalReduction>
                    <motorInertia>6.0</motorInertia>
            </actuator>
  	</transmission>
  	<transmission name="L_ADPFTransmission">
            <joint name="left_ankle_dpf"/>
            <actuator>
                    <mechanicalReduction>50</mechanicalReduction>
                    <motorInertia>2.2</motorInertia>
            </actuator>
  	</transmission>
  	<transmission name="R_HAATransmission">
            <joint name="right_hip_aa"/>
            <actuator>
                    <mechanicalReduction>25</mechanicalReduction>
                    <motorInertia>5.4</motorInertia>
            </actuator>
  	</transmission>
  	<transmission name="R_HFETransmission">
            <joint name="right_hip_fe"/>
            <actuator>
                    <mechanicalReduction>16</mechanicalReduction>
                    <motorInertia>6.0</motorInertia>
            </actuator>
  	</transmission>
  	<transmission name="R_KFETransmission">
            <joint name="right_knee"/>
            <actuator>
                    <mechanicalReduction>16</mechanicalReduction>
                    <motorInertia>6.0</motorInertia>
            </actuator>
  	</transmission>
  	<transmission name="R_ADPFTransmission">
            <joint name="right_ankle_dpf"/>
            <actuator>
                    <mechanicalReduction>50</mechanicalReduction>
                    <motorInertia>2.2</motorInertia>
            </actuator>
  	</transmission>
</robot>