<?xml version="1.0" encoding="utf-8"?>
<!-- This URDF was automatically created by SolidWorks to URDF Exporter! Originally created by Stephen Brawner (brawner@gmail.com) 
     Commit Version: 1.6.0-1-g15f4949  Build Version: 1.6.7594.29634
     For more information, please see http://wiki.ros.org/sw_urdf_exporter -->
<robot name="march7_description_rl">
  <link name="base_link">
    <inertial>
      <origin xyz="-5.7119E-16 0.039393 0.19048" rpy="0 0 0" />
      <mass value="0.61034" />
      <inertia ixx="0.0052863" ixy="1.2971E-18" ixz="6.4773E-18" iyy="0.0045574" iyz="-0.0011083" izz="0.0009832" />
    </inertial>
    <visual>
      <origin xyz="0 0 0" rpy="0 0 0" />
      <geometry>
        <mesh filename="package://march7_description_rl/meshes/base_link.STL" />
      </geometry>
      <material name="">
        <color rgba="0.79216 0.81961 0.93333 1" />
      </material>
    </visual>
    <collision>
      <origin xyz="0 0 0" rpy="0 0 0" />
      <geometry>
        <mesh filename="package://march7_description_rl/meshes/base_link.STL" />
      </geometry>
    </collision>
  </link>
  <link name="right_lower_leg">
    <inertial>
      <origin xyz="-7.7065E-16 0.205 7.2164E-16" rpy="0 0 0" />
      <mass value="1.1232" />
      <inertia ixx="0.019156" ixy="1.8575E-19" ixz="-1.3892E-20" iyy="0.00046288" iyz="-2.647E-20" izz="0.019161" />
    </inertial>
    <visual>
      <origin xyz="0 0 0" rpy="0 0 0" />
      <geometry>
        <mesh filename="package://march7_description_rl/meshes/right_lower_leg.STL" />
      </geometry>
      <material name="">
        <color rgba="0.79216 0.81961 0.93333 1" />
      </material>
    </visual>
    <collision>
      <origin xyz="0 0 0" rpy="0 0 0" />
      <geometry>
        <mesh filename="package://march7_description_rl/meshes/right_lower_leg.STL" />
      </geometry>
    </collision>
  </link>
  <joint name="right_ankle" type="revolute">
    <origin xyz="0 -0.258 0.108" rpy="1.5708 0 0" />
    <parent link="base_link" />
    <child link="right_lower_leg" />
    <axis xyz="-1 0 0" />
    <limit lower="-1.2217" upper="0.087266" effort="0" velocity="0" />
  </joint>
  <link name="right_upper_leg">
    <inertial>
      <origin xyz="-7.6703E-16 0.205 5.5511E-17" rpy="0 0 0" />
      <mass value="1.1232" />
      <inertia ixx="0.019156" ixy="-7.4621E-20" ixz="8.6957E-21" iyy="0.00046288" iyz="7.9409E-20" izz="0.019161" />
    </inertial>
    <visual>
      <origin xyz="0 0 0" rpy="0 0 0" />
      <geometry>
        <mesh filename="package://march7_description_rl/meshes/right_upper_leg.STL" />
      </geometry>
      <material name="">
        <color rgba="0.79216 0.81961 0.93333 1" />
      </material>
    </visual>
    <collision>
      <origin xyz="0 0 0" rpy="0 0 0" />
      <geometry>
        <mesh filename="package://march7_description_rl/meshes/right_upper_leg.STL" />
      </geometry>
    </collision>
  </link>
  <joint name="right_knee" type="revolute">
    <origin xyz="0 0.41 0" rpy="0 0 0" />
    <parent link="right_lower_leg" />
    <child link="right_upper_leg" />
    <axis xyz="1 0 0" />
    <limit lower="0" upper="2.3562" effort="0" velocity="0" />
  </joint>
  <link name="right_hip">
    <inertial>
      <origin xyz="-0.037749 -3.3307E-16 -0.1395" rpy="0 0 0" />
      <mass value="0.98442" />
      <inertia ixx="0.0055337" ixy="-6.9259E-18" ixz="-0.0022482" iyy="0.0084589" iyz="-1.2843E-17" izz="0.0033252" />
    </inertial>
    <visual>
      <origin xyz="0 0 0" rpy="0 0 0" />
      <geometry>
        <mesh filename="package://march7_description_rl/meshes/right_hip.STL" />
      </geometry>
      <material name="">
        <color rgba="0.79216 0.81961 0.93333 1" />
      </material>
    </visual>
    <collision>
      <origin xyz="0 0 0" rpy="0 0 0" />
      <geometry>
        <mesh filename="package://march7_description_rl/meshes/right_hip.STL" />
      </geometry>
    </collision>
  </link>
  <joint name="right_hip_fe" type="revolute">
    <origin xyz="0 0.41 0" rpy="-3.1416 0 0" />
    <parent link="right_upper_leg" />
    <child link="right_hip" />
    <axis xyz="-1 0 0" />
    <limit lower="-0.2618" upper="2.0071" effort="0" velocity="0" />
  </joint>
  <link name="hip">
    <inertial>
      <origin xyz="-0.0725 0.010671 0.025" rpy="0 0 0" />
      <mass value="0.58567" />
      <inertia ixx="0.00048472" ixy="1.8581E-19" ixz="4.5352E-21" iyy="0.0014656" iyz="-1.0201E-20" izz="0.0017063" />
    </inertial>
    <visual>
      <origin xyz="0 0 0" rpy="0 0 0" />
      <geometry>
        <mesh filename="package://march7_description_rl/meshes/hip.STL" />
      </geometry>
      <material name="">
        <color rgba="0.79216 0.81961 0.93333 1" />
      </material>
    </visual>
    <collision>
      <origin xyz="0 0 0" rpy="0 0 0" />
      <geometry>
        <mesh filename="package://march7_description_rl/meshes/hip.STL" />
      </geometry>
    </collision>
  </link>
  <joint name="right_hip_aa" type="revolute">
    <origin xyz="-0.1545 0 -0.175" rpy="3.1416 0 0" />
    <parent link="right_hip" />
    <child link="hip" />
    <axis xyz="0 0 -1" />
    <limit lower="-0.34907" upper="0.5236" effort="0" velocity="0" />
  </joint>
  <link name="left_hip">
    <inertial>
      <origin xyz="0.11675 -1.4433E-15 0.035499" rpy="0 0 0" />
      <mass value="0.98442" />
      <inertia ixx="0.0055337" ixy="3.0788E-18" ixz="-0.0022482" iyy="0.0084589" iyz="8.5063E-18" izz="0.0033252" />
    </inertial>
    <visual>
      <origin xyz="0 0 0" rpy="0 0 0" />
      <geometry>
        <mesh filename="package://march7_description_rl/meshes/left_hip.STL" />
      </geometry>
      <material name="">
        <color rgba="0.79216 0.81961 0.93333 1" />
      </material>
    </visual>
    <collision>
      <origin xyz="0 0 0" rpy="0 0 0" />
      <geometry>
        <mesh filename="package://march7_description_rl/meshes/left_hip.STL" />
      </geometry>
    </collision>
  </link>
  <joint name="left_hip_aa" type="revolute">
    <origin xyz="-0.145 0 0" rpy="3.1416 0 3.1416" />
    <parent link="hip" />
    <child link="left_hip" />
    <axis xyz="0 0 1" />
    <limit lower="-0.34907" upper="0.5236" effort="0" velocity="0" />
  </joint>
  <link name="left_upper_leg">
    <inertial>
      <origin xyz="-0.025 -0.205 2.8866E-15" rpy="0 0 0" />
      <mass value="1.1232" />
      <inertia ixx="0.019156" ixy="3.7863E-19" ixz="-8.4131E-20" iyy="0.00046288" iyz="2.227E-19" izz="0.019161" />
    </inertial>
    <visual>
      <origin xyz="0 0 0" rpy="0 0 0" />
      <geometry>
        <mesh filename="package://march7_description_rl/meshes/left_upper_leg.STL" />
      </geometry>
      <material name="">
        <color rgba="0.79216 0.81961 0.93333 1" />
      </material>
    </visual>
    <collision>
      <origin xyz="0 0 0" rpy="0 0 0" />
      <geometry>
        <mesh filename="package://march7_description_rl/meshes/left_upper_leg.STL" />
      </geometry>
    </collision>
  </link>
  <joint name="left_hip_fe" type="revolute">
    <origin xyz="0.1295 0 0.175" rpy="3.1416 0 3.1416" />
    <parent link="left_hip" />
    <child link="left_upper_leg" />
    <axis xyz="1 0 0" />
    <limit lower="-0.2618" upper="2.0071" effort="0" velocity="0" />
  </joint>
  <link name="left_lower_leg">
    <inertial>
      <origin xyz="-0.025 -0.205 2.276E-15" rpy="0 0 0" />
      <mass value="1.1232" />
      <inertia ixx="0.019156" ixy="4.245E-19" ixz="-8.3708E-20" iyy="0.00046288" iyz="-3.1764E-19" izz="0.019161" />
    </inertial>
    <visual>
      <origin xyz="0 0 0" rpy="0 0 0" />
      <geometry>
        <mesh filename="package://march7_description_rl/meshes/left_lower_leg.STL" />
      </geometry>
      <material name="">
        <color rgba="0.79216 0.81961 0.93333 1" />
      </material>
    </visual>
    <collision>
      <origin xyz="0 0 0" rpy="0 0 0" />
      <geometry>
        <mesh filename="package://march7_description_rl/meshes/left_lower_leg.STL" />
      </geometry>
    </collision>
  </link>
  <joint name="left_knee" type="revolute">
    <origin xyz="0 -0.41 0" rpy="0 0 0" />
    <parent link="left_upper_leg" />
    <child link="left_lower_leg" />
    <axis xyz="-1 0 0" />
    <limit lower="0" upper="2.3562" effort="0" velocity="0" />
  </joint>
  <link name="left_foot">
    <inertial>
      <origin xyz="0.025 -0.068607 0.067523" rpy="0 0 0" />
      <mass value="0.61034" />
      <inertia ixx="0.0052863" ixy="-1.3639E-20" ixz="1.6129E-20" iyy="0.0045574" iyz="0.0011083" izz="0.0009832" />
    </inertial>
    <visual>
      <origin xyz="0 0 0" rpy="0 0 0" />
      <geometry>
        <mesh filename="package://march7_description_rl/meshes/left_foot.STL" />
      </geometry>
      <material name="">
        <color rgba="0.79216 0.81961 0.93333 1" />
      </material>
    </visual>
    <collision>
      <origin xyz="0 0 0" rpy="0 0 0" />
      <geometry>
        <mesh filename="package://march7_description_rl/meshes/left_foot.STL" />
      </geometry>
    </collision>
  </link>
  <joint name="left_ankle" type="revolute">
    <origin xyz="0 -0.41 0" rpy="3.1416 0 3.1416" />
    <parent link="left_lower_leg" />
    <child link="left_foot" />
    <axis xyz="-1 0 0" />
    <limit lower="-1.2217" upper="0.087266" effort="0" velocity="0" />
  </joint>
</robot>