<?xml version="1.0" encoding="utf-8"?>
<!-- This URDF was automatically created by SolidWorks to URDF Exporter! Originally created by Stephen Brawner (brawner@gmail.com) 
     Commit Version: 1.6.0-1-g15f4949  Build Version: 1.6.7594.29634
     For more information, please see http://wiki.ros.org/sw_urdf_exporter -->
<robot name="march7_description_lr">
  <link name="base_link">
    <inertial>
      <origin xyz="1.4875E-16 0.039393 0.19048" rpy="0 0 0" />
      <mass value="0.61034" />
      <inertia ixx="0.0052863" ixy="1.2997E-19" ixz="2.5843E-19" iyy="0.0045574" iyz="-0.0011083" izz="0.0009832" />
    </inertial>
    <visual>
      <origin xyz="0 0 0" rpy="0 0 0" />
      <geometry>
        <mesh filename="package://march7_description_lr/meshes/base_link.STL" />
      </geometry>
      <material name="">
        <color rgba="0.79216 0.81961 0.93333 1" />
      </material>
    </visual>
    <collision>
      <origin xyz="0 0 0" rpy="0 0 0" />
      <geometry>
        <mesh filename="package://march7_description_lr/meshes/base_link.STL" />
      </geometry>
    </collision>
  </link>
  <link name="left_lower_leg">
    <inertial>
      <origin xyz="6.4248E-15 0.205 -1.4988E-15" rpy="0 0 0" />
      <mass value="1.1232" />
      <inertia ixx="0.019156" ixy="1.7871E-19" ixz="-1.3892E-20" iyy="0.00046288" iyz="-1.0588E-19" izz="0.019161" />
    </inertial>
    <visual>
      <origin xyz="0 0 0" rpy="0 0 0" />
      <geometry>
        <mesh filename="package://march7_description_lr/meshes/left_lower_leg.STL" />
      </geometry>
      <material name="">
        <color rgba="0.79216 0.81961 0.93333 1" />
      </material>
    </visual>
    <collision>
      <origin xyz="0 0 0" rpy="0 0 0" />
      <geometry>
        <mesh filename="package://march7_description_lr/meshes/left_lower_leg.STL" />
      </geometry>
    </collision>
  </link>
  <joint name="left_ankle" type="revolute">
    <origin xyz="0 -0.258 0.108" rpy="1.5708 0 0" />
    <parent link="base_link" />
    <child link="left_lower_leg" />
    <axis xyz="-1 0 0" />
    <limit lower="-1.2217" upper="0.174533" effort="0" velocity="0" />
  </joint>
  <link name="left_upper_leg">
    <inertial>
      <origin xyz="-2.1222E-16 0.205 -4.5519E-15" rpy="0 0 0" />
      <mass value="1.1232" />
      <inertia ixx="0.019156" ixy="3.1159E-19" ixz="-3.6451E-20" iyy="0.00046288" iyz="-3.1764E-19" izz="0.019161" />
    </inertial>
    <visual>
      <origin xyz="0 0 0" rpy="0 0 0" />
      <geometry>
        <mesh filename="package://march7_description_lr/meshes/left_upper_leg.STL" />
      </geometry>
      <material name="">
        <color rgba="0.79216 0.81961 0.93333 1" />
      </material>
    </visual>
    <collision>
      <origin xyz="0 0 0" rpy="0 0 0" />
      <geometry>
        <mesh filename="package://march7_description_lr/meshes/left_upper_leg.STL" />
      </geometry>
    </collision>
  </link>
  <joint name="left_knee" type="revolute">
    <origin xyz="0 0.41 0" rpy="0 0 0" />
    <parent link="left_lower_leg" />
    <child link="left_upper_leg" />
    <axis xyz="1 0 0" />
    <limit lower="0" upper="2.3562" effort="0" velocity="0" />
  </joint>
  <link name="left_hip">
    <inertial>
      <origin xyz="-0.037749 -6.6613E-16 -0.1395" rpy="0 0 0" />
      <mass value="0.98442" />
      <inertia ixx="0.0055337" ixy="4.5142E-18" ixz="-0.0022482" iyy="0.0084589" iyz="9.6495E-18" izz="0.0033252" />
    </inertial>
    <visual>
      <origin xyz="0 0 0" rpy="0 0 0" />
      <geometry>
        <mesh filename="package://march7_description_lr/meshes/left_hip.STL" />
      </geometry>
      <material name="">
        <color rgba="0.79216 0.81961 0.93333 1" />
      </material>
    </visual>
    <collision>
      <origin xyz="0 0 0" rpy="0 0 0" />
      <geometry>
        <mesh filename="package://march7_description_lr/meshes/left_hip.STL" />
      </geometry>
    </collision>
  </link>
  <joint name="left_hip_fe" type="revolute">
    <origin xyz="0 0.41 0" rpy="3.1416 0 3.1416" />
    <parent link="left_upper_leg" />
    <child link="left_hip" />
    <axis xyz="1 0 0" />
    <limit lower="-0.2618" upper="2.0071" effort="0" velocity="0" />
  </joint>
  <link name="hip">
    <inertial>
      <origin xyz="0.0725 0.010671 0.025" rpy="0 0 0" />
      <mass value="0.58567" />
      <inertia ixx="0.00048472" ixy="-3.5847E-20" ixz="-1.1997E-22" iyy="0.0014656" iyz="1.6217E-22" izz="0.0017063" />
    </inertial>
    <visual>
      <origin xyz="0 0 0" rpy="0 0 0" />
      <geometry>
        <mesh filename="package://march7_description_lr/meshes/hip.STL" />
      </geometry>
      <material name="">
        <color rgba="0.79216 0.81961 0.93333 1" />
      </material>
    </visual>
    <collision>
      <origin xyz="0 0 0" rpy="0 0 0" />
      <geometry>
        <mesh filename="package://march7_description_lr/meshes/hip.STL" />
      </geometry>
    </collision>
  </link>
  <joint name="left_hip_aa" type="revolute">
    <origin xyz="-0.1545 0 -0.175" rpy="3.1416 0 3.1416" />
    <parent link="left_hip" />
    <child link="hip" />
    <axis xyz="0 0 1" />
    <limit lower="-0.34907" upper="0.5236" effort="0" velocity="0" />
  </joint>
  <link name="right_hip">
    <inertial>
      <origin xyz="0.11675 1.9984E-15 0.035499" rpy="0 0 0" />
      <mass value="0.98442" />
      <inertia ixx="0.0055337" ixy="-6.8866E-18" ixz="-0.0022482" iyy="0.0084589" iyz="-1.285E-17" izz="0.0033252" />
    </inertial>
    <visual>
      <origin xyz="0 0 0" rpy="0 0 0" />
      <geometry>
        <mesh filename="package://march7_description_lr/meshes/right_hip.STL" />
      </geometry>
      <material name="">
        <color rgba="0.79216 0.81961 0.93333 1" />
      </material>
    </visual>
    <collision>
      <origin xyz="0 0 0" rpy="0 0 0" />
      <geometry>
        <mesh filename="package://march7_description_lr/meshes/right_hip.STL" />
      </geometry>
    </collision>
  </link>
  <joint name="right_hip_aa" type="revolute">
    <origin xyz="0.145 0 0" rpy="-3.1416 0 0" />
    <parent link="hip" />
    <child link="right_hip" />
    <axis xyz="0 0 -1" />
    <limit lower="-0.34907" upper="0.5236" effort="0" velocity="0" />
  </joint>
  <link name="right_upper_leg">
    <inertial>
      <origin xyz="0.025 -0.205 0" rpy="0 0 0" />
      <mass value="1.1232" />
      <inertia ixx="0.019156" ixy="5.1688E-19" ixz="-9.4983E-20" iyy="0.00046288" iyz="-2.9117E-19" izz="0.019161" />
    </inertial>
    <visual>
      <origin xyz="0 0 0" rpy="0 0 0" />
      <geometry>
        <mesh filename="package://march7_description_lr/meshes/right_upper_leg.STL" />
      </geometry>
      <material name="">
        <color rgba="0.79216 0.81961 0.93333 1" />
      </material>
    </visual>
    <collision>
      <origin xyz="0 0 0" rpy="0 0 0" />
      <geometry>
        <mesh filename="package://march7_description_lr/meshes/right_upper_leg.STL" />
      </geometry>
    </collision>
  </link>
  <joint name="right_hip_fe" type="revolute">
    <origin xyz="0.1295 0 0.175" rpy="3.1416 0 0" />
    <parent link="right_hip" />
    <child link="right_upper_leg" />
    <axis xyz="1 0 0" />
    <limit lower="-0.2618" upper="2.0071" effort="0" velocity="0" />
  </joint>
  <link name="right_lower_leg">
    <inertial>
      <origin xyz="0.025 -0.205 5.5511E-17" rpy="0 0 0" />
      <mass value="1.1232" />
      <inertia ixx="0.019156" ixy="3.2727E-19" ixz="-9.2783E-20" iyy="0.00046288" iyz="1.3235E-19" izz="0.019161" />
    </inertial>
    <visual>
      <origin xyz="0 0 0" rpy="0 0 0" />
      <geometry>
        <mesh filename="package://march7_description_lr/meshes/right_lower_leg.STL" />
      </geometry>
      <material name="">
        <color rgba="0.79216 0.81961 0.93333 1" />
      </material>
    </visual>
    <collision>
      <origin xyz="0 0 0" rpy="0 0 0" />
      <geometry>
        <mesh filename="package://march7_description_lr/meshes/right_lower_leg.STL" />
      </geometry>
    </collision>
  </link>
  <joint name="right_knee" type="revolute">
    <origin xyz="0 -0.41 0" rpy="0 0 0" />
    <parent link="right_upper_leg" />
    <child link="right_lower_leg" />
    <axis xyz="-1 0 0" />
    <limit lower="0" upper="2.3562" effort="0" velocity="0" />
  </joint>
  <link name="right_foot">
    <inertial>
      <origin xyz="-0.025 -0.068607 0.067523" rpy="0 0 0" />
      <mass value="0.61034" />
      <inertia ixx="0.0052863" ixy="-1.4086E-18" ixz="6.2808E-18" iyy="0.0045574" iyz="0.0011083" izz="0.0009832" />
    </inertial>
    <visual>
      <origin xyz="0 0 0" rpy="0 0 0" />
      <geometry>
        <mesh filename="package://march7_description_lr/meshes/right_foot.STL" />
      </geometry>
      <material name="">
        <color rgba="0.79216 0.81961 0.93333 1" />
      </material>
    </visual>
    <collision>
      <origin xyz="0 0 0" rpy="0 0 0" />
      <geometry>
        <mesh filename="package://march7_description_lr/meshes/right_foot.STL" />
      </geometry>
    </collision>
  </link>
  <joint name="right_ankle" type="revolute">
    <origin xyz="0 -0.41 0" rpy="3.1416 0 3.1416" />
    <parent link="right_lower_leg" />
    <child link="right_foot" />
    <axis xyz="-1 0 0" />
    <limit lower="-1.2217" upper="0.174533" effort="0" velocity="0" />
  </joint>
</robot>