<?xml version="1.0" encoding="utf-8"?>
<!-- This URDF was automatically created by SolidWorks to URDF Exporter! Originally created by Stephen Brawner (brawner@gmail.com) 
     Commit Version: 1.6.0-1-g15f4949  Build Version: 1.6.7594.29634
     For more information, please see http://wiki.ros.org/sw_urdf_exporter -->
<robot
  name="march7_description_lr">
  <link
    name="base_link">
    <inertial>
      <origin
        xyz="2.3365E-17 -6.9028E-18 0.1"
        rpy="0 0 0" />
      <mass
        value="0.5" />
      <inertia
        ixx="0.0017708"
        ixy="8.4929E-21"
        ixz="-2.9387E-36"
        iyy="0.0017708"
        iyz="0"
        izz="0.00020833" />
    </inertial>
    <visual>
      <origin
        xyz="0 0 0"
        rpy="0 0 0" />
      <geometry>
        <mesh
          filename="package://march7_description_lr/meshes/base_link.STL" />
      </geometry>
      <material
        name="">
        <color
          rgba="0.79216 0.81961 0.93333 1" />
      </material>
    </visual>
    <collision>
      <origin
        xyz="0 0 0"
        rpy="0 0 0" />
      <geometry>
        <mesh
          filename="package://march7_description_lr/meshes/base_link.STL" />
      </geometry>
    </collision>
  </link>
  <link
    name="left_lower_leg">
    <inertial>
      <origin
        xyz="-0.025 0.14577 0.025"
        rpy="0 0 0" />
      <mass
        value="0.72546" />
      <inertia
        ixx="0.0053829"
        ixy="-2.0262E-20"
        ixz="-1.2881E-20"
        iyy="0.00030643"
        iyz="-1.4006E-19"
        izz="0.0053787" />
    </inertial>
    <visual>
      <origin
        xyz="0 0 0"
        rpy="0 0 0" />
      <geometry>
        <mesh
          filename="package://march7_description_lr/meshes/left_lower_leg.STL" />
      </geometry>
      <material
        name="">
        <color
          rgba="0.79216 0.81961 0.93333 1" />
      </material>
    </visual>
    <collision>
      <origin
        xyz="0 0 0"
        rpy="0 0 0" />
      <geometry>
        <mesh
          filename="package://march7_description_lr/meshes/left_lower_leg.STL" />
      </geometry>
    </collision>
  </link>
  <joint
    name="left_ankle"
    type="revolute">
    <origin
      xyz="0.025 -0.2 0.025"
      rpy="1.5708 0 0" />
    <parent
      link="base_link" />
    <child
      link="left_lower_leg" />
    <axis
      xyz="1 0 0" />
    <limit
      lower="-0.7854"
      upper="0.7854"
      effort="0"
      velocity="0" />
  </joint>
  <link
    name="left_upper_leg">
    <inertial>
      <origin
        xyz="-0.025 0.14577 -0.025"
        rpy="0 0 0" />
      <mass
        value="0.72546" />
      <inertia
        ixx="0.0053829"
        ixy="1.8767E-20"
        ixz="-4.308E-20"
        iyy="0.00030643"
        iyz="-9.1999E-20"
        izz="0.0053787" />
    </inertial>
    <visual>
      <origin
        xyz="0 0 0"
        rpy="0 0 0" />
      <geometry>
        <mesh
          filename="package://march7_description_lr/meshes/left_upper_leg.STL" />
      </geometry>
      <material
        name="">
        <color
          rgba="0.79216 0.81961 0.93333 1" />
      </material>
    </visual>
    <collision>
      <origin
        xyz="0 0 0"
        rpy="0 0 0" />
      <geometry>
        <mesh
          filename="package://march7_description_lr/meshes/left_upper_leg.STL" />
      </geometry>
    </collision>
  </link>
  <joint
    name="left_knee"
    type="revolute">
    <origin
      xyz="0 0.3 0.05"
      rpy="0 0 0" />
    <parent
      link="left_lower_leg" />
    <child
      link="left_upper_leg" />
    <axis
      xyz="1 0 0" />
    <limit
      lower="0"
      upper="1.5708"
      effort="0"
      velocity="0" />
  </joint>
  <link
    name="left_hip">
    <inertial>
      <origin
        xyz="-0.043295 -5.5511E-16 -1.4988E-15"
        rpy="0 0 0" />
      <mass
        value="0.27454" />
      <inertia
        ixx="0.00010608"
        ixy="-5.5597E-21"
        ixz="2.1088E-19"
        iyy="0.0003922"
        iyz="-1.9783E-20"
        izz="0.0003922" />
    </inertial>
    <visual>
      <origin
        xyz="0 0 0"
        rpy="0 0 0" />
      <geometry>
        <mesh
          filename="package://march7_description_lr/meshes/left_hip.STL" />
      </geometry>
      <material
        name="">
        <color
          rgba="0.79216 0.81961 0.93333 1" />
      </material>
    </visual>
    <collision>
      <origin
        xyz="0 0 0"
        rpy="0 0 0" />
      <geometry>
        <mesh
          filename="package://march7_description_lr/meshes/left_hip.STL" />
      </geometry>
    </collision>
  </link>
  <joint
    name="left_hip_fe"
    type="revolute">
    <origin
      xyz="0 0.275 -0.025"
      rpy="3.1416 0 3.1416" />
    <parent
      link="left_upper_leg" />
    <child
      link="left_hip" />
    <axis
      xyz="1 0 0" />
    <limit
      lower="-0.7854"
      upper="0.7854"
      effort="0"
      velocity="0" />
  </joint>
  <link
    name="hip">
    <inertial>
      <origin
        xyz="0.075 -0.025 -0.025"
        rpy="0 0 0" />
      <mass
        value="0.375" />
      <inertia
        ixx="0.00015625"
        ixy="-8.6266E-36"
        ixz="2.2588E-20"
        iyy="0.00078125"
        iyz="-8.0638E-21"
        izz="0.00078125" />
    </inertial>
    <visual>
      <origin
        xyz="0 0 0"
        rpy="0 0 0" />
      <geometry>
        <mesh
          filename="package://march7_description_lr/meshes/hip.STL" />
      </geometry>
      <material
        name="">
        <color
          rgba="0.79216 0.81961 0.93333 1" />
      </material>
    </visual>
    <collision>
      <origin
        xyz="0 0 0"
        rpy="0 0 0" />
      <geometry>
        <mesh
          filename="package://march7_description_lr/meshes/hip.STL" />
      </geometry>
    </collision>
  </link>
  <joint
    name="left_hip_aa"
    type="revolute">
    <origin
      xyz="-0.1 0.025 -0.025"
      rpy="3.1416 0 3.1416" />
    <parent
      link="left_hip" />
    <child
      link="hip" />
    <axis
      xyz="0 0 1" />
    <limit
      lower="-0.34907"
      upper="0.34907"
      effort="0"
      velocity="0" />
  </joint>
  <link
    name="right_hip">
    <inertial>
      <origin
        xyz="0.056705 -0.025 -0.025"
        rpy="0 0 0" />
      <mass
        value="0.27454" />
      <inertia
        ixx="0.00010608"
        ixy="5.7765E-21"
        ixz="-4.7948E-21"
        iyy="0.0003922"
        iyz="-2.9364E-22"
        izz="0.0003922" />
    </inertial>
    <visual>
      <origin
        xyz="0 0 0"
        rpy="0 0 0" />
      <geometry>
        <mesh
          filename="package://march7_description_lr/meshes/right_hip.STL" />
      </geometry>
      <material
        name="">
        <color
          rgba="0.79216 0.81961 0.93333 1" />
      </material>
    </visual>
    <collision>
      <origin
        xyz="0 0 0"
        rpy="0 0 0" />
      <geometry>
        <mesh
          filename="package://march7_description_lr/meshes/right_hip.STL" />
      </geometry>
    </collision>
  </link>
  <joint
    name="right_hip_aa"
    type="revolute">
    <origin
      xyz="0.15 0 0"
      rpy="0 0 0" />
    <parent
      link="hip" />
    <child
      link="right_hip" />
    <axis
      xyz="0 0 1" />
    <limit
      lower="-0.34907"
      upper="0.34907"
      effort="0"
      velocity="0" />
  </joint>
  <link
    name="right_upper_leg">
    <inertial>
      <origin
        xyz="0.025 -0.12923 -6.8556E-15"
        rpy="0 0 0" />
      <mass
        value="0.72546" />
      <inertia
        ixx="0.0053829"
        ixy="3.2768E-20"
        ixz="-6.4023E-20"
        iyy="0.00030643"
        iyz="-3.5412E-20"
        izz="0.0053787" />
    </inertial>
    <visual>
      <origin
        xyz="0 0 0"
        rpy="0 0 0" />
      <geometry>
        <mesh
          filename="package://march7_description_lr/meshes/right_upper_leg.STL" />
      </geometry>
      <material
        name="">
        <color
          rgba="0.79216 0.81961 0.93333 1" />
      </material>
    </visual>
    <collision>
      <origin
        xyz="0 0 0"
        rpy="0 0 0" />
      <geometry>
        <mesh
          filename="package://march7_description_lr/meshes/right_upper_leg.STL" />
      </geometry>
    </collision>
  </link>
  <joint
    name="right_hip_fe"
    type="revolute">
    <origin
      xyz="0.1 -0.025 -0.025"
      rpy="0 0 0" />
    <parent
      link="right_hip" />
    <child
      link="right_upper_leg" />
    <axis
      xyz="1 0 0" />
    <limit
      lower="-0.7854"
      upper="0.7854"
      effort="0"
      velocity="0" />
  </joint>
  <link
    name="right_lower_leg">
    <inertial>
      <origin
        xyz="0.025 -0.15423 -0.025"
        rpy="0 0 0" />
      <mass
        value="0.72546" />
      <inertia
        ixx="0.0053829"
        ixy="-1.8629E-19"
        ixz="-8.0964E-20"
        iyy="0.00030643"
        iyz="-1.7259E-19"
        izz="0.0053787" />
    </inertial>
    <visual>
      <origin
        xyz="0 0 0"
        rpy="0 0 0" />
      <geometry>
        <mesh
          filename="package://march7_description_lr/meshes/right_lower_leg.STL" />
      </geometry>
      <material
        name="">
        <color
          rgba="0.79216 0.81961 0.93333 1" />
      </material>
    </visual>
    <collision>
      <origin
        xyz="0 0 0"
        rpy="0 0 0" />
      <geometry>
        <mesh
          filename="package://march7_description_lr/meshes/right_lower_leg.STL" />
      </geometry>
    </collision>
  </link>
  <joint
    name="right_knee"
    type="revolute">
    <origin
      xyz="0 -0.275 0.025"
      rpy="0 0 0" />
    <parent
      link="right_upper_leg" />
    <child
      link="right_lower_leg" />
    <axis
      xyz="1 0 0" />
    <limit
      lower="-1.5708"
      upper="0"
      effort="0"
      velocity="0" />
  </joint>
  <link
    name="right_foot">
    <inertial>
      <origin
        xyz="0.025 -0.025 -0.1"
        rpy="0 0 0" />
      <mass
        value="0.5" />
      <inertia
        ixx="0.0017708"
        ixy="7.7249E-21"
        ixz="0"
        iyy="0.0017708"
        iyz="3.7947E-20"
        izz="0.00020833" />
    </inertial>
    <visual>
      <origin
        xyz="0 0 0"
        rpy="0 0 0" />
      <geometry>
        <mesh
          filename="package://march7_description_lr/meshes/right_foot.STL" />
      </geometry>
      <material
        name="">
        <color
          rgba="0.79216 0.81961 0.93333 1" />
      </material>
    </visual>
    <collision>
      <origin
        xyz="0 0 0"
        rpy="0 0 0" />
      <geometry>
        <mesh
          filename="package://march7_description_lr/meshes/right_foot.STL" />
      </geometry>
    </collision>
  </link>
  <joint
    name="right_ankle"
    type="revolute">
    <origin
      xyz="0 -0.3 -0.05"
      rpy="0 0 0" />
    <parent
      link="right_lower_leg" />
    <child
      link="right_foot" />
    <axis
      xyz="1 0 0" />
    <limit
      lower="-0.7854"
      upper="0.7854"
      effort="0"
      velocity="0" />
  </joint>
</robot>