<?xml version="1.0" ?>
<!-- Hennie URDF for IK solver -->
<!-- written by Tessel 03/07/23 -->

<robot name ="HennieKoen">
	<!-- Robot Link Definitions -->
	<!--     22 linkages        -->
	<link name="base_link"></link>
	<link name="backpack">
		<inertial>
			<origin rpy="0 0 0" xyz="0.171 -0.006 0.342"/>
      		<mass value="57.096"/>
      		<inertia ixx="2.931" ixy="0.023" ixz="-0.1" iyy="2.492" iyz="0.025" izz="1.522"/>
		</inertial>
		<visual>
			<geometry>
				<mesh filename="package://march_description/meshes/march8/Backpack.stl" scale="1 1 1"/>
			</geometry>
			<material name="">
				<color rgba="0.8 0.8 0.8 1.0"/>
			</material>
		</visual>
		<collision>
			<geometry>
				<mesh filename="package://march_description/meshes/march8/Backpack.stl" scale="1 1 1"/>
			</geometry>
		</collision>
	</link>
	<link name="L_hip">
		<inertial>
			<origin rpy="0 0 0" xyz="0.05 0.109 0.033"/>
      		<mass value="1.849"/>
      		<inertia ixx="0.012" ixy="-0.004" ixz="0.002" iyy="0.013" iyz="0.0" izz="0.012"/>
		</inertial>
		<visual>
			<geometry>
				<mesh filename="package://march_description/meshes/march8/HipLeft.stl" scale="1 1 1"/>
			</geometry>
			<material name="">
				<color rgba="0.8 0.8 0.8 1.0"/>
			</material>
		</visual>
		<collision>
			<geometry>
				<mesh filename="package://march_description/meshes/march8/HipLeft.stl" scale="1 1 1"/>
			</geometry>
		</collision>
	</link>
	<link name="L_UL">
		<inertial>
			<origin rpy="0 0 0" xyz="0.012 -0.098 -0.151"/>
			<mass value="26.104"/>
			<inertia ixx="0.859" ixy="0.021" ixz="-0.025" iyy="0.733" iyz="0.055" izz="0.23"/>
		</inertial>
		<visual>
			<geometry>
				<mesh filename="package://march_description/meshes/march8/UpperLegLeft.stl" scale="1 1 1"/>
			</geometry>
			<material name="">
				<color rgba="0.8 0.8 0.8 1.0"/>
			</material>
		</visual>
		<collision>
			<geometry>
				<mesh filename="package://march_description/meshes/march8/UpperLegLeft.stl"  scale="1 1 1"/>
			</geometry>
		</collision>
	</link>
	<link name="L_LL">
		<inertial>
			<origin rpy="0 0 0" xyz="-0.021 -0.079 -0.157"/>
			<mass value="7.061"/>
			<inertia ixx="0.12" ixy="0.003" ixz="-0.008" iyy="0.117" iyz="0.012" izz="0.034"/>
		</inertial>
		<visual>
			<geometry>
				<mesh filename="package://march_description/meshes/march8/LowerLegLeft.stl" scale="1 1 1"/>
			</geometry>
			<material name="">
				<color rgba="0.8 0.8 0.8 1.0"/>
			</material>
		</visual>
		<collision>
			<geometry>
				<mesh filename="package://march_description/meshes/march8/LowerLegLeft.stl" scale="1 1 1"/>
			</geometry>
		</collision>
	</link>
	<link name="L_foot">
		<inertial>
			<origin rpy="0 0 0" xyz="0.007 -0.054 -0.035"/>
			<mass value="2.964"/>
			<inertia ixx="0.023" ixy="0.004" ixz="0.011" iyy="0.031" iyz="-0.004" izz="0.019"/>
		</inertial>
		<visual>
			<geometry>
				<mesh filename="package://march_description/meshes/march8/FootLeft.stl" scale="1 1 1"/>
			</geometry>
			<material name="">
				<color rgba="0.8 0.8 0.8 1.0"/>
			</material>
		</visual>
		<collision>
			<geometry>
				<mesh filename="package://march_description/meshes/march8/FootLeft.stl" scale="1 1 1"/>
			</geometry>
		</collision>
	</link>
	<link name="R_hip">
		<inertial>
			<origin rpy="0 0 0" xyz="0.05 -0.109 0.033"/>
      		<mass value="1.849"/>
      		<inertia ixx="0.012" ixy="0.004" ixz="0.002" iyy="0.013" iyz="-0.0" izz="0.012"/>
		</inertial>
		<visual>
			<geometry>
				<mesh filename="package://march_description/meshes/march8/HipLeft.stl" scale="1 -1 1"/>
			</geometry>
			<material name="">
				<color rgba="0.8 0.8 0.8 1.0"/>
			</material>
		</visual>
		<collision>
			<geometry>
				<mesh filename="package://march_description/meshes/march8/HipLeft.stl" scale="1 -1 1"/>
			</geometry>
		</collision>
	</link>
	<link name="R_UL">
		<inertial>
			<origin rpy="0 0 0" xyz="0.012 0.098 -0.151"/>
			<mass value="26.104"/>
			<inertia ixx="0.859" ixy="-0.021" ixz="-0.025" iyy="0.733" iyz="-0.055" izz="0.23"/>
		</inertial>
		<visual>
			<geometry>
				<mesh filename="package://march_description/meshes/march8/UpperLegLeft.stl" scale="1 -1 1"/>
			</geometry>
			<material name="">
				<color rgba="0.8 0.8 0.8 1.0"/>
			</material>
		</visual>
		<collision>
			<geometry>
				<mesh filename="package://march_description/meshes/march8/UpperLegLeft.stl" scale="1 -1 1"/>
			</geometry>
		</collision>
	</link>
	<link name="R_LL">
		<inertial>
			<origin rpy="0 0 0" xyz="-0.021 0.079 -0.157"/>
			<mass value="7.061"/>
			<inertia ixx="0.12" ixy="-0.003" ixz="-0.008" iyy="0.117" iyz="-0.012" izz="0.034"/>
		</inertial>
		<visual>
			<geometry>
				<mesh filename="package://march_description/meshes/march8/LowerLegLeft.stl" scale="1 -1 1"/>
			</geometry>
			<material name="">
				<color rgba="0.8 0.8 0.8 1.0"/>
			</material>
		</visual>
		<collision>
			<geometry>
				<mesh filename="package://march_description/meshes/march8/LowerLegLeft.stl" scale="1 -1 1"/>
			</geometry>
		</collision>
	</link>
	<link name="R_foot">
		<inertial>
			<origin rpy="0 0 0" xyz="0.007 0.054 -0.035"/>
			<mass value="2.964"/>
			<inertia ixx="0.023" ixy="-0.004" ixz="0.011" iyy="0.031" iyz="0.004" izz="0.019"/>
		</inertial>
		<visual>
			<geometry>
				<mesh filename="package://march_description/meshes/march8/FootLeft.stl" scale="1 -1 1"/>
			</geometry>
			<material name="">
				<color rgba="0.8 0.8 0.8 1.0"/>
			</material>
		</visual>
		<collision>
			<geometry>
				<mesh filename="package://march_description/meshes/march8/FootLeft.stl" scale="1 -1 1"/>
			</geometry>
		</collision>
	</link>
	<link name="R_toe">
	</link>
	<link name="L_toe">
	</link>
	<link name="L_ground">
	</link>
	<link name="R_ground">
	</link>

	<!-- Robot Joint Definitions -->
	<!--                         -->
	<joint name="base_link_to_backpack" type="fixed">
		<origin rpy="0 0 0" xyz="0 0 0"/>
		<parent link="base_link"/>
		<child link="backpack"/>
	</joint>
	<joint name="left_hip_aa" type="revolute">
		<origin rpy="0 0 0" xyz="-0.021 0.08 0.025"/>
		<axis xyz="-1 0 0"/>
		<parent link="backpack"/>
		<child link="L_hip"/>
		<!-- <limit effort="280" lower="-0.2618" upper="0.174533" velocity="2.6"/> -->
		<limit effort="280" lower="-0.2617993878" upper="0.1745329252" velocity="2.6"/>
	</joint>
	<joint name="left_hip_fe" type="revolute">
		<origin rpy="0 0 0.0" xyz="0.182 0.182 0"/>
		<axis xyz="0 -1 0"/>
		<parent link="L_hip"/>
		<child link="L_UL"/>
		<!-- <limit effort="250" lower="-2.00713" upper="0.20944" velocity="3.94"/> -->
		<limit effort="250" lower="-0.1745329252" upper="1.9634954085" velocity="3.94"/>
	</joint>
	<joint name="left_knee" type="revolute">
		<origin rpy="0 0 0" xyz="0 -0.06 -0.413"/>
		<axis xyz="0 1 0"/>
		<parent link="L_UL"/>
		<child link="L_LL"/>
		<limit effort="250" lower="0.08" upper="2.131661565" velocity="3.94"/>
	</joint>
	<joint name="left_ankle" type="revolute">
		<origin rpy="0 0 0" xyz="0 -0.037 -0.414"/>
		<axis xyz="0 -1 0"/>
		<parent link="L_LL"/>
		<child link="L_foot"/>
		<!-- <limit effort="0.9" lower="-0.0174533" upper="0.436332" velocity="4.1"/> -->
		<limit effort="179" lower="-0.336332313" upper="0.155000" velocity="4.1"/>
	</joint>
	<joint name="right_hip_aa" type="revolute">
		<origin rpy="0 0 0" xyz="-0.021 -0.08 0.025"/>
		<axis xyz="1 0 0"/>
		<parent link="backpack"/>
		<child link="R_hip"/>
		<limit effort="280" lower="-0.2617993878" upper="0.1745329252" velocity="2.6"/>
	</joint>
	<joint name="right_hip_fe" type="revolute">
		<origin rpy="0 0 0.0" xyz="0.182 -0.182 0"/>
		<axis xyz="0 -1 0"/>
		<parent link="R_hip"/>
		<child link="R_UL"/>
		<!-- <limit effort="12.2" lower="-2.00713" upper="0.20944" velocity="3.94"/> -->
		<limit effort="250" lower="-0.1745329252" upper="1.9634954085" velocity="3.94"/>
	</joint>
	<joint name="right_knee" type="revolute">
		<origin rpy="0 0 0" xyz="0 0.06 -0.413"/>
		<axis xyz="0 1 0"/>
		<parent link="R_UL"/>
		<child link="R_LL"/>
		<limit effort="250" lower="0.08" upper="2.131661565" velocity="3.94"/>
	</joint>
	<joint name="right_ankle" type="revolute">
		<origin rpy="0 0 0" xyz="0 0.037 -0.414"/>
		<axis xyz="0 -1 0"/>
		<parent link="R_LL"/>
		<child link="R_foot"/>
		<!-- <limit effort="0.9" lower="-0.0174533" upper="0.436332" velocity="4.1"/> -->
		<limit effort="179" lower="-0.336332313" upper="0.155000" velocity="4.1"/>
	</joint> 
	<joint name="L_ground" type="fixed">
		<origin xyz="0 0 -0.126"/>
		<parent link="L_foot"/>
		<child link="L_ground"/>
	</joint>
	<joint name="R_ground" type="fixed">
		<origin xyz="0 0 -0.126"/>
		<parent link="R_foot"/>
		<child link="R_ground"/>
	</joint>

	<joint name="right_toe" type="fixed">
		<origin xyz="0.184 0.085 0"/>
		<parent link="R_ground"/>
		<child link="R_toe"/>
	</joint>

	<joint name="left_toe" type="fixed">
		<origin xyz="0.184 -0.085 0"/>
		<parent link="L_ground"/>
		<child link="L_toe"/>
	</joint>

	<!-- Robot Transmission Definitions -->
	<!--                                -->
	<transmission name="L_HAATransmission">
            <joint name="left_hip_aa"/>
            <actuator>
                    <mechanicalReduction>25</mechanicalReduction>
                    <motorInertia>5.4</motorInertia>
            </actuator>
  	</transmission>
  	<transmission name="L_HFETransmission">
            <joint name="left_hip_fe"/>
            <actuator>
                    <mechanicalReduction>16</mechanicalReduction>
                    <motorInertia>6.0</motorInertia>
            </actuator>
  	</transmission>
  	<transmission name="L_KFETransmission">
            <joint name="left_knee"/>
            <actuator>
                    <mechanicalReduction>16</mechanicalReduction>
                    <motorInertia>6.0</motorInertia>
            </actuator>
  	</transmission>
  	<transmission name="L_ADPFTransmission">
            <joint name="left_ankle"/>
            <actuator>
                    <mechanicalReduction>50</mechanicalReduction>
                    <motorInertia>2.2</motorInertia>
            </actuator>
  	</transmission>
  	<transmission name="R_HAATransmission">
            <joint name="right_hip_aa"/>
            <actuator>
                    <mechanicalReduction>25</mechanicalReduction>
                    <motorInertia>5.4</motorInertia>
            </actuator>
  	</transmission>
  	<transmission name="R_HFETransmission">
            <joint name="right_hip_fe"/>
            <actuator>
                    <mechanicalReduction>16</mechanicalReduction>
                    <motorInertia>6.0</motorInertia>
            </actuator>
  	</transmission>
  	<transmission name="R_KFETransmission">
            <joint name="right_knee"/>
            <actuator>
                    <mechanicalReduction>16</mechanicalReduction>
                    <motorInertia>6.0</motorInertia>
            </actuator>
  	</transmission>
  	<transmission name="R_ADPFTransmission">
            <joint name="right_ankle"/>
            <actuator>
                    <mechanicalReduction>50</mechanicalReduction>
                    <motorInertia>2.2</motorInertia>
            </actuator>
  	</transmission>
</robot>