<!-- 
Copyright (C) 2023. Stichting Moving Bird 
Joy Brand, joy.brand@projectmarch.nl 
Thijn Hoekstra, thijn.hoekstra@projectmarch.nl 

This program is free software: you can redistribute it and/or modify 
it under the terms of the GNU General Public License as published by 
the Free Software Foundation, either version 3 of the License, or 
(at your option) any later version. 

This program is distributed in the hope that it will be useful, 
but WITHOUT ANY WARRANTY; without even the implied warranty of 
MERCHANTABILITY or FITNESS FOR A PARTICULAR PURPOSE.  See the 
GNU General Public License for more details. 

See <https://www.gnu.org/licenses/>.
-->

<mujoco model="exoskeleton">
  <compiler meshdir="obj-files" angle="degree" autolimits="true"/>
  <size nuser_actuator='1' nuser_sensor='1' nuser_geom='1'/>
  <option timestep='0.0005' iterations='50' solver='PGS' gravity='0 0 -9.81'/>

  <asset>
    <texture type="skybox" builtin="gradient" rgb1=".3 .5 .7" rgb2="0 0 0" width="512" height="512"/>
    <texture name="body" type="cube" builtin="flat" mark="cross" width="127" height="1278"
             rgb1="0.8 0.6 0.4" rgb2="0.8 0.6 0.4" markrgb="1 1 1" random="0.01"/>
    <texture name="grid" type="2d" builtin="checker" width="512" height="512" rgb1=".1 .2 .3" rgb2=".2 .3 .4"/>
    <material name="grid" texture="grid" texrepeat="1 1" texuniform="true" reflectance=".2"/>
    <material name="march_grey" rgba=".87 .89 .91 1"/>
    <mesh name="backpack"    file="Backpack.obj"/>
    <mesh name="L_foot"      file="FootLeft.obj"/>
    <mesh name="L_hip"       file="HipLeft.obj"/>
    <mesh name="L_thigh"     file="UpperLegLeft.obj"/>
    <mesh name="L_shin"      file="LowerLegLeft.obj"/>
    <mesh name="R_foot"     scale="1 -1 1"    file="FootLeft.obj"/>
    <mesh name="R_hip"      scale="1 -1 1"    file="HipLeft.obj"/>
    <mesh name="R_thigh"    scale="1 -1 1"    file="UpperLegLeft.obj"/>
    <mesh name="R_shin"     scale="1 -1 1"    file="LowerLegLeft.obj"/>
  </asset>

  <default>
    <site group="5"/>
    <motor ctrlrange="-1 1" ctrllimited="true"/>
    <geom contype="0" conaffinity="0" condim="1" solref="0.005 1"/>
    <equality solref="0.005 1"/>
    <default class="exoskeleton">
      <geom material="march_grey" group="2"/>
    </default>
    <default class="collision">
      <geom contype="1" group="3" type="capsule"/>
      <default class="L_collision">
        <geom contype="2" conaffinity="4"/>
      </default>
      <default class="R_collision">
        <geom contype="4" conaffinity="2"/>
      </default>
    </default>
    <default class="HAA_joint">
      <joint damping="107.692308"
              armature="5.4"
             frictionloss="0" stiffness="0"/>
    </default>
    <default class="ADPF_joint">
      <joint damping="43.658537"
              armature="2.2"
             frictionloss="0" stiffness="0"/>
    </default>
    <default class="rotational_joint">
      <joint damping="63.451777"
              armature="9.98"
             frictionloss="0" stiffness="0"/>
    </default>
  </default>

  <visual>
    <map force="0.1" zfar="30"/>
    <rgba haze="0.15 0.25 0.35 1"/>
    <quality shadowsize="4096"/>
    <global offwidth="800" offheight="800"/>
  </visual>

  <worldbody>
    <geom name="floor" size="0 0 .05" type="plane" material="grid" conaffinity="15" condim="3"/>
    <light name="spotlight" mode="targetbodycom" target="backpack"
           diffuse=".8 .8 .8" specular="0.3 0.3 0.3" pos="0 -20 4" cutoff="10"/>

    <body name="backpack"
          pos="0 0 1.2"
          childclass="exoskeleton">
      <light name="top" pos="0 0 2" mode="trackcom"/>
      <camera name="diag" pos="3 -2.5 1" xyaxes="1 1 0 0 1 2" mode="trackcom"/>
      <camera name="right" pos="0 -3 1" xyaxes="1 0 0 0 1 2" mode="trackcom"/>
      <site name='imu_backpack' size='0.01' pos="0 0 0"/>
      <inertial pos="0.171 -0.006 0.342" mass="57.096"
                fullinertia="2.931 2.492 1.522 0.023 -0.1 0.025"/>
<!--      <freejoint/>-->
      <geom type="mesh" mesh="backpack" />
      <geom name="backpack" type="box"
            size="0.051 0.189 0.165"
            pos="-0.02 0 0.13" class="collision"/>

    <site name="imu_torso" size='0.01' pos="0.2 0 0.4"/>

      <!--  LEFT LEG -->
      <body name="L_hip" pos="-0.021 0.08 0.025">
        <inertial pos="0.05 0.109 0.033" mass="1.849"
                  fullinertia="0.012 0.013 0.012 -0.004 0.002 0"/>
        <joint name="L_HAA" axis="-1 0 0" range="-15 10" class="HAA_joint"/>
        <geom type="mesh" mesh="L_hip" />
        <geom name="L_hip" fromto="0 0 0 0.182 0.182 0"
              size="0.032" class="L_collision"/>
        <site name="tor_L_HAA" size="0.01" pos="0 0 0"/>

        <body name="L_UL" pos="0.182 0.182 0">
        <inertial pos="0.012 -0.098 -0.151" mass="26.104"
                  fullinertia="0.859 0.733 0.23 0.021 -0.025 0.055"/>
          <joint name="L_HFE" axis="0 -1 0" range="-10 112.5" class="rotational_joint"/>
          <geom type="mesh" mesh="L_thigh" pos="0 .013 0" />
          <geom name="L_UL" fromto="0 0 0 0 -0.06 -0.413"
              size="0.069" class="L_collision"/>
          <site name="tor_L_HFE" size="0.01" pos="0 0 0"/>

          <body name="L_LL" pos="0 -0.06 -0.413">
            <inertial pos="-0.021 -0.079 -0.157" mass="7.061"
                  fullinertia="0.12 0.117 0.034 0.003 -0.008 0.012"/>
            <joint name="L_KFE" axis="0 1 0" range="0 125" class="rotational_joint"/>
            <geom type="mesh" mesh="L_shin"/>
            <geom name="L_LL" fromto="0 0 0 0.0 -0.037 -0.414"
              size="0.047" class="L_collision"/>
            <site name="tor_L_KFE" size="0.01" pos="0 0 0"/>

            <body name="L_foot" pos="0.0 -0.037 -0.414">
              <inertial pos="0.007 -0.054 -0.035" mass="2.964"
                  fullinertia="0.023 0.031 0.019 0.004 0.011 -0.004"/>
              <joint name="L_ADPF" axis="0 -1 0" range="-25 10" class="ADPF_joint"/>
              <geom type="mesh" mesh="L_foot"/>
              <site name="tor_L_ADPF" size="0.01" pos="0 0 0"/>

              <!-- The L_foot geometry models a footplate which extends past the pressure pads on the soles-->
              <geom name="L_foot" type="box" size="0.159 0.057 0.007"
                  pos="0.069 -0.086 -0.118"  class="L_collision"
                  friction="3.0"/>

              <!-- Pressure sole  -->
             <body name="pres_L_0" pos="-0.045 -0.072 -0.138">
                <geom name="pres_L_0" type="sphere" pos="0 0 0"
                      size="0.01" class="L_collision"  friction="3.0"/>
                <site name="pres_L_0"/>
              </body>
              <body name="pres_L_1" pos="-0.045 -0.072 -0.138">
                <geom name="pres_L_1" type="sphere" pos="0 0 0"
                      size="0.01" class="L_collision"  friction="3.0"/>
                <site name="pres_L_1"/>
              </body>
              <body name="pres_L_2" pos="0.05 -0.061 -0.138">
                <geom name="pres_L_2" type="sphere" pos="0 0 0"
                      size="0.01" class="L_collision"  friction="3.0"/>
                <site name="pres_L_2"/>
              </body>
              <body name="pres_L_3" pos="0.118 -0.05 -0.138">
                <geom name="pres_L_3" type="sphere" pos="0 0 0"
                      size="0.01" class="L_collision"  friction="3.0"/>
                <site name="pres_L_3"/>
              </body>
              <body name="pres_L_4" pos="0.13 -0.083 -0.138">
                <geom name="pres_L_4" type="sphere" pos="0 0 0"
                      size="0.01" class="L_collision"  friction="3.0"/>
                <site name="pres_L_4"/>
              </body>
              <body name="pres_L_5" pos="0.137 -0.115 -0.138">
                <geom name="pres_L_5" type="sphere" pos="0 0 0"
                      size="0.01" class="L_collision"  friction="3.0"/>
                <site name="pres_L_5"/>
              </body>
              <body name="pres_L_6" pos="0.174 -0.07 -0.138">
                <geom name="pres_L_6" type="sphere" pos="0 0 0"
                      size="0.01" class="L_collision"  friction="3.0"/>
                <site name="pres_L_6"/>
              </body>
              <body name="pres_L_7" pos="0.184 -0.105 -0.138">
                <geom name="pres_L_7" type="sphere" pos="0 0 0"
                      size="0.01" class="L_collision"  friction="3.0"/>
                <site name="pres_L_7"/>
              </body>
            </body>
          </body>
        </body>
      </body>

      <!--  RIGHT LEG -->
      <body name="R_hip" pos="-0.021 -0.08 0.025">
        <inertial pos="0.05 -0.109 0.033" mass="1.849"
                  fullinertia="0.012 0.013 0.012 0.004 0.002 -0"/>
        <joint name="R_HAA" axis="1 0 0" range="-15 10" class="HAA_joint"/>
        <geom type="mesh" mesh="R_hip" />
        <geom name="R_hip" fromto="0 0 0 0.182 -0.182 0"
              size="0.032" class="R_collision"/>
        <site name="tor_R_HAA" size="0.01" pos="0 0 0"/>

        <body name="R_UL" pos="0.182 -0.182 0">
          <inertial pos="0.012 0.098 -0.151" mass="26.104"
                  fullinertia="0.859 0.733 0.23 -0.021 -0.025 -0.055"/>
          <joint name="R_HFE" axis="0 -1 0" range="-10 112.5" class="rotational_joint"/>
          <geom type="mesh" mesh="R_thigh"/>
          <geom name="R_UL" fromto="0 0 0 0 0.06 -0.413"
              size="0.069" class="R_collision"/>
          <site name="tor_R_HFE" size="0.01" pos="0 0 0"/>

          <body name="R_LL" pos="0 0.06 -0.413">
            <inertial pos="-0.021 0.079 -0.157" mass="7.061"
                  fullinertia="0.12 0.117 0.034 -0.003 -0.008 -0.012"/>
            <joint name="R_KFE" axis="0 1 0" range="0 125" class="rotational_joint"/>
            <geom type="mesh" mesh="R_shin"/>
            <geom name="R_LL" fromto="0 0 0 0.0 0.037 -0.414"
              size="0.047" class="R_collision"/>
            <site name="tor_R_KFE" size="0.01" pos="0 0 0"/>

            <body name="R_foot" pos="0.0 0.037 -0.414">
              <inertial pos="0.007 0.054 -0.035" mass="2.964"
                  fullinertia="0.023 0.031 0.019 -0.004 0.011 0.004"/>
              <joint name="R_ADPF" axis="0 -1 0" range="-25 10" class="ADPF_joint"/>
              <geom type="mesh" mesh="R_foot"/>
              <site name="tor_R_ADPF" size="0.01" pos="0 0 0"/>

              <!-- The R_foot geometry models a footplate which extends past the pressure pads on the soles-->
              <geom name="R_foot" type="box" size="0.159 0.057 0.007"
                  pos="0.069 0.086 -0.118"  class="R_collision"
                  friction="3.0"/>

                  <!-- Pressure sole  -->
              <body name="pres_R_0" pos="-0.045 0.072 -0.138">
                <geom name="pres_R_0" type="sphere" pos="0 0 0"
                      size="0.01" class="L_collision"  friction="3.0"/>
                <site name="pres_R_0"/>
              </body>
              <body name="pres_R_1" pos="-0.045 0.072 -0.138">
                <geom name="pres_R_1" type="sphere" pos="0 0 0"
                      size="0.01" class="L_collision"  friction="3.0"/>
                <site name="pres_R_1"/>
              </body>
              <body name="pres_R_2" pos="0.05 0.061 -0.138">
                <geom name="pres_R_2" type="sphere" pos="0 0 0"
                      size="0.01" class="L_collision"  friction="3.0"/>
                <site name="pres_R_2"/>
              </body>
              <body name="pres_R_3" pos="0.118 0.05 -0.138">
                <geom name="pres_R_3" type="sphere" pos="0 0 0"
                      size="0.01" class="L_collision"  friction="3.0"/>
                <site name="pres_R_3"/>
              </body>
              <body name="pres_R_4" pos="0.13 0.083 -0.138">
                <geom name="pres_R_4" type="sphere" pos="0 0 0"
                      size="0.01" class="L_collision"  friction="3.0"/>
                <site name="pres_R_4"/>
              </body>
              <body name="pres_R_5" pos="0.137 0.115 -0.138">
                <geom name="pres_R_5" type="sphere" pos="0 0 0"
                      size="0.01" class="L_collision"  friction="3.0"/>
                <site name="pres_R_5"/>
              </body>
              <body name="pres_R_6" pos="0.174 0.07 -0.138">
                <geom name="pres_R_6" type="sphere" pos="0 0 0"
                      size="0.01" class="L_collision"  friction="3.0"/>
                <site name="pres_R_6"/>
              </body>
              <body name="pres_R_7" pos="0.184 0.105 -0.138">
                <geom name="pres_R_7" type="sphere" pos="0 0 0"
                      size="0.01" class="L_collision"  friction="3.0"/>
                <site name="pres_R_7"/>
              </body>
            </body>
          </body>
        </body>
      </body>

    </body>
  </worldbody>

  <actuator>
    <!-- User parameter is the maximum no-load motor RPM -->
    <motor name="left_ankle"    gear="179"  joint="L_ADPF"  forcerange="-3.8 3.8"/>
    <motor name="left_hip_aa"     gear="280"  joint="L_HAA"  forcerange="-3.8 3.8"/>
    <motor name="left_hip_fe"     gear="250" joint="L_HFE"  forcerange="-3.8 3.8"/>
    <motor name="left_knee"     gear="250"  joint="L_KFE"  forcerange="-3.8 3.8"/>
    <motor name="right_ankle"    gear="179"  joint="R_ADPF"  forcerange="-3.8 3.8"/>
    <motor name="right_hip_aa"     gear="280"  joint="R_HAA"  forcerange="-3.8 3.8"/>
    <motor name="right_hip_fe"     gear="250" joint="R_HFE"  forcerange="-3.8 3.8"/>
    <motor name="right_knee"     gear="250"  joint="R_KFE"  forcerange="-3.8 3.8"/>
  </actuator>

  <sensor>
    <!-- User parameter is the number of absolute encoder bits -->
    <!-- encodersoutput position; connected to the actuator -->
    <jointpos name="L_ADPF_pos_output" joint="L_ADPF" user="18" noise="000"/>
    <jointpos name="L_HAA_pos_output" joint="L_HAA" user="18" noise="000"/>
    <jointpos name="L_HFE_pos_output" joint="L_HFE" user="18" noise="000"/>
    <jointpos name="L_KFE_pos_output" joint="L_KFE" user="18" noise="000"/>
    <jointpos name="R_ADPF_output" joint="R_ADPF" user="18" noise="000"/>
    <jointpos name="R_HAA_output" joint="R_HAA" user="18" noise="000"/>
    <jointpos name="R_HFE_output" joint="R_HFE" user="18" noise="000"/>
    <jointpos name="R_KFE_output" joint="R_KFE" user="18" noise="000"/>
    <!-- encodersoutput velocity; connected to the actuator -->
    <jointvel name="L_ADPF_vel_output" joint="L_ADPF" user="18" noise="000"/>
    <jointvel name="L_HAA_vel_output" joint="L_HAA" user="18" noise="000"/>
    <jointvel name="L_HFE_vel_output" joint="L_HFE" user="18" noise="000"/>
    <jointvel name="L_KFE_vel_output" joint="L_KFE" user="18" noise="000"/>
    <jointvel name="R_ADPF_vel_output" joint="R_ADPF" user="18" noise="000"/> 
    <jointvel name="R_HAA_vel_output" joint="R_HAA" user="18" noise="000"/>
    <jointvel name="R_HFE_vel_output" joint="R_HFE" user="18" noise="000"/>
    <jointvel name="R_KFE_vel_output" joint="R_KFE" user="18" noise="000"/>
    <!-- torque sensors; connected to the actuator-->

<!--    TODO: This could also be of the type actuatorvel -->
    <torque name="L_ADPF_tor_output" site="tor_L_ADPF" user="13" noise="000"/>
    <torque name="L_HAA_tor_output" site="tor_L_HAA" user="13" noise="000"/>
    <torque name="L_HFE_tor_output" site="tor_L_HFE" user="13" noise="000"/>
    <torque name="L_KFE_tor_output" site="tor_L_KFE" user="13" noise="000"/>
    <torque name="R_ADPF_tor_output" site="tor_R_ADPF" user="13" noise="000"/>
    <torque name="R_HAA_tor_output" site="tor_R_HAA" user="13" noise="000"/>
    <torque name="R_HFE_tor_output" site="tor_R_HFE" user="13" noise="000"/>
    <torque name="R_KFE_tor_output" site="tor_R_KFE" user="13" noise="000"/>

    <!-- pressure soles not finished yet -->
    <force name="L_pressuresole_1_output" site="pres_L_0" noise="000" cutoff="000"/>
    <force name="L_pressuresole_2_output" site="pres_L_1" noise="000" cutoff="000"/>
    <force name="L_pressuresole_3_output" site="pres_L_2" noise="000" cutoff="000"/>
    <force name="L_pressuresole_4_output" site="pres_L_3" noise="000" cutoff="000"/>
    <force name="L_pressuresole_5_output" site="pres_L_4" noise="000" cutoff="000"/>
    <force name="L_pressuresole_6_output" site="pres_L_5" noise="000" cutoff="000"/>
    <force name="L_pressuresole_7_output" site="pres_L_6" noise="000" cutoff="000"/>
    <force name="L_pressuresole_8_output" site="pres_L_7" noise="000" cutoff="000"/>

    <force name="R_pressuresole_1_output" site="pres_R_0" noise="000" cutoff="000"/>
    <force name="R_pressuresole_2_output" site="pres_R_1" noise="000" cutoff="000"/>
    <force name="R_pressuresole_3_output" site="pres_R_2" noise="000" cutoff="000"/>
    <force name="R_pressuresole_4_output" site="pres_R_3" noise="000" cutoff="000"/>
    <force name="R_pressuresole_5_output" site="pres_R_4" noise="000" cutoff="000"/>
    <force name="R_pressuresole_6_output" site="pres_R_5" noise="000" cutoff="000"/>
    <force name="R_pressuresole_7_output" site="pres_R_6" noise="000" cutoff="000"/>
    <force name="R_pressuresole_8_output" site="pres_R_7" noise="000" cutoff="000"/>

    <!-- Noise & cutoff must be determined -->
    <framepos name='backpack_position' objtype='site' objname='imu_backpack'/>
    <framelinvel name='backpack_velocity' objtype='site' objname='imu_backpack'/>
    <framequat name='backpack_orientation' objtype='site' objname='imu_backpack'/>
    <gyro name='vel_imu_backpack' site='imu_backpack' noise='5e-4' cutoff='34.9'/>
    <accelerometer name='acc_imu_backpack' site='imu_backpack' noise='1e-2' cutoff='157'/>
    <magnetometer name='magnet_imu_backpack' site='imu_backpack'/>

    <framequat name='torso_orientation' objtype='site' objname='imu_torso'/>
    <gyro name='vel_imu_torso' site='imu_torso' noise='5e-4' cutoff='34.9'/>
    <accelerometer name='acc_imu_torso' site='imu_torso' noise='1e-2' cutoff='157'/>
    <magnetometer name='magnet_imu_torso' site='imu_torso'/>

  </sensor>
</mujoco>