<?xml version="1.0" ?>
<!-- =================================================================================== -->
<!-- |    This document was autogenerated by xacro from urdf/march7.xacro              | -->
<!-- |    EDITING THIS FILE BY HAND IS NOT RECOMMENDED                                 | -->
<!-- =================================================================================== -->
<!-- Revolute-Revolute Manipulator -->
<robot name="march">
  <!-- Square dimensions (widthxwidth) of beams -->
  <!-- mass = Hip base + HAA actuators -->
  <!-- mass = Moving hip -->
  <!-- mass = KFE joint + HFE joint + Upper leg -->
  <!-- mass = Ankle actuator + Lower leg -->
  <!-- mass = Passive ankle + foot -->
  <material name="visuals_material">
    <color rgba="1.0 1.0 1.0 1"/>
  </material>
  <!-- Used for fixing robot to Gazebo 'base_link' -->
  <link name="world"/>
  <link name="hip_base">
    <visual>
      <origin rpy="0 0 0" xyz="0 0 0"/>
      <geometry>
        <mesh filename="package://march_description/urdf/stl-files/march7/HipBase.stl" scale="1 1 1"/>
      </geometry>
      <material name="visuals_material"/>
    </visual>
    <inertial>
      <origin rpy="0 0 0" xyz="-0.04201099999999999 0.016341 0.147761"/>
      <mass value="8.686"/>
      <inertia ixx="0.303498" ixy="-0.000197304" ixz="0.0189663" iyy="0.239254" iyz="0.00122058" izz="0.11822"/>
    </inertial>
    <collision>
      <origin rpy="0 0 0" xyz="0 0 0"/>
      <geometry>
        <box size="0.05 0.13 0.05"/>
      </geometry>
    </collision>
  </link>
  <!-- IMU-->
  <link name="imu_link">
    </link>
  <link name="hip_aa_frame_left_side">
    <visual>
      <origin rpy="0 0 0" xyz="0 0 0"/>
      <geometry>
        <mesh filename="package://march_description/urdf/stl-files/march7/HipLeft.stl" scale="1 1 1"/>
      </geometry>
      <material name="visuals_material"/>
    </visual>
    <collision>
      <origin rpy="0 0 0" xyz="0 -0.115 0"/>
      <geometry>
        <box size="0.05 0.23 0.05"/>
      </geometry>
    </collision>
  </link>
  <link name="hip_aa_frame_left_front">
    <inertial>
      <origin rpy="0 0 0" xyz="-0.081906 0.09724200000000005 0.029507"/>
      <mass value="3.019"/>
      <inertia ixx="0.068391" ixy="0.0426776" ixz="0.000171569" iyy="0.0388633" iyz="-0.00117041" izz="0.104156"/>
    </inertial>
    <collision>
      <origin rpy="0 0 0" xyz="-0.095 0 0"/>
      <geometry>
        <box size="0.19 0.05 0.05"/>
      </geometry>
    </collision>
  </link>
  &gt;
            
  <link name="upper_leg_left">
    <visual>
      <origin rpy="0 0 0" xyz="0 0 0"/>
      <geometry>
        <mesh filename="package://march_description/urdf/stl-files/march7/UpperLegLeft.stl" scale="1 1 1"/>
      </geometry>
      <material name="visuals_material"/>
    </visual>
    <inertial>
      <origin rpy="0 0 0" xyz="0.000709 0.07974600000000004 -0.19205"/>
      <mass value="8.161"/>
      <inertia ixx="1.68779" ixy="0.0439623" ixz="0.249519" iyy="1.68452" iyz="-0.0814673" izz="0.20142"/>
    </inertial>
    <collision>
      <origin rpy="0 0 0" xyz="0 0 -0.205"/>
      <geometry>
        <box size="0.05 0.05 0.41"/>
      </geometry>
    </collision>
  </link>
  &gt;
            
  <link name="lower_leg_left">
    <visual>
      <origin rpy="0 0 0" xyz="0 0 0"/>
      <geometry>
        <mesh filename="package://march_description/urdf/stl-files/march7/LowerLegLeft.stl" scale="1 1 1"/>
      </geometry>
      <material name="visuals_material"/>
    </visual>
    <inertial>
      <origin rpy="0 0 0" xyz="-0.00321 0.11091900000000005 -0.11708200000000007"/>
      <mass value="4.997"/>
      <inertia ixx="0.567226" ixy="-0.00351928" ixz="0.0146315" iyy="0.561191" iyz="0.019722" izz="0.0624652"/>
    </inertial>
    <collision>
      <origin rpy="0 0 0" xyz="0 0 -0.2"/>
      <geometry>
        <box size="0.05 0.05 0.4"/>
      </geometry>
    </collision>
  </link>
  &gt;
            
  <link name="ankle_plate_left">
    <visual>
      <origin rpy="0 0 0" xyz="0 0 0"/>
      <geometry>
        <mesh filename="package://march_description/urdf/stl-files/march7/FootLeft.stl" scale="1 1 1"/>
      </geometry>
      <material name="visuals_material"/>
    </visual>
    <collision>
      <origin rpy="0 0 0" xyz="0 0.07 -0.0325"/>
      <geometry>
        <box size="0.05 0.05 0.065"/>
      </geometry>
    </collision>
  </link>
  <link name="foot_left">
    <inertial>
      <origin rpy="0 0 0" xyz="-0.028926 0.12908400000000003 0.08521199999999995"/>
      <mass value="0.789"/>
      <inertia ixx="0.00388523" ixy="0.00209516" ixz="-0.00189858" iyy="0.00659119" iyz="0.00168033" izz="0.00630322"/>
    </inertial>
    <collision>
      <origin rpy="0 0 0" xyz="-0.069 0 0"/>
      <geometry>
        <box size="0.296 0.05 0.05"/>
      </geometry>
    </collision>
  </link>
  <link name="pressure_sole_left_heel_1">
    <collision>
      <origin rpy="0 0 0" xyz="0.042 0.0125 0"/>
      <geometry>
        <box size="0.074 0.025 0.001"/>
      </geometry>
    </collision>
  </link>
  <gazebo reference="pressure_sole_left_heel_1">
    <sensor name="pressure_sole_heel_1_sensor" type="contact">
      <always_on>true</always_on>
      <contact>
        <collision>ankle_plate_left_fixed_joint_lump__pressure_sole_left_heel_1_collision_8</collision>
      </contact>
      <plugin filename="libgazebo_ros_bumper.so" name="pressure_sole_plugin_heel_1">
        <bumperTopicName>march/sensor/left_pressure_sole_heel_1</bumperTopicName>
        <frameName>world</frameName>
      </plugin>
    </sensor>
  </gazebo>
  <gazebo reference="pressure_sole_left_heel_1">
    <mu1>1</mu1>
    <mu2>1</mu2>
    <minDepth>0.0005</minDepth>
    <fdir1>1 0 0</fdir1>
  </gazebo>
  <joint name="pressure_sole_left_heel_1_joint" type="fixed">
    <parent link="foot_left"/>
    <child link="pressure_sole_left_heel_1"/>
    <origin rpy="0 0 0" xyz="0 0 -0.025"/>
  </joint>
  <gazebo reference="pressure_sole_left">
    <mu1>1</mu1>
    <mu2>1</mu2>
    <minDepth>0.0005</minDepth>
    <fdir1>1 0 0</fdir1>
  </gazebo>
  <link name="pressure_sole_left_heel_2">
    <collision>
      <origin rpy="0 0 0" xyz="0.042 -0.0125 0"/>
      <geometry>
        <box size="0.074 0.025 0.001"/>
      </geometry>
    </collision>
  </link>
  <gazebo reference="pressure_sole_left_heel_2">
    <sensor name="pressure_sole_heel_2_sensor" type="contact">
      <always_on>true</always_on>
      <contact>
        <collision>ankle_plate_left_fixed_joint_lump__pressure_sole_left_heel_2_collision_9</collision>
      </contact>
      <plugin filename="libgazebo_ros_bumper.so" name="pressure_sole_plugin_heel_2">
        <bumperTopicName>march/sensor/left_pressure_sole_heel_2</bumperTopicName>
        <frameName>world</frameName>
      </plugin>
    </sensor>
  </gazebo>
  <gazebo reference="pressure_sole_left_heel_2">
    <mu1>1</mu1>
    <mu2>1</mu2>
    <minDepth>0.0005</minDepth>
    <fdir1>1 0 0</fdir1>
  </gazebo>
  <joint name="pressure_sole_left_heel_2_joint" type="fixed">
    <parent link="foot_left"/>
    <child link="pressure_sole_left_heel_2"/>
    <origin rpy="0 0 0" xyz="0 0 -0.025"/>
  </joint>
  <gazebo reference="pressure_sole_left">
    <mu1>1</mu1>
    <mu2>1</mu2>
    <minDepth>0.0005</minDepth>
    <fdir1>1 0 0</fdir1>
  </gazebo>
  <link name="pressure_sole_left_arch">
    <collision>
      <origin rpy="0 0 0" xyz="-0.03199999999999999 0.0125 0"/>
      <geometry>
        <box size="0.074 0.025 0.001"/>
      </geometry>
    </collision>
  </link>
  <gazebo reference="pressure_sole_left_arch">
    <sensor name="pressure_sole_arch_sensor" type="contact">
      <always_on>true</always_on>
      <contact>
        <collision>ankle_plate_left_fixed_joint_lump__pressure_sole_left_arch_collision_2</collision>
      </contact>
      <plugin filename="libgazebo_ros_bumper.so" name="pressure_sole_plugin_arch">
        <bumperTopicName>march/sensor/left_pressure_sole_arch</bumperTopicName>
        <frameName>world</frameName>
      </plugin>
    </sensor>
  </gazebo>
  <gazebo reference="pressure_sole_left_arch">
    <mu1>1</mu1>
    <mu2>1</mu2>
    <minDepth>0.0005</minDepth>
    <fdir1>1 0 0</fdir1>
  </gazebo>
  <joint name="pressure_sole_left_arch_joint" type="fixed">
    <parent link="foot_left"/>
    <child link="pressure_sole_left_arch"/>
    <origin rpy="0 0 0" xyz="0 0 -0.025"/>
  </joint>
  <gazebo reference="pressure_sole_left">
    <mu1>1</mu1>
    <mu2>1</mu2>
    <minDepth>0.0005</minDepth>
    <fdir1>1 0 0</fdir1>
  </gazebo>
  <link name="pressure_sole_left_met1">
    <collision>
      <origin rpy="0 0 0" xyz="-0.03199999999999999 -0.0125 0"/>
      <geometry>
        <box size="0.074 0.025 0.001"/>
      </geometry>
    </collision>
  </link>
  <gazebo reference="pressure_sole_left_met1">
    <sensor name="pressure_sole_met1_sensor" type="contact">
      <always_on>true</always_on>
      <contact>
        <collision>ankle_plate_left_fixed_joint_lump__pressure_sole_left_met1_collision_4</collision>
      </contact>
      <plugin filename="libgazebo_ros_bumper.so" name="pressure_sole_plugin_met1">
        <bumperTopicName>march/sensor/left_pressure_sole_met1</bumperTopicName>
        <frameName>world</frameName>
      </plugin>
    </sensor>
  </gazebo>
  <gazebo reference="pressure_sole_left_met1">
    <mu1>1</mu1>
    <mu2>1</mu2>
    <minDepth>0.0005</minDepth>
    <fdir1>1 0 0</fdir1>
  </gazebo>
  <joint name="pressure_sole_left_met1_joint" type="fixed">
    <parent link="foot_left"/>
    <child link="pressure_sole_left_met1"/>
    <origin rpy="0 0 0" xyz="0 0 -0.025"/>
  </joint>
  <gazebo reference="pressure_sole_left">
    <mu1>1</mu1>
    <mu2>1</mu2>
    <minDepth>0.0005</minDepth>
    <fdir1>1 0 0</fdir1>
  </gazebo>
  <link name="pressure_sole_left_met3">
    <collision>
      <origin rpy="0 0 0" xyz="-0.106 -0.0125 0"/>
      <geometry>
        <box size="0.074 0.025 0.001"/>
      </geometry>
    </collision>
  </link>
  <gazebo reference="pressure_sole_left_met3">
    <sensor name="pressure_sole_met3_sensor" type="contact">
      <always_on>true</always_on>
      <contact>
        <collision>ankle_plate_left_fixed_joint_lump__pressure_sole_left_met3_collision_5</collision>
      </contact>
      <plugin filename="libgazebo_ros_bumper.so" name="pressure_sole_plugin_met3">
        <bumperTopicName>march/sensor/left_pressure_sole_met3</bumperTopicName>
        <frameName>world</frameName>
      </plugin>
    </sensor>
  </gazebo>
  <gazebo reference="pressure_sole_left_met3">
    <mu1>1</mu1>
    <mu2>1</mu2>
    <minDepth>0.0005</minDepth>
    <fdir1>1 0 0</fdir1>
  </gazebo>
  <joint name="pressure_sole_left_met3_joint" type="fixed">
    <parent link="foot_left"/>
    <child link="pressure_sole_left_met3"/>
    <origin rpy="0 0 0" xyz="0 0 -0.025"/>
  </joint>
  <gazebo reference="pressure_sole_left">
    <mu1>1</mu1>
    <mu2>1</mu2>
    <minDepth>0.0005</minDepth>
    <fdir1>1 0 0</fdir1>
  </gazebo>
  <link name="pressure_sole_left_met5">
    <collision>
      <origin rpy="0 0 0" xyz="-0.106 0.0125 0"/>
      <geometry>
        <box size="0.074 0.025 0.001"/>
      </geometry>
    </collision>
  </link>
  <gazebo reference="pressure_sole_left_met5">
    <sensor name="pressure_sole_met5_sensor" type="contact">
      <always_on>true</always_on>
      <contact>
        <collision>ankle_plate_left_fixed_joint_lump__pressure_sole_left_met5_collision_6</collision>
      </contact>
      <plugin filename="libgazebo_ros_bumper.so" name="pressure_sole_plugin_met5">
        <bumperTopicName>march/sensor/left_pressure_sole_met5</bumperTopicName>
        <frameName>world</frameName>
      </plugin>
    </sensor>
  </gazebo>
  <gazebo reference="pressure_sole_left_met5">
    <mu1>1</mu1>
    <mu2>1</mu2>
    <minDepth>0.0005</minDepth>
    <fdir1>1 0 0</fdir1>
  </gazebo>
  <joint name="pressure_sole_left_met5_joint" type="fixed">
    <parent link="foot_left"/>
    <child link="pressure_sole_left_met5"/>
    <origin rpy="0 0 0" xyz="0 0 -0.025"/>
  </joint>
  <gazebo reference="pressure_sole_left">
    <mu1>1</mu1>
    <mu2>1</mu2>
    <minDepth>0.0005</minDepth>
    <fdir1>1 0 0</fdir1>
  </gazebo>
  <link name="pressure_sole_left_toes">
    <collision>
      <origin rpy="0 0 0" xyz="-0.18 0.0125 0"/>
      <geometry>
        <box size="0.074 0.025 0.001"/>
      </geometry>
    </collision>
  </link>
  <gazebo reference="pressure_sole_left_toes">
    <sensor name="pressure_sole_toes_sensor" type="contact">
      <always_on>true</always_on>
      <contact>
        <collision>ankle_plate_left_fixed_joint_lump__pressure_sole_left_toes_collision_7</collision>
      </contact>
      <plugin filename="libgazebo_ros_bumper.so" name="pressure_sole_plugin_toes">
        <bumperTopicName>march/sensor/left_pressure_sole_toes</bumperTopicName>
        <frameName>world</frameName>
      </plugin>
    </sensor>
  </gazebo>
  <gazebo reference="pressure_sole_left_toes">
    <mu1>1</mu1>
    <mu2>1</mu2>
    <minDepth>0.0005</minDepth>
    <fdir1>1 0 0</fdir1>
  </gazebo>
  <joint name="pressure_sole_left_toes_joint" type="fixed">
    <parent link="foot_left"/>
    <child link="pressure_sole_left_toes"/>
    <origin rpy="0 0 0" xyz="0 0 -0.025"/>
  </joint>
  <gazebo reference="pressure_sole_left">
    <mu1>1</mu1>
    <mu2>1</mu2>
    <minDepth>0.0005</minDepth>
    <fdir1>1 0 0</fdir1>
  </gazebo>
  <link name="pressure_sole_left_hallux">
    <collision>
      <origin rpy="0 0 0" xyz="-0.18 -0.0125 0"/>
      <geometry>
        <box size="0.074 0.025 0.001"/>
      </geometry>
    </collision>
  </link>
  <gazebo reference="pressure_sole_left_hallux">
    <sensor name="pressure_sole_hallux_sensor" type="contact">
      <always_on>true</always_on>
      <contact>
        <collision>ankle_plate_left_fixed_joint_lump__pressure_sole_left_hallux_collision_3</collision>
      </contact>
      <plugin filename="libgazebo_ros_bumper.so" name="pressure_sole_plugin_hallux">
        <bumperTopicName>march/sensor/left_pressure_sole_hallux</bumperTopicName>
        <frameName>world</frameName>
      </plugin>
    </sensor>
  </gazebo>
  <gazebo reference="pressure_sole_left_hallux">
    <mu1>1</mu1>
    <mu2>1</mu2>
    <minDepth>0.0005</minDepth>
    <fdir1>1 0 0</fdir1>
  </gazebo>
  <joint name="pressure_sole_left_hallux_joint" type="fixed">
    <parent link="foot_left"/>
    <child link="pressure_sole_left_hallux"/>
    <origin rpy="0 0 0" xyz="0 0 -0.025"/>
  </joint>
  <gazebo reference="pressure_sole_left">
    <mu1>1</mu1>
    <mu2>1</mu2>
    <minDepth>0.0005</minDepth>
    <fdir1>1 0 0</fdir1>
  </gazebo>
  <link name="hip_aa_frame_right_side">
    <visual>
      <origin rpy="0 0 0" xyz="0 0 0"/>
      <geometry>
        <mesh filename="package://march_description/urdf/stl-files/march7/HipRight.stl" scale="1 1 1"/>
      </geometry>
      <material name="visuals_material"/>
    </visual>
    <collision>
      <origin rpy="0 0 0" xyz="0 0.115 0"/>
      <geometry>
        <box size="0.05 0.23 0.05"/>
      </geometry>
    </collision>
  </link>
  <link name="hip_aa_frame_right_front">
    <inertial>
      <origin rpy="0 0 0" xyz="-0.081906 -0.09724200000000005 0.029507"/>
      <mass value="3.019"/>
      <inertia ixx="0.068391" ixy="-0.0426776" ixz="0.000171569" iyy="0.0388633" iyz="0.00117041" izz="0.104156"/>
    </inertial>
    <collision>
      <origin rpy="0 0 0" xyz="-0.095 0 0"/>
      <geometry>
        <box size="0.19 0.05 0.05"/>
      </geometry>
    </collision>
  </link>
  &gt;
            
  <link name="upper_leg_right">
    <visual>
      <origin rpy="0 0 0" xyz="0 0 0"/>
      <geometry>
        <mesh filename="package://march_description/urdf/stl-files/march7/UpperLegRight.stl" scale="1 1 1"/>
      </geometry>
      <material name="visuals_material"/>
    </visual>
    <inertial>
      <origin rpy="0 0 0" xyz="0.000709 -0.07974600000000004 -0.19205"/>
      <mass value="8.161"/>
      <inertia ixx="1.68779" ixy="-0.0439623" ixz="0.249519" iyy="1.68452" iyz="0.0814673" izz="0.20142"/>
    </inertial>
    <collision>
      <origin rpy="0 0 0" xyz="0 0 -0.205"/>
      <geometry>
        <box size="0.05 0.05 0.41"/>
      </geometry>
    </collision>
  </link>
  &gt;
            
  <link name="lower_leg_right">
    <visual>
      <origin rpy="0 0 0" xyz="0 0 0"/>
      <geometry>
        <mesh filename="package://march_description/urdf/stl-files/march7/LowerLegRight.stl" scale="1 1 1"/>
      </geometry>
      <material name="visuals_material"/>
    </visual>
    <inertial>
      <origin rpy="0 0 0" xyz="-0.00321 -0.11091900000000005 -0.11708200000000007"/>
      <mass value="4.997"/>
      <inertia ixx="0.567226" ixy="0.00351928" ixz="0.0146315" iyy="0.561191" iyz="-0.019722" izz="0.0624652"/>
    </inertial>
    <collision>
      <origin rpy="0 0 0" xyz="0 0 -0.2"/>
      <geometry>
        <box size="0.05 0.05 0.4"/>
      </geometry>
    </collision>
  </link>
  &gt;
            
  <link name="ankle_plate_right">
    <visual>
      <origin rpy="0 0 0" xyz="0 0 0"/>
      <geometry>
        <mesh filename="package://march_description/urdf/stl-files/march7/FootRight.stl" scale="1 1 1"/>
      </geometry>
      <material name="visuals_material"/>
    </visual>
    <collision>
      <origin rpy="0 0 0" xyz="0 -0.07 -0.0325"/>
      <geometry>
        <box size="0.05 0.05 0.065"/>
      </geometry>
    </collision>
  </link>
  <link name="pressure_sole_right_heel_1">
    <collision>
      <origin rpy="0 0 0" xyz="0.042 0.0125 0"/>
      <geometry>
        <box size="0.074 0.025 0.001"/>
      </geometry>
    </collision>
  </link>
  <gazebo reference="pressure_sole_right_heel_1">
    <sensor name="pressure_sole_heel_1_sensor" type="contact">
      <always_on>true</always_on>
      <contact>
        <collision>ankle_plate_right_fixed_joint_lump__pressure_sole_right_heel_1_collision_8</collision>
      </contact>
      <plugin filename="libgazebo_ros_bumper.so" name="pressure_sole_plugin_heel_1">
        <bumperTopicName>march/sensor/right_pressure_sole_heel_1</bumperTopicName>
        <frameName>world</frameName>
      </plugin>
    </sensor>
  </gazebo>
  <gazebo reference="pressure_sole_right_heel_1">
    <mu1>1</mu1>
    <mu2>1</mu2>
    <minDepth>0.0005</minDepth>
    <fdir1>1 0 0</fdir1>
  </gazebo>
  <joint name="pressure_sole_right_heel_1_joint" type="fixed">
    <parent link="foot_right"/>
    <child link="pressure_sole_right_heel_1"/>
    <origin rpy="0 0 0" xyz="0 0 -0.025"/>
  </joint>
  <gazebo reference="pressure_sole_right">
    <mu1>1</mu1>
    <mu2>1</mu2>
    <minDepth>0.0005</minDepth>
    <fdir1>1 0 0</fdir1>
  </gazebo>
  <link name="pressure_sole_right_heel_2">
    <collision>
      <origin rpy="0 0 0" xyz="0.042 -0.0125 0"/>
      <geometry>
        <box size="0.074 0.025 0.001"/>
      </geometry>
    </collision>
  </link>
  <gazebo reference="pressure_sole_right_heel_2">
    <sensor name="pressure_sole_heel_2_sensor" type="contact">
      <always_on>true</always_on>
      <contact>
        <collision>ankle_plate_right_fixed_joint_lump__pressure_sole_right_heel_2_collision_9</collision>
      </contact>
      <plugin filename="libgazebo_ros_bumper.so" name="pressure_sole_plugin_heel_2">
        <bumperTopicName>march/sensor/right_pressure_sole_heel_2</bumperTopicName>
        <frameName>world</frameName>
      </plugin>
    </sensor>
  </gazebo>
  <gazebo reference="pressure_sole_right_heel_2">
    <mu1>1</mu1>
    <mu2>1</mu2>
    <minDepth>0.0005</minDepth>
    <fdir1>1 0 0</fdir1>
  </gazebo>
  <joint name="pressure_sole_right_heel_2_joint" type="fixed">
    <parent link="foot_right"/>
    <child link="pressure_sole_right_heel_2"/>
    <origin rpy="0 0 0" xyz="0 0 -0.025"/>
  </joint>
  <gazebo reference="pressure_sole_right">
    <mu1>1</mu1>
    <mu2>1</mu2>
    <minDepth>0.0005</minDepth>
    <fdir1>1 0 0</fdir1>
  </gazebo>
  <link name="pressure_sole_right_arch">
    <collision>
      <origin rpy="0 0 0" xyz="-0.03199999999999999 0.0125 0"/>
      <geometry>
        <box size="0.074 0.025 0.001"/>
      </geometry>
    </collision>
  </link>
  <gazebo reference="pressure_sole_right_arch">
    <sensor name="pressure_sole_arch_sensor" type="contact">
      <always_on>true</always_on>
      <contact>
        <collision>ankle_plate_right_fixed_joint_lump__pressure_sole_right_arch_collision_2</collision>
      </contact>
      <plugin filename="libgazebo_ros_bumper.so" name="pressure_sole_plugin_arch">
        <bumperTopicName>march/sensor/right_pressure_sole_arch</bumperTopicName>
        <frameName>world</frameName>
      </plugin>
    </sensor>
  </gazebo>
  <gazebo reference="pressure_sole_right_arch">
    <mu1>1</mu1>
    <mu2>1</mu2>
    <minDepth>0.0005</minDepth>
    <fdir1>1 0 0</fdir1>
  </gazebo>
  <joint name="pressure_sole_right_arch_joint" type="fixed">
    <parent link="foot_right"/>
    <child link="pressure_sole_right_arch"/>
    <origin rpy="0 0 0" xyz="0 0 -0.025"/>
  </joint>
  <gazebo reference="pressure_sole_right">
    <mu1>1</mu1>
    <mu2>1</mu2>
    <minDepth>0.0005</minDepth>
    <fdir1>1 0 0</fdir1>
  </gazebo>
  <link name="pressure_sole_right_met1">
    <collision>
      <origin rpy="0 0 0" xyz="-0.03199999999999999 -0.0125 0"/>
      <geometry>
        <box size="0.074 0.025 0.001"/>
      </geometry>
    </collision>
  </link>
  <gazebo reference="pressure_sole_right_met1">
    <sensor name="pressure_sole_met1_sensor" type="contact">
      <always_on>true</always_on>
      <contact>
        <collision>ankle_plate_right_fixed_joint_lump__pressure_sole_right_met1_collision_4</collision>
      </contact>
      <plugin filename="libgazebo_ros_bumper.so" name="pressure_sole_plugin_met1">
        <bumperTopicName>march/sensor/right_pressure_sole_met1</bumperTopicName>
        <frameName>world</frameName>
      </plugin>
    </sensor>
  </gazebo>
  <gazebo reference="pressure_sole_right_met1">
    <mu1>1</mu1>
    <mu2>1</mu2>
    <minDepth>0.0005</minDepth>
    <fdir1>1 0 0</fdir1>
  </gazebo>
  <joint name="pressure_sole_right_met1_joint" type="fixed">
    <parent link="foot_right"/>
    <child link="pressure_sole_right_met1"/>
    <origin rpy="0 0 0" xyz="0 0 -0.025"/>
  </joint>
  <gazebo reference="pressure_sole_right">
    <mu1>1</mu1>
    <mu2>1</mu2>
    <minDepth>0.0005</minDepth>
    <fdir1>1 0 0</fdir1>
  </gazebo>
  <link name="pressure_sole_right_met3">
    <collision>
      <origin rpy="0 0 0" xyz="-0.106 -0.0125 0"/>
      <geometry>
        <box size="0.074 0.025 0.001"/>
      </geometry>
    </collision>
  </link>
  <gazebo reference="pressure_sole_right_met3">
    <sensor name="pressure_sole_met3_sensor" type="contact">
      <always_on>true</always_on>
      <contact>
        <collision>ankle_plate_right_fixed_joint_lump__pressure_sole_right_met3_collision_5</collision>
      </contact>
      <plugin filename="libgazebo_ros_bumper.so" name="pressure_sole_plugin_met3">
        <bumperTopicName>march/sensor/right_pressure_sole_met3</bumperTopicName>
        <frameName>world</frameName>
      </plugin>
    </sensor>
  </gazebo>
  <gazebo reference="pressure_sole_right_met3">
    <mu1>1</mu1>
    <mu2>1</mu2>
    <minDepth>0.0005</minDepth>
    <fdir1>1 0 0</fdir1>
  </gazebo>
  <joint name="pressure_sole_right_met3_joint" type="fixed">
    <parent link="foot_right"/>
    <child link="pressure_sole_right_met3"/>
    <origin rpy="0 0 0" xyz="0 0 -0.025"/>
  </joint>
  <gazebo reference="pressure_sole_right">
    <mu1>1</mu1>
    <mu2>1</mu2>
    <minDepth>0.0005</minDepth>
    <fdir1>1 0 0</fdir1>
  </gazebo>
  <link name="pressure_sole_right_met5">
    <collision>
      <origin rpy="0 0 0" xyz="-0.106 0.0125 0"/>
      <geometry>
        <box size="0.074 0.025 0.001"/>
      </geometry>
    </collision>
  </link>
  <gazebo reference="pressure_sole_right_met5">
    <sensor name="pressure_sole_met5_sensor" type="contact">
      <always_on>true</always_on>
      <contact>
        <collision>ankle_plate_right_fixed_joint_lump__pressure_sole_right_met5_collision_6</collision>
      </contact>
      <plugin filename="libgazebo_ros_bumper.so" name="pressure_sole_plugin_met5">
        <bumperTopicName>march/sensor/right_pressure_sole_met5</bumperTopicName>
        <frameName>world</frameName>
      </plugin>
    </sensor>
  </gazebo>
  <gazebo reference="pressure_sole_right_met5">
    <mu1>1</mu1>
    <mu2>1</mu2>
    <minDepth>0.0005</minDepth>
    <fdir1>1 0 0</fdir1>
  </gazebo>
  <joint name="pressure_sole_right_met5_joint" type="fixed">
    <parent link="foot_right"/>
    <child link="pressure_sole_right_met5"/>
    <origin rpy="0 0 0" xyz="0 0 -0.025"/>
  </joint>
  <gazebo reference="pressure_sole_right">
    <mu1>1</mu1>
    <mu2>1</mu2>
    <minDepth>0.0005</minDepth>
    <fdir1>1 0 0</fdir1>
  </gazebo>
  <link name="pressure_sole_right_toes">
    <collision>
      <origin rpy="0 0 0" xyz="-0.18 0.0125 0"/>
      <geometry>
        <box size="0.074 0.025 0.001"/>
      </geometry>
    </collision>
  </link>
  <gazebo reference="pressure_sole_right_toes">
    <sensor name="pressure_sole_toes_sensor" type="contact">
      <always_on>true</always_on>
      <contact>
        <collision>ankle_plate_right_fixed_joint_lump__pressure_sole_right_toes_collision_7</collision>
      </contact>
      <plugin filename="libgazebo_ros_bumper.so" name="pressure_sole_plugin_toes">
        <bumperTopicName>march/sensor/right_pressure_sole_toes</bumperTopicName>
        <frameName>world</frameName>
      </plugin>
    </sensor>
  </gazebo>
  <gazebo reference="pressure_sole_right_toes">
    <mu1>1</mu1>
    <mu2>1</mu2>
    <minDepth>0.0005</minDepth>
    <fdir1>1 0 0</fdir1>
  </gazebo>
  <joint name="pressure_sole_right_toes_joint" type="fixed">
    <parent link="foot_right"/>
    <child link="pressure_sole_right_toes"/>
    <origin rpy="0 0 0" xyz="0 0 -0.025"/>
  </joint>
  <gazebo reference="pressure_sole_right">
    <mu1>1</mu1>
    <mu2>1</mu2>
    <minDepth>0.0005</minDepth>
    <fdir1>1 0 0</fdir1>
  </gazebo>
  <link name="pressure_sole_right_hallux">
    <collision>
      <origin rpy="0 0 0" xyz="-0.18 -0.0125 0"/>
      <geometry>
        <box size="0.074 0.025 0.001"/>
      </geometry>
    </collision>
  </link>
  <gazebo reference="pressure_sole_right_hallux">
    <sensor name="pressure_sole_hallux_sensor" type="contact">
      <always_on>true</always_on>
      <contact>
        <collision>ankle_plate_right_fixed_joint_lump__pressure_sole_right_hallux_collision_3</collision>
      </contact>
      <plugin filename="libgazebo_ros_bumper.so" name="pressure_sole_plugin_hallux">
        <bumperTopicName>march/sensor/right_pressure_sole_hallux</bumperTopicName>
        <frameName>world</frameName>
      </plugin>
    </sensor>
  </gazebo>
  <gazebo reference="pressure_sole_right_hallux">
    <mu1>1</mu1>
    <mu2>1</mu2>
    <minDepth>0.0005</minDepth>
    <fdir1>1 0 0</fdir1>
  </gazebo>
  <joint name="pressure_sole_right_hallux_joint" type="fixed">
    <parent link="foot_right"/>
    <child link="pressure_sole_right_hallux"/>
    <origin rpy="0 0 0" xyz="0 0 -0.025"/>
  </joint>
  <gazebo reference="pressure_sole_right">
    <mu1>1</mu1>
    <mu2>1</mu2>
    <minDepth>0.0005</minDepth>
    <fdir1>1 0 0</fdir1>
  </gazebo>
  <link name="foot_right">
    <inertial>
      <origin rpy="0 0 0" xyz="-0.028926 -0.12908400000000003 0.08521199999999995"/>
      <mass value="0.789"/>
      <inertia ixx="0.00388523" ixy="-0.00209516" ixz="-0.00189858" iyy="0.00659119" iyz="-0.00168033" izz="0.00630322"/>
    </inertial>
    <collision>
      <origin rpy="0 0 0" xyz="-0.069 0 0"/>
      <geometry>
        <box size="0.296 0.05 0.05"/>
      </geometry>
    </collision>
  </link>
  <!-- Joints -->
  <joint name="imu_joint" type="fixed">
    <parent link="world"/>
    <child link="imu_link"/>
  </joint>
  <joint name="hip" type="fixed">
    <parent link="imu_link"/>
    <child link="hip_base"/>
    <origin rpy="0 0 0" xyz="0 0 0"/>
  </joint>
  <joint name="left_hip_aa" type="revolute">
    <parent link="hip_base"/>
    <child link="hip_aa_frame_left_side"/>
    <origin rpy="0 0 0" xyz="0 -0.065 0"/>
    <axis xyz="-1 0 0"/>
    <limit effort="30.0" lower="-0.1932815792735908" upper="0.20248546400090464" velocity="2.5"/>
    <safety_controller k_position="6.6430091259949355" k_velocity="28.775519491677287" soft_lower_limit="-0.18979092076960213" soft_upper_limit="0.19899480549691598"/>
  </joint>
  <transmission name="left_hip_aa">
    <type>transmission_interface/SimpleTransmission</type>
    <joint name="left_hip_aa">
      <hardwareInterface>hardware_interface/EffortJointInterface</hardwareInterface>
    </joint>
    <actuator name="left_hip_aa_motor">
      <mechanicalReduction>
                    240
                </mechanicalReduction>
    </actuator>
  </transmission>
  <joint name="left_hip_angle" type="fixed">
    <parent link="hip_aa_frame_left_side"/>
    <child link="hip_aa_frame_left_front"/>
    <origin rpy="0 0 0" xyz="0 -0.23 0"/>
  </joint>
  <joint name="left_hip_fe" type="revolute">
    <parent link="hip_aa_frame_left_front"/>
    <child link="upper_leg_left"/>
    <origin rpy="0 0 0" xyz="-0.19 0.0 0"/>
    <axis xyz="0 1 0"/>
    <limit effort="30.0" lower="-0.37755102141835345" upper="1.8026191733641141" velocity="3.0"/>
    <safety_controller k_position="3.3401714863487983" k_velocity="6.105877562284971" soft_lower_limit="-0.34264443637846687" soft_upper_limit="1.7677125883242275"/>
  </joint>
  <transmission name="left_hip_fe">
    <type>transmission_interface/SimpleTransmission</type>
    <joint name="left_hip_fe">
      <hardwareInterface>hardware_interface/EffortJointInterface</hardwareInterface>
    </joint>
    <actuator name="left_hip_fe_motor">
      <mechanicalReduction>
                    121.19999999999999
                </mechanicalReduction>
    </actuator>
  </transmission>
  <joint name="left_knee" type="revolute">
    <parent link="upper_leg_left"/>
    <child link="lower_leg_left"/>
    <origin rpy="0 0 0" xyz="0 0.07 -0.41"/>
    <axis xyz="0 -1 0"/>
    <limit effort="30.0" lower="-0.10258496518985226" upper="1.9959966264369478" velocity="3.5"/>
    <safety_controller k_position="9.656085595298899" k_velocity="23.06987607064259" soft_lower_limit="-0.06767838014996566" soft_upper_limit="1.9610900413970611"/>
  </joint>
  <transmission name="left_knee">
    <type>transmission_interface/SimpleTransmission</type>
    <joint name="left_knee">
      <hardwareInterface>hardware_interface/EffortJointInterface</hardwareInterface>
    </joint>
    <actuator name="left_knee_motor">
      <mechanicalReduction>
                    121.19999999999999
                </mechanicalReduction>
    </actuator>
  </transmission>
  <joint name="left_ankle" type="revolute">
    <parent link="lower_leg_left"/>
    <child link="ankle_plate_left"/>
    <origin rpy="0 0 0" xyz="0 0.01 -0.4"/>
    <axis xyz="0 1 0"/>
    <limit effort="30.0" lower="-0.6285486278361415" upper="0.2726650850466727" velocity="2.5"/>
    <safety_controller k_position="7.692354754168206" k_velocity="2.246279388462071" soft_lower_limit="-0.5936420427962549" soft_upper_limit="0.26917442654268403"/>
  </joint>
  <transmission name="left_ankle">
    <type>transmission_interface/SimpleTransmission</type>
    <joint name="left_ankle">
      <hardwareInterface>hardware_interface/EffortJointInterface</hardwareInterface>
    </joint>
    <actuator name="left_ankle_motor">
      <mechanicalReduction>
                    236
                </mechanicalReduction>
    </actuator>
  </transmission>
  <joint name="left_foot_angle" type="fixed">
    <parent link="ankle_plate_left"/>
    <child link="foot_left"/>
    <origin rpy="0 0 0" xyz="0 0.07 -0.09"/>
  </joint>
  <joint name="right_hip_aa" type="revolute">
    <parent link="hip_base"/>
    <child link="hip_aa_frame_right_side"/>
    <origin rpy="0 0 0" xyz="0 0.065 0"/>
    <axis xyz="1 0 0"/>
    <limit effort="30.0" lower="-0.17065536265227757" upper="0.22664566141010348" velocity="2.5"/>
    <safety_controller k_position="6.6430091259949355" k_velocity="28.775519491677287" soft_lower_limit="-0.1671647041482889" soft_upper_limit="0.2231550029061148"/>
  </joint>
  <transmission name="right_hip_aa">
    <type>transmission_interface/SimpleTransmission</type>
    <joint name="right_hip_aa">
      <hardwareInterface>hardware_interface/EffortJointInterface</hardwareInterface>
    </joint>
    <actuator name="right_hip_aa_motor">
      <mechanicalReduction>
                    236
                </mechanicalReduction>
    </actuator>
  </transmission>
  <joint name="right_hip_angle" type="fixed">
    <parent link="hip_aa_frame_right_side"/>
    <child link="hip_aa_frame_right_front"/>
    <origin rpy="0 0 0" xyz="0 0.23 0"/>
  </joint>
  <joint name="right_hip_fe" type="revolute">
    <parent link="hip_aa_frame_right_front"/>
    <child link="upper_leg_right"/>
    <origin rpy="0 0 0" xyz="-0.19 -0.0 0"/>
    <axis xyz="0 1 0"/>
    <limit effort="30.0" lower="-0.41398306513063743" upper="1.8146033982694707" velocity="3.0"/>
    <safety_controller k_position="3.3401714863487983" k_velocity="6.105877562284971" soft_lower_limit="-0.37907648009075084" soft_upper_limit="1.779696813229584"/>
  </joint>
  <transmission name="right_hip_fe">
    <type>transmission_interface/SimpleTransmission</type>
    <joint name="right_hip_fe">
      <hardwareInterface>hardware_interface/EffortJointInterface</hardwareInterface>
    </joint>
    <actuator name="right_hip_fe_motor">
      <mechanicalReduction>
                    121.19999999999999
                </mechanicalReduction>
    </actuator>
  </transmission>
  <joint name="right_knee" type="revolute">
    <parent link="upper_leg_right"/>
    <child link="lower_leg_right"/>
    <origin rpy="0 0 0" xyz="0 -0.07 -0.41"/>
    <axis xyz="0 -1 0"/>
    <limit effort="30.0" lower="-0.09951700361408097" upper="2.002899539982433" velocity="3.5"/>
    <safety_controller k_position="9.656085595298899" k_velocity="23.06987607064259" soft_lower_limit="-0.06461041857419439" soft_upper_limit="1.9679929549425466"/>
  </joint>
  <transmission name="right_knee">
    <type>transmission_interface/SimpleTransmission</type>
    <joint name="right_knee">
      <hardwareInterface>hardware_interface/EffortJointInterface</hardwareInterface>
    </joint>
    <actuator name="right_knee_motor">
      <mechanicalReduction>
                    121.19999999999999
                </mechanicalReduction>
    </actuator>
  </transmission>
  <joint name="right_ankle" type="revolute">
    <parent link="lower_leg_right"/>
    <child link="ankle_plate_right"/>
    <origin rpy="0 0 0" xyz="0 -0.01 -0.4"/>
    <axis xyz="0 1 0"/>
    <limit effort="30.0" lower="-0.6189612479118562" upper="0.230864108576789" velocity="2.5"/>
    <safety_controller k_position="7.692354754168206" k_velocity="2.246279388462071" soft_lower_limit="-0.5840546628719696" soft_upper_limit="0.22737345007280033"/>
  </joint>
  <transmission name="right_ankle">
    <type>transmission_interface/SimpleTransmission</type>
    <joint name="right_ankle">
      <hardwareInterface>hardware_interface/EffortJointInterface</hardwareInterface>
    </joint>
    <actuator name="right_ankle_motor">
      <mechanicalReduction>
                    236
                </mechanicalReduction>
    </actuator>
  </transmission>
  <joint name="right_foot_angle" type="fixed">
    <parent link="ankle_plate_right"/>
    <child link="foot_right"/>
    <origin rpy="0 0 0" xyz="0 -0.07 -0.09"/>
  </joint>
  <material name="camera_front_right_aluminum">
    <color rgba="0.5 0.5 0.5 1"/>
  </material>
  <!-- camera body, with origin at bottom screw mount -->
  <joint name="camera_front_right_joint" type="fixed">
    <origin rpy="0.0 1.064650843716541 3.141592653589793" xyz="-0.07 -0.011 -0.007 "/>
    <parent link="upper_leg_right"/>
    <child link="camera_front_right_bottom_screw_frame"/>
  </joint>
  <link name="camera_front_right_bottom_screw_frame"/>
  <joint name="camera_front_right_link_joint" type="fixed">
    <origin rpy="0 0 0" xyz="0 0.0175 0.0125"/>
    <parent link="camera_front_right_bottom_screw_frame"/>
    <child link="camera_front_right_link"/>
  </joint>
  <link name="camera_front_right_link">
    <visual>
      <origin rpy="1.5707963267948966 0 1.5707963267948966" xyz="0.0149 -0.0175 0"/>
      <geometry>
        <!-- <box size="${d435_cam_width} ${d435_cam_height} ${d435_cam_depth}"/> -->
        <mesh filename="package://march_description/urdf/camera/_d435.dae"/>
      </geometry>
      <material name="camera_front_right_aluminum"/>
    </visual>
    <collision>
      <origin rpy="0 0 0" xyz="0 -0.0175 0"/>
      <geometry>
        <box size="0.02505 0.09 0.025"/>
      </geometry>
    </collision>
    <inertial>
      <!-- The following are not reliable values, and should not be used for modeling -->
      <mass value="0.564"/>
      <origin xyz="0 0 0"/>
      <inertia ixx="0.003881243" ixy="0.0" ixz="0.0" iyy="0.000498940" iyz="0.0" izz="0.003879257"/>
    </inertial>
  </link>
  <!-- camera depth joints and links -->
  <joint name="camera_front_right_depth_joint" type="fixed">
    <origin rpy="0 0 0" xyz="0 0 0"/>
    <parent link="camera_front_right_link"/>
    <child link="camera_front_right_depth_frame"/>
  </joint>
  <link name="camera_front_right_depth_frame"/>
  <joint name="camera_front_right_depth_optical_joint" type="fixed">
    <origin rpy="-1.5707963267948966 0 -1.5707963267948966" xyz="0 0 0"/>
    <parent link="camera_front_right_depth_frame"/>
    <child link="camera_front_right_depth_optical_frame"/>
  </joint>
  <link name="camera_front_right_depth_optical_frame"/>
  <!-- camera left IR joints and links -->
  <joint name="camera_front_right_left_ir_joint" type="fixed">
    <origin rpy="0 0 0" xyz="0 0.0 0"/>
    <parent link="camera_front_right_depth_frame"/>
    <child link="camera_front_right_left_ir_frame"/>
  </joint>
  <link name="camera_front_right_left_ir_frame"/>
  <joint name="camera_front_right_left_ir_optical_joint" type="fixed">
    <origin rpy="-1.5707963267948966 0 -1.5707963267948966" xyz="0 0 0"/>
    <parent link="camera_front_right_left_ir_frame"/>
    <child link="camera_front_right_left_ir_optical_frame"/>
  </joint>
  <link name="camera_front_right_left_ir_optical_frame"/>
  <!-- camera right IR joints and links -->
  <joint name="camera_front_right_right_ir_joint" type="fixed">
    <origin rpy="0 0 0" xyz="0 -0.05 0"/>
    <parent link="camera_front_right_depth_frame"/>
    <child link="camera_front_right_right_ir_frame"/>
  </joint>
  <link name="camera_front_right_right_ir_frame"/>
  <joint name="camera_front_right_right_ir_optical_joint" type="fixed">
    <origin rpy="-1.5707963267948966 0 -1.5707963267948966" xyz="0 0 0"/>
    <parent link="camera_front_right_right_ir_frame"/>
    <child link="camera_front_right_right_ir_optical_frame"/>
  </joint>
  <link name="camera_front_right_right_ir_optical_frame"/>
  <!-- camera color joints and links -->
  <joint name="camera_front_right_color_joint" type="fixed">
    <origin rpy="0 0 0" xyz="0 0.015 0"/>
    <parent link="camera_front_right_depth_frame"/>
    <child link="camera_front_right_color_frame"/>
  </joint>
  <link name="camera_front_right_color_frame"/>
  <joint name="camera_front_right_color_optical_joint" type="fixed">
    <origin rpy="-1.5707963267948966 0 -1.5707963267948966" xyz="0 0 0"/>
    <parent link="camera_front_right_color_frame"/>
    <child link="camera_front_right_color_optical_frame"/>
  </joint>
  <link name="camera_front_right_color_optical_frame"/>
  <link name="camera_front_right_imu_optical_frame"/>
  <joint name="camera_front_right_imu_optical_joint" type="fixed">
    <origin rpy="-1.5707963267948966 0 -1.5707963267948966" xyz="0 0 0"/>
    <parent link="camera_front_right_depth_frame"/>
    <child link="camera_front_right_imu_optical_frame"/>
  </joint>
  <material name="camera_front_left_aluminum">
    <color rgba="0.5 0.5 0.5 1"/>
  </material>
  <!-- camera body, with origin at bottom screw mount -->
  <joint name="camera_front_left_joint" type="fixed">
    <origin rpy="0.0 2.076941809873252 0.0" xyz="-0.094 0.011 0.005 "/>
    <parent link="upper_leg_left"/>
    <child link="camera_front_left_bottom_screw_frame"/>
  </joint>
  <link name="camera_front_left_bottom_screw_frame"/>
  <joint name="camera_front_left_link_joint" type="fixed">
    <origin rpy="0 0 0" xyz="0 0.0175 0.0125"/>
    <parent link="camera_front_left_bottom_screw_frame"/>
    <child link="camera_front_left_link"/>
  </joint>
  <link name="camera_front_left_link">
    <visual>
      <origin rpy="1.5707963267948966 0 1.5707963267948966" xyz="0.0149 -0.0175 0"/>
      <geometry>
        <!-- <box size="${d435_cam_width} ${d435_cam_height} ${d435_cam_depth}"/> -->
        <mesh filename="package://march_description/urdf/camera/_d435.dae"/>
      </geometry>
      <material name="camera_front_left_aluminum"/>
    </visual>
    <collision>
      <origin rpy="0 0 0" xyz="0 -0.0175 0"/>
      <geometry>
        <box size="0.02505 0.09 0.025"/>
      </geometry>
    </collision>
    <inertial>
      <!-- The following are not reliable values, and should not be used for modeling -->
      <mass value="0.564"/>
      <origin xyz="0 0 0"/>
      <inertia ixx="0.003881243" ixy="0.0" ixz="0.0" iyy="0.000498940" iyz="0.0" izz="0.003879257"/>
    </inertial>
  </link>
  <!-- camera depth joints and links -->
  <joint name="camera_front_left_depth_joint" type="fixed">
    <origin rpy="0 0 0" xyz="0 0 0"/>
    <parent link="camera_front_left_link"/>
    <child link="camera_front_left_depth_frame"/>
  </joint>
  <link name="camera_front_left_depth_frame"/>
  <joint name="camera_front_left_depth_optical_joint" type="fixed">
    <origin rpy="-1.5707963267948966 0 -1.5707963267948966" xyz="0 0 0"/>
    <parent link="camera_front_left_depth_frame"/>
    <child link="camera_front_left_depth_optical_frame"/>
  </joint>
  <link name="camera_front_left_depth_optical_frame"/>
  <!-- camera left IR joints and links -->
  <joint name="camera_front_left_left_ir_joint" type="fixed">
    <origin rpy="0 0 0" xyz="0 0.0 0"/>
    <parent link="camera_front_left_depth_frame"/>
    <child link="camera_front_left_left_ir_frame"/>
  </joint>
  <link name="camera_front_left_left_ir_frame"/>
  <joint name="camera_front_left_left_ir_optical_joint" type="fixed">
    <origin rpy="-1.5707963267948966 0 -1.5707963267948966" xyz="0 0 0"/>
    <parent link="camera_front_left_left_ir_frame"/>
    <child link="camera_front_left_left_ir_optical_frame"/>
  </joint>
  <link name="camera_front_left_left_ir_optical_frame"/>
  <!-- camera right IR joints and links -->
  <joint name="camera_front_left_right_ir_joint" type="fixed">
    <origin rpy="0 0 0" xyz="0 -0.05 0"/>
    <parent link="camera_front_left_depth_frame"/>
    <child link="camera_front_left_right_ir_frame"/>
  </joint>
  <link name="camera_front_left_right_ir_frame"/>
  <joint name="camera_front_left_right_ir_optical_joint" type="fixed">
    <origin rpy="-1.5707963267948966 0 -1.5707963267948966" xyz="0 0 0"/>
    <parent link="camera_front_left_right_ir_frame"/>
    <child link="camera_front_left_right_ir_optical_frame"/>
  </joint>
  <link name="camera_front_left_right_ir_optical_frame"/>
  <!-- camera color joints and links -->
  <joint name="camera_front_left_color_joint" type="fixed">
    <origin rpy="0 0 0" xyz="0 0.015 0"/>
    <parent link="camera_front_left_depth_frame"/>
    <child link="camera_front_left_color_frame"/>
  </joint>
  <link name="camera_front_left_color_frame"/>
  <joint name="camera_front_left_color_optical_joint" type="fixed">
    <origin rpy="-1.5707963267948966 0 -1.5707963267948966" xyz="0 0 0"/>
    <parent link="camera_front_left_color_frame"/>
    <child link="camera_front_left_color_optical_frame"/>
  </joint>
  <link name="camera_front_left_color_optical_frame"/>
  <link name="camera_front_left_imu_optical_frame"/>
  <joint name="camera_front_left_imu_optical_joint" type="fixed">
    <origin rpy="-1.5707963267948966 0 -1.5707963267948966" xyz="0 0 0"/>
    <parent link="camera_front_left_depth_frame"/>
    <child link="camera_front_left_imu_optical_frame"/>
  </joint>
  <material name="camera_back_aluminum">
    <color rgba="0.5 0.5 0.5 1"/>
  </material>
  <!-- camera body, with origin at bottom screw mount -->
  <joint name="camera_back_joint" type="fixed">
    <origin rpy="0 1.3089969389957472 0" xyz="0.018 0.126 -0.018"/>
    <parent link="hip_aa_frame_right_side"/>
    <child link="camera_back_bottom_screw_frame"/>
  </joint>
  <link name="camera_back_bottom_screw_frame"/>
  <joint name="camera_back_link_joint" type="fixed">
    <origin rpy="0 0 0" xyz="0 0.0175 0.0125"/>
    <parent link="camera_back_bottom_screw_frame"/>
    <child link="camera_back_link"/>
  </joint>
  <link name="camera_back_link">
    <visual>
      <origin rpy="1.5707963267948966 0 1.5707963267948966" xyz="0.0149 -0.0175 0"/>
      <geometry>
        <!-- <box size="${d435_cam_width} ${d435_cam_height} ${d435_cam_depth}"/> -->
        <mesh filename="package://march_description/urdf/camera/_d435.dae"/>
      </geometry>
      <material name="camera_back_aluminum"/>
    </visual>
    <collision>
      <origin rpy="0 0 0" xyz="0 -0.0175 0"/>
      <geometry>
        <box size="0.02505 0.09 0.025"/>
      </geometry>
    </collision>
    <inertial>
      <!-- The following are not reliable values, and should not be used for modeling -->
      <mass value="0.564"/>
      <origin xyz="0 0 0"/>
      <inertia ixx="0.003881243" ixy="0.0" ixz="0.0" iyy="0.000498940" iyz="0.0" izz="0.003879257"/>
    </inertial>
  </link>
  <!-- camera depth joints and links -->
  <joint name="camera_back_depth_joint" type="fixed">
    <origin rpy="0 0 0" xyz="0 0 0"/>
    <parent link="camera_back_link"/>
    <child link="camera_back_depth_frame"/>
  </joint>
  <link name="camera_back_depth_frame"/>
  <joint name="camera_back_depth_optical_joint" type="fixed">
    <origin rpy="-1.5707963267948966 0 -1.5707963267948966" xyz="0 0 0"/>
    <parent link="camera_back_depth_frame"/>
    <child link="camera_back_depth_optical_frame"/>
  </joint>
  <link name="camera_back_depth_optical_frame"/>
  <!-- camera left IR joints and links -->
  <joint name="camera_back_left_ir_joint" type="fixed">
    <origin rpy="0 0 0" xyz="0 0.0 0"/>
    <parent link="camera_back_depth_frame"/>
    <child link="camera_back_left_ir_frame"/>
  </joint>
  <link name="camera_back_left_ir_frame"/>
  <joint name="camera_back_left_ir_optical_joint" type="fixed">
    <origin rpy="-1.5707963267948966 0 -1.5707963267948966" xyz="0 0 0"/>
    <parent link="camera_back_left_ir_frame"/>
    <child link="camera_back_left_ir_optical_frame"/>
  </joint>
  <link name="camera_back_left_ir_optical_frame"/>
  <!-- camera right IR joints and links -->
  <joint name="camera_back_right_ir_joint" type="fixed">
    <origin rpy="0 0 0" xyz="0 -0.05 0"/>
    <parent link="camera_back_depth_frame"/>
    <child link="camera_back_right_ir_frame"/>
  </joint>
  <link name="camera_back_right_ir_frame"/>
  <joint name="camera_back_right_ir_optical_joint" type="fixed">
    <origin rpy="-1.5707963267948966 0 -1.5707963267948966" xyz="0 0 0"/>
    <parent link="camera_back_right_ir_frame"/>
    <child link="camera_back_right_ir_optical_frame"/>
  </joint>
  <link name="camera_back_right_ir_optical_frame"/>
  <!-- camera color joints and links -->
  <joint name="camera_back_color_joint" type="fixed">
    <origin rpy="0 0 0" xyz="0 0.015 0"/>
    <parent link="camera_back_depth_frame"/>
    <child link="camera_back_color_frame"/>
  </joint>
  <link name="camera_back_color_frame"/>
  <joint name="camera_back_color_optical_joint" type="fixed">
    <origin rpy="-1.5707963267948966 0 -1.5707963267948966" xyz="0 0 0"/>
    <parent link="camera_back_color_frame"/>
    <child link="camera_back_color_optical_frame"/>
  </joint>
  <link name="camera_back_color_optical_frame"/>
  <link name="camera_back_imu_optical_frame"/>
  <joint name="camera_back_imu_optical_joint" type="fixed">
    <origin rpy="-1.5707963267948966 0 -1.5707963267948966" xyz="0 0 0"/>
    <parent link="camera_back_depth_frame"/>
    <child link="camera_back_imu_optical_frame"/>
  </joint>
  <link name="camera_imu_optical_frame"/>
  <joint name="camera_imu_optical_joint" type="fixed">
    <origin rpy="0 0 0" xyz="0 0 0"/>
    <parent link="camera_back_imu_optical_frame"/>
    <child link="camera_imu_optical_frame"/>
  </joint>
</robot>
