<!-- Copyright 2021 DeepMind Technologies Limited

     Licensed under the Apache License, Version 2.0 (the "License");
     you may not use this file except in compliance with the License.
     You may obtain a copy of the License at

         http://www.apache.org/licenses/LICENSE-2.0

     Unless required by applicable law or agreed to in writing, software
     distributed under the License is distributed on an "AS IS" BASIS,
     WITHOUT WARRANTIES OR CONDITIONS OF ANY KIND, either express or implied.
     See the License for the specific language governing permissions and
     limitations under the License.
-->

<mujoco model="MARCH">
<!-- Degree of Freedom: 27
     Actuators: 21

     This simplified humanoid model, introduced in [1], is designed for bipedal locomotion
     behaviours. While several variants of it exist in the wild, this version is based on the model
     in the DeepMind Control Suite [2], which has fairly realistic actuator gains.
     [1] Synthesis and Stabilization of Complex Behaviors through Online Trajectory Optimization.
           https://doi.org/10.1109/IROS.2012.6386025
     [2] DeepMind Control Suite, Tassa et al. https://arxiv.org/abs/1801.00690
-->
  <option timestep="0.005"/>

  <asset>
    <texture type="skybox" builtin="gradient" rgb1=".3 .5 .7" rgb2="0 0 0" width="512" height="512"/>
    <texture name="body" type="cube" builtin="flat" mark="cross" width="127" height="1278"
             rgb1="0.8 0.6 0.4" rgb2="0.8 0.6 0.4" markrgb="1 1 1" random="0.01"/>
    <material name="body" texture="body" texuniform="true" rgba="0.8 0.6 .4 1"/>
    <texture name="grid" type="2d" builtin="checker" width="512" height="512" rgb1=".1 .2 .3" rgb2=".2 .3 .4"/>
    <material name="grid" texture="grid" texrepeat="1 1" texuniform="true" reflectance=".2"/>
  </asset>

  <default>
    <motor ctrlrange="-1 1" ctrllimited="true"/>
    <default class="body">
      <geom type="capsule" condim="1" friction=".7" solimp=".9 .99 .003" solref=".015 1" material="body"/>
      <joint type="hinge" damping=".2" stiffness="1" armature=".01" limited="true" solimplimit="0 .99 .01"/>
      <default class="big_joint">
        <joint damping="5" stiffness="30"/>
        <default class="big_stiff_joint">
          <joint stiffness="50"/>
        </default>
      </default>
    </default>
  </default>

  <visual>
    <map force="0.1" zfar="30"/>
    <rgba haze="0.15 0.25 0.35 1"/>
    <quality shadowsize="4096"/>
    <global offwidth="800" offheight="800"/>
  </visual>

  <worldbody>
    <geom name="floor" size="0 0 .05" type="plane" material="grid" condim="3"/>
    <light name="spotlight" mode="targetbodycom" target="torso"
           diffuse=".8 .8 .8" specular="0.3 0.3 0.3" pos="0 -20 4" cutoff="10"/>
    <body name="torso" pos="0 0 1.0" childclass="body">
      <light name="top" pos="0 0 2" mode="trackcom"/>
      <camera name="diag" pos="1.1 -1.1 0.1" xyaxes="1 1 0 0 1 2" mode="trackcom"/>
      <camera name="side" pos="0 -3 1" xyaxes="1 0 0 0 1 2" mode="trackcom"/>
      <freejoint name="root"/>
      <geom name="butt" fromto="-.02 -.04 0 -.02 .04 0" size=".09"/>
      <body name="right_hip" pos="0 -.075 -.09">
        <joint name="R_HAA" axis="1 0 0" range="-25 5" class="big_joint"/>
        <geom name="right_hip" fromto="0 0 0 0 -.1 0" size=".049"/>
          <body name="right_thigh" pos=".1 -.1 0">
            <joint name="R_HFE" axis="0 1 0" range="-110 20" class="big_stiff_joint"/>
            <geom name="right_thigh" fromto="0 0 0 0 .01 -.34" size=".06"/>
            <body name="right_shin" pos="0 .01 -.403">
              <joint name="R_KFE" pos="0 0 .02" axis="0 -1 0" range="-160 2"/>
              <geom name="right_shin" fromto="0 0 0 0 0 -.3"  size=".049"/>
              <body name="right_foot" pos="0 0 -.39">
                <joint name="R_ADPF" pos="0 0 .08" axis="0 1 0" range="-50 50" stiffness="6"/>
                <geom name="right_foot" type="box" pos="0.05 .05 0.05" size=".1 .05 .03"/>
              </body>
            </body>
          </body>
      </body>
      <body name="left_hip" pos="0 .075 -.09">
        <joint name="L_HAA" axis="-1 0 0" range="-25 5" class="big_joint"/>
        <geom name="left_hip" fromto="0 0 0 0 .1 0" size=".049"/>
        <body name="left_thigh" pos=".1 .1 0">
          <joint name="L_HFE" axis="0 1 0" range="-110 20" class="big_stiff_joint"/>
          <geom name="left_thigh" fromto="0 0 0 0 -.01 -.34" size=".06"/>
          <body name="left_shin" pos="0 -.01 -.403">
            <joint name="L_KFE" pos="0 0 .02" axis="0 -1 0" range="-160 2"/>
            <geom name="left_shin" fromto="0 0 0 0 0 -.3"  size=".049"/>
            <body name="left_foot" pos="0 0 -.39">
              <joint name="L_ADPF" pos="0 0 .08" axis="0 1 0" range="-50 50" stiffness="6"/>
              <geom name="left_foot" type="box" pos="0.05 -.05 0.05" size=".1 .05 .03"/>
            </body>
          </body>
        </body>
      </body>
    </body>
  </worldbody>

  <actuator>
    <motor name="R_HAA"     gear="40"  joint="R_HAA"/>
    <motor name="R_HFE"     gear="120" joint="R_HFE"/>
    <motor name="R_KFE"      gear="80"  joint="R_KFE"/>
    <motor name="R_ADPF"   gear="20"  joint="R_ADPF"/>
    <motor name="L_HAA"      gear="40"  joint="L_HAA"/>
    <motor name="L_HFE"      gear="120" joint="L_HFE"/>
    <motor name="L_KFE"       gear="80"  joint="L_KFE"/>
    <motor name="L_ADPF"    gear="20"  joint="L_ADPF"/>
  </actuator>
</mujoco>
