<?xml version="1.0" ?>
<!-- =================================================================================== -->
<!-- |    This document was autogenerated by xacro from march6_three_cameras.xacro     | -->
<!-- |    EDITING THIS FILE BY HAND IS NOT RECOMMENDED                                 | -->
<!-- =================================================================================== -->
<!-- Revolute-Revolute Manipulator -->
<robot name="march">
  <!-- Square dimensions (widthxwidth) of beams -->
  <!-- mass = Hip base + HAA actuators -->
  <!-- mass = Moving hip -->
  <!-- mass = KFE joint + HFE joint + Upper leg -->
  <!-- mass = Ankle actuator + Lower leg -->
  <!-- mass = Passive ankle + foot -->
  <gazebo>
    <plugin filename="libgazebo_ros_control.so" name="gazebo_ros_control">
      <robotNamespace>/march</robotNamespace>
      <robotSimType>gazebo_ros_control/DefaultRobotHWSim</robotSimType>
    </plugin>
  </gazebo>
  <material name="visuals_material">
    <color rgba="0.163 0.476 0.718 1"/>
  </material>
  <!-- Used for fixing robot to Gazebo 'base_link' -->
  <link name="world"/>
  <link name="hip_base">
    <visual>
      <origin rpy="0 0 0" xyz="0.151 -0.025 -0.025"/>
      <geometry>
        <mesh filename="package://march_description/urdf/stl-files/march6/HipBase.stl" scale="1 1 1"/>
      </geometry>
      <material name="visuals_material"/>
    </visual>
    <inertial>
      <origin rpy="0 0 0" xyz="-0.003010999999999986 0.016341 0.147761"/>
      <mass value="8.686"/>
      <inertia ixx="0.303498" ixy="-0.000197304" ixz="0.0189663" iyy="0.239254" iyz="0.00122058" izz="0.11822"/>
    </inertial>
    <collision>
      <origin rpy="0 0 0" xyz="0 0 0"/>
      <geometry>
        <box size="0.05 0.145 0.05"/>
      </geometry>
    </collision>
  </link>
  <!-- IMU-->
  <link name="imu_link">
    </link>
  <link name="hip_aa_frame_left_side">
    <visual>
      <origin rpy="0 0 0" xyz="0.025 -0.006999999999999999 -0.05"/>
      <geometry>
        <mesh filename="package://march_description/urdf/stl-files/march6/HipLeft.stl" scale="1 1 1"/>
      </geometry>
      <material name="visuals_material"/>
    </visual>
    <collision>
      <origin rpy="0 0 0" xyz="0 -0.08025 0"/>
      <geometry>
        <box size="0.05 0.1605 0.05"/>
      </geometry>
    </collision>
  </link>
  <link name="hip_aa_frame_left_front">
    <inertial>
      <origin rpy="0 0 0" xyz="-0.042906 0.035241999999999996 0.029507"/>
      <mass value="3.019"/>
      <inertia ixx="0.068391" ixy="0.0426776" ixz="0.000171569" iyy="0.0388633" iyz="-0.00117041" izz="0.104156"/>
    </inertial>
    <collision>
      <origin rpy="0 0 0" xyz="-0.0755 0 0"/>
      <geometry>
        <box size="0.151 0.05 0.05"/>
      </geometry>
    </collision>
  </link>
  &gt;
            
  <link name="upper_leg_left">
    <visual>
      <origin rpy="0 0 3.141592653589793" xyz="-0.01 -0.032 -0.48"/>
      <geometry>
        <mesh filename="package://march_description/urdf/stl-files/march6/UpperLegLeft.stl" scale="1 1 1"/>
      </geometry>
      <material name="visuals_material"/>
    </visual>
    <inertial>
      <origin rpy="0 0 0" xyz="0.000709 0.017745999999999984 -0.19205"/>
      <mass value="8.161"/>
      <inertia ixx="1.68779" ixy="0.0439623" ixz="0.249519" iyy="1.68452" iyz="-0.0814673" izz="0.20142"/>
    </inertial>
    <collision>
      <origin rpy="0 0 0" xyz="0 0 -0.205"/>
      <geometry>
        <box size="0.05 0.05 0.41"/>
      </geometry>
    </collision>
  </link>
  &gt;
            
  <link name="lower_leg_left">
    <visual>
      <origin rpy="0 0 3.141592653589793" xyz="0.005000000000000001 -0.032 -0.42500000000000004"/>
      <geometry>
        <mesh filename="package://march_description/urdf/stl-files/march6/LowerLegLeft.stl" scale="1 1 1"/>
      </geometry>
      <material name="visuals_material"/>
    </visual>
    <inertial>
      <origin rpy="0 0 0" xyz="-0.00321 0.04891899999999999 -0.11708200000000007"/>
      <mass value="4.997"/>
      <inertia ixx="0.567226" ixy="-0.00351928" ixz="0.0146315" iyy="0.561191" iyz="0.019722" izz="0.0624652"/>
    </inertial>
    <collision>
      <origin rpy="0 0 0" xyz="0 0 -0.195"/>
      <geometry>
        <box size="0.05 0.05 0.39"/>
      </geometry>
    </collision>
  </link>
  &gt;
            
  <link name="ankle_plate_left">
    <visual>
      <origin rpy="0 0 3.141592653589793" xyz="-0.179 -0.09500000000000001 -0.10500000000000001"/>
      <geometry>
        <mesh filename="package://march_description/urdf/stl-files/march6/FootLeft.stl" scale="1 1 1"/>
      </geometry>
      <material name="visuals_material"/>
    </visual>
    <collision>
      <origin rpy="0 0 0" xyz="0 0 -0.0325"/>
      <geometry>
        <box size="0.05 0.05 0.065"/>
      </geometry>
    </collision>
  </link>
  <link name="foot_left">
    <inertial>
      <origin rpy="0 0 0" xyz="-0.028926 -0.0029160000000000297 0.07521199999999995"/>
      <mass value="0.789"/>
      <inertia ixx="0.00388523" ixy="0.00209516" ixz="-0.00189858" iyy="0.00659119" iyz="0.00168033" izz="0.00630322"/>
    </inertial>
    <collision>
      <origin rpy="0 0 0" xyz="-0.0625 0 0"/>
      <geometry>
        <box size="0.243 0.05 0.05"/>
      </geometry>
    </collision>
  </link>
  <link name="pressure_sole_left_heel_1">
    <collision>
      <origin rpy="0 0 0" xyz="0.028624999999999998 0.0125 0"/>
      <geometry>
        <box size="0.06075 0.025 0.001"/>
      </geometry>
    </collision>
  </link>
  <gazebo reference="pressure_sole_left_heel_1">
    <sensor name="pressure_sole_heel_1_sensor" type="contact">
      <always_on>true</always_on>
      <contact>
        <collision>ankle_plate_left_fixed_joint_lump__pressure_sole_left_heel_1_collision_8</collision>
      </contact>
      <plugin filename="libgazebo_ros_bumper.so" name="pressure_sole_plugin_heel_1">
        <bumperTopicName>march/sensor/left_pressure_sole_heel_1</bumperTopicName>
        <frameName>world</frameName>
      </plugin>
    </sensor>
  </gazebo>
  <gazebo reference="pressure_sole_left_heel_1">
    <mu1>1</mu1>
    <mu2>1</mu2>
    <minDepth>0.0005</minDepth>
    <fdir1>1 0 0</fdir1>
  </gazebo>
  <joint name="pressure_sole_left_heel_1_joint" type="fixed">
    <parent link="foot_left"/>
    <child link="pressure_sole_left_heel_1"/>
    <origin rpy="0 0 0" xyz="0 0 -0.025"/>
  </joint>
  <gazebo reference="pressure_sole_left">
    <mu1>1</mu1>
    <mu2>1</mu2>
    <minDepth>0.0005</minDepth>
    <fdir1>1 0 0</fdir1>
  </gazebo>
  <link name="pressure_sole_left_heel_2">
    <collision>
      <origin rpy="0 0 0" xyz="0.028624999999999998 -0.0125 0"/>
      <geometry>
        <box size="0.06075 0.025 0.001"/>
      </geometry>
    </collision>
  </link>
  <gazebo reference="pressure_sole_left_heel_2">
    <sensor name="pressure_sole_heel_2_sensor" type="contact">
      <always_on>true</always_on>
      <contact>
        <collision>ankle_plate_left_fixed_joint_lump__pressure_sole_left_heel_2_collision_9</collision>
      </contact>
      <plugin filename="libgazebo_ros_bumper.so" name="pressure_sole_plugin_heel_2">
        <bumperTopicName>march/sensor/left_pressure_sole_heel_2</bumperTopicName>
        <frameName>world</frameName>
      </plugin>
    </sensor>
  </gazebo>
  <gazebo reference="pressure_sole_left_heel_2">
    <mu1>1</mu1>
    <mu2>1</mu2>
    <minDepth>0.0005</minDepth>
    <fdir1>1 0 0</fdir1>
  </gazebo>
  <joint name="pressure_sole_left_heel_2_joint" type="fixed">
    <parent link="foot_left"/>
    <child link="pressure_sole_left_heel_2"/>
    <origin rpy="0 0 0" xyz="0 0 -0.025"/>
  </joint>
  <gazebo reference="pressure_sole_left">
    <mu1>1</mu1>
    <mu2>1</mu2>
    <minDepth>0.0005</minDepth>
    <fdir1>1 0 0</fdir1>
  </gazebo>
  <link name="pressure_sole_left_arch">
    <collision>
      <origin rpy="0 0 0" xyz="-0.032125 0.0125 0"/>
      <geometry>
        <box size="0.06075 0.025 0.001"/>
      </geometry>
    </collision>
  </link>
  <gazebo reference="pressure_sole_left_arch">
    <sensor name="pressure_sole_arch_sensor" type="contact">
      <always_on>true</always_on>
      <contact>
        <collision>ankle_plate_left_fixed_joint_lump__pressure_sole_left_arch_collision_2</collision>
      </contact>
      <plugin filename="libgazebo_ros_bumper.so" name="pressure_sole_plugin_arch">
        <bumperTopicName>march/sensor/left_pressure_sole_arch</bumperTopicName>
        <frameName>world</frameName>
      </plugin>
    </sensor>
  </gazebo>
  <gazebo reference="pressure_sole_left_arch">
    <mu1>1</mu1>
    <mu2>1</mu2>
    <minDepth>0.0005</minDepth>
    <fdir1>1 0 0</fdir1>
  </gazebo>
  <joint name="pressure_sole_left_arch_joint" type="fixed">
    <parent link="foot_left"/>
    <child link="pressure_sole_left_arch"/>
    <origin rpy="0 0 0" xyz="0 0 -0.025"/>
  </joint>
  <gazebo reference="pressure_sole_left">
    <mu1>1</mu1>
    <mu2>1</mu2>
    <minDepth>0.0005</minDepth>
    <fdir1>1 0 0</fdir1>
  </gazebo>
  <link name="pressure_sole_left_met1">
    <collision>
      <origin rpy="0 0 0" xyz="-0.032125 -0.0125 0"/>
      <geometry>
        <box size="0.06075 0.025 0.001"/>
      </geometry>
    </collision>
  </link>
  <gazebo reference="pressure_sole_left_met1">
    <sensor name="pressure_sole_met1_sensor" type="contact">
      <always_on>true</always_on>
      <contact>
        <collision>ankle_plate_left_fixed_joint_lump__pressure_sole_left_met1_collision_4</collision>
      </contact>
      <plugin filename="libgazebo_ros_bumper.so" name="pressure_sole_plugin_met1">
        <bumperTopicName>march/sensor/left_pressure_sole_met1</bumperTopicName>
        <frameName>world</frameName>
      </plugin>
    </sensor>
  </gazebo>
  <gazebo reference="pressure_sole_left_met1">
    <mu1>1</mu1>
    <mu2>1</mu2>
    <minDepth>0.0005</minDepth>
    <fdir1>1 0 0</fdir1>
  </gazebo>
  <joint name="pressure_sole_left_met1_joint" type="fixed">
    <parent link="foot_left"/>
    <child link="pressure_sole_left_met1"/>
    <origin rpy="0 0 0" xyz="0 0 -0.025"/>
  </joint>
  <gazebo reference="pressure_sole_left">
    <mu1>1</mu1>
    <mu2>1</mu2>
    <minDepth>0.0005</minDepth>
    <fdir1>1 0 0</fdir1>
  </gazebo>
  <link name="pressure_sole_left_met3">
    <collision>
      <origin rpy="0 0 0" xyz="-0.09287499999999999 -0.0125 0"/>
      <geometry>
        <box size="0.06075 0.025 0.001"/>
      </geometry>
    </collision>
  </link>
  <gazebo reference="pressure_sole_left_met3">
    <sensor name="pressure_sole_met3_sensor" type="contact">
      <always_on>true</always_on>
      <contact>
        <collision>ankle_plate_left_fixed_joint_lump__pressure_sole_left_met3_collision_5</collision>
      </contact>
      <plugin filename="libgazebo_ros_bumper.so" name="pressure_sole_plugin_met3">
        <bumperTopicName>march/sensor/left_pressure_sole_met3</bumperTopicName>
        <frameName>world</frameName>
      </plugin>
    </sensor>
  </gazebo>
  <gazebo reference="pressure_sole_left_met3">
    <mu1>1</mu1>
    <mu2>1</mu2>
    <minDepth>0.0005</minDepth>
    <fdir1>1 0 0</fdir1>
  </gazebo>
  <joint name="pressure_sole_left_met3_joint" type="fixed">
    <parent link="foot_left"/>
    <child link="pressure_sole_left_met3"/>
    <origin rpy="0 0 0" xyz="0 0 -0.025"/>
  </joint>
  <gazebo reference="pressure_sole_left">
    <mu1>1</mu1>
    <mu2>1</mu2>
    <minDepth>0.0005</minDepth>
    <fdir1>1 0 0</fdir1>
  </gazebo>
  <link name="pressure_sole_left_met5">
    <collision>
      <origin rpy="0 0 0" xyz="-0.09287499999999999 0.0125 0"/>
      <geometry>
        <box size="0.06075 0.025 0.001"/>
      </geometry>
    </collision>
  </link>
  <gazebo reference="pressure_sole_left_met5">
    <sensor name="pressure_sole_met5_sensor" type="contact">
      <always_on>true</always_on>
      <contact>
        <collision>ankle_plate_left_fixed_joint_lump__pressure_sole_left_met5_collision_6</collision>
      </contact>
      <plugin filename="libgazebo_ros_bumper.so" name="pressure_sole_plugin_met5">
        <bumperTopicName>march/sensor/left_pressure_sole_met5</bumperTopicName>
        <frameName>world</frameName>
      </plugin>
    </sensor>
  </gazebo>
  <gazebo reference="pressure_sole_left_met5">
    <mu1>1</mu1>
    <mu2>1</mu2>
    <minDepth>0.0005</minDepth>
    <fdir1>1 0 0</fdir1>
  </gazebo>
  <joint name="pressure_sole_left_met5_joint" type="fixed">
    <parent link="foot_left"/>
    <child link="pressure_sole_left_met5"/>
    <origin rpy="0 0 0" xyz="0 0 -0.025"/>
  </joint>
  <gazebo reference="pressure_sole_left">
    <mu1>1</mu1>
    <mu2>1</mu2>
    <minDepth>0.0005</minDepth>
    <fdir1>1 0 0</fdir1>
  </gazebo>
  <link name="pressure_sole_left_toes">
    <collision>
      <origin rpy="0 0 0" xyz="-0.153625 0.0125 0"/>
      <geometry>
        <box size="0.06075 0.025 0.001"/>
      </geometry>
    </collision>
  </link>
  <gazebo reference="pressure_sole_left_toes">
    <sensor name="pressure_sole_toes_sensor" type="contact">
      <always_on>true</always_on>
      <contact>
        <collision>ankle_plate_left_fixed_joint_lump__pressure_sole_left_toes_collision_7</collision>
      </contact>
      <plugin filename="libgazebo_ros_bumper.so" name="pressure_sole_plugin_toes">
        <bumperTopicName>march/sensor/left_pressure_sole_toes</bumperTopicName>
        <frameName>world</frameName>
      </plugin>
    </sensor>
  </gazebo>
  <gazebo reference="pressure_sole_left_toes">
    <mu1>1</mu1>
    <mu2>1</mu2>
    <minDepth>0.0005</minDepth>
    <fdir1>1 0 0</fdir1>
  </gazebo>
  <joint name="pressure_sole_left_toes_joint" type="fixed">
    <parent link="foot_left"/>
    <child link="pressure_sole_left_toes"/>
    <origin rpy="0 0 0" xyz="0 0 -0.025"/>
  </joint>
  <gazebo reference="pressure_sole_left">
    <mu1>1</mu1>
    <mu2>1</mu2>
    <minDepth>0.0005</minDepth>
    <fdir1>1 0 0</fdir1>
  </gazebo>
  <link name="pressure_sole_left_hallux">
    <collision>
      <origin rpy="0 0 0" xyz="-0.153625 -0.0125 0"/>
      <geometry>
        <box size="0.06075 0.025 0.001"/>
      </geometry>
    </collision>
  </link>
  <gazebo reference="pressure_sole_left_hallux">
    <sensor name="pressure_sole_hallux_sensor" type="contact">
      <always_on>true</always_on>
      <contact>
        <collision>ankle_plate_left_fixed_joint_lump__pressure_sole_left_hallux_collision_3</collision>
      </contact>
      <plugin filename="libgazebo_ros_bumper.so" name="pressure_sole_plugin_hallux">
        <bumperTopicName>march/sensor/left_pressure_sole_hallux</bumperTopicName>
        <frameName>world</frameName>
      </plugin>
    </sensor>
  </gazebo>
  <gazebo reference="pressure_sole_left_hallux">
    <mu1>1</mu1>
    <mu2>1</mu2>
    <minDepth>0.0005</minDepth>
    <fdir1>1 0 0</fdir1>
  </gazebo>
  <joint name="pressure_sole_left_hallux_joint" type="fixed">
    <parent link="foot_left"/>
    <child link="pressure_sole_left_hallux"/>
    <origin rpy="0 0 0" xyz="0 0 -0.025"/>
  </joint>
  <gazebo reference="pressure_sole_left">
    <mu1>1</mu1>
    <mu2>1</mu2>
    <minDepth>0.0005</minDepth>
    <fdir1>1 0 0</fdir1>
  </gazebo>
  <link name="hip_aa_frame_right_side">
    <visual>
      <origin rpy="0 0 3.141592653589793" xyz="-0.183 0.006999999999999999 -0.05"/>
      <geometry>
        <mesh filename="package://march_description/urdf/stl-files/march6/HipRight.stl" scale="1 1 1"/>
      </geometry>
      <material name="visuals_material"/>
    </visual>
    <collision>
      <origin rpy="0 0 0" xyz="0 0.08025 0"/>
      <geometry>
        <box size="0.05 0.1605 0.05"/>
      </geometry>
    </collision>
  </link>
  <link name="hip_aa_frame_right_front">
    <inertial>
      <origin rpy="0 0 0" xyz="-0.042906 -0.035241999999999996 0.029507"/>
      <mass value="3.019"/>
      <inertia ixx="0.068391" ixy="-0.0426776" ixz="0.000171569" iyy="0.0388633" iyz="0.00117041" izz="0.104156"/>
    </inertial>
    <collision>
      <origin rpy="0 0 0" xyz="-0.0755 0 0"/>
      <geometry>
        <box size="0.151 0.05 0.05"/>
      </geometry>
    </collision>
  </link>
  &gt;
            
  <link name="upper_leg_right">
    <visual>
      <origin rpy="0 0 0" xyz="-0.01 0.032 -0.48"/>
      <geometry>
        <mesh filename="package://march_description/urdf/stl-files/march6/UpperLegRight.stl" scale="1 1 1"/>
      </geometry>
      <material name="visuals_material"/>
    </visual>
    <inertial>
      <origin rpy="0 0 0" xyz="0.000709 -0.017745999999999984 -0.19205"/>
      <mass value="8.161"/>
      <inertia ixx="1.68779" ixy="-0.0439623" ixz="0.249519" iyy="1.68452" iyz="0.0814673" izz="0.20142"/>
    </inertial>
    <collision>
      <origin rpy="0 0 0" xyz="0 0 -0.205"/>
      <geometry>
        <box size="0.05 0.05 0.41"/>
      </geometry>
    </collision>
  </link>
  &gt;
            
  <link name="lower_leg_right">
    <visual>
      <origin rpy="0 0 0" xyz="0.0 0.032 -0.42500000000000004"/>
      <geometry>
        <mesh filename="package://march_description/urdf/stl-files/march6/LowerLegRight.stl" scale="1 1 1"/>
      </geometry>
      <material name="visuals_material"/>
    </visual>
    <inertial>
      <origin rpy="0 0 0" xyz="-0.00321 -0.04891899999999999 -0.11708200000000007"/>
      <mass value="4.997"/>
      <inertia ixx="0.567226" ixy="0.00351928" ixz="0.0146315" iyy="0.561191" iyz="-0.019722" izz="0.0624652"/>
    </inertial>
    <collision>
      <origin rpy="0 0 0" xyz="0 0 -0.195"/>
      <geometry>
        <box size="0.05 0.05 0.39"/>
      </geometry>
    </collision>
  </link>
  &gt;
            
  <link name="ankle_plate_right">
    <visual>
      <origin rpy="0 0 0" xyz="0 0.09500000000000001 -0.10500000000000001"/>
      <geometry>
        <mesh filename="package://march_description/urdf/stl-files/march6/FootRight.stl" scale="1 1 1"/>
      </geometry>
      <material name="visuals_material"/>
    </visual>
    <collision>
      <origin rpy="0 0 0" xyz="0 0 -0.0325"/>
      <geometry>
        <box size="0.05 0.05 0.065"/>
      </geometry>
    </collision>
  </link>
  <link name="pressure_sole_right_heel_1">
    <collision>
      <origin rpy="0 0 0" xyz="0.028624999999999998 0.0125 0"/>
      <geometry>
        <box size="0.06075 0.025 0.001"/>
      </geometry>
    </collision>
  </link>
  <gazebo reference="pressure_sole_right_heel_1">
    <sensor name="pressure_sole_heel_1_sensor" type="contact">
      <always_on>true</always_on>
      <contact>
        <collision>ankle_plate_right_fixed_joint_lump__pressure_sole_right_heel_1_collision_8</collision>
      </contact>
      <plugin filename="libgazebo_ros_bumper.so" name="pressure_sole_plugin_heel_1">
        <bumperTopicName>march/sensor/right_pressure_sole_heel_1</bumperTopicName>
        <frameName>world</frameName>
      </plugin>
    </sensor>
  </gazebo>
  <gazebo reference="pressure_sole_right_heel_1">
    <mu1>1</mu1>
    <mu2>1</mu2>
    <minDepth>0.0005</minDepth>
    <fdir1>1 0 0</fdir1>
  </gazebo>
  <joint name="pressure_sole_right_heel_1_joint" type="fixed">
    <parent link="foot_right"/>
    <child link="pressure_sole_right_heel_1"/>
    <origin rpy="0 0 0" xyz="0 0 -0.025"/>
  </joint>
  <gazebo reference="pressure_sole_right">
    <mu1>1</mu1>
    <mu2>1</mu2>
    <minDepth>0.0005</minDepth>
    <fdir1>1 0 0</fdir1>
  </gazebo>
  <link name="pressure_sole_right_heel_2">
    <collision>
      <origin rpy="0 0 0" xyz="0.028624999999999998 -0.0125 0"/>
      <geometry>
        <box size="0.06075 0.025 0.001"/>
      </geometry>
    </collision>
  </link>
  <gazebo reference="pressure_sole_right_heel_2">
    <sensor name="pressure_sole_heel_2_sensor" type="contact">
      <always_on>true</always_on>
      <contact>
        <collision>ankle_plate_right_fixed_joint_lump__pressure_sole_right_heel_2_collision_9</collision>
      </contact>
      <plugin filename="libgazebo_ros_bumper.so" name="pressure_sole_plugin_heel_2">
        <bumperTopicName>march/sensor/right_pressure_sole_heel_2</bumperTopicName>
        <frameName>world</frameName>
      </plugin>
    </sensor>
  </gazebo>
  <gazebo reference="pressure_sole_right_heel_2">
    <mu1>1</mu1>
    <mu2>1</mu2>
    <minDepth>0.0005</minDepth>
    <fdir1>1 0 0</fdir1>
  </gazebo>
  <joint name="pressure_sole_right_heel_2_joint" type="fixed">
    <parent link="foot_right"/>
    <child link="pressure_sole_right_heel_2"/>
    <origin rpy="0 0 0" xyz="0 0 -0.025"/>
  </joint>
  <gazebo reference="pressure_sole_right">
    <mu1>1</mu1>
    <mu2>1</mu2>
    <minDepth>0.0005</minDepth>
    <fdir1>1 0 0</fdir1>
  </gazebo>
  <link name="pressure_sole_right_arch">
    <collision>
      <origin rpy="0 0 0" xyz="-0.032125 0.0125 0"/>
      <geometry>
        <box size="0.06075 0.025 0.001"/>
      </geometry>
    </collision>
  </link>
  <gazebo reference="pressure_sole_right_arch">
    <sensor name="pressure_sole_arch_sensor" type="contact">
      <always_on>true</always_on>
      <contact>
        <collision>ankle_plate_right_fixed_joint_lump__pressure_sole_right_arch_collision_2</collision>
      </contact>
      <plugin filename="libgazebo_ros_bumper.so" name="pressure_sole_plugin_arch">
        <bumperTopicName>march/sensor/right_pressure_sole_arch</bumperTopicName>
        <frameName>world</frameName>
      </plugin>
    </sensor>
  </gazebo>
  <gazebo reference="pressure_sole_right_arch">
    <mu1>1</mu1>
    <mu2>1</mu2>
    <minDepth>0.0005</minDepth>
    <fdir1>1 0 0</fdir1>
  </gazebo>
  <joint name="pressure_sole_right_arch_joint" type="fixed">
    <parent link="foot_right"/>
    <child link="pressure_sole_right_arch"/>
    <origin rpy="0 0 0" xyz="0 0 -0.025"/>
  </joint>
  <gazebo reference="pressure_sole_right">
    <mu1>1</mu1>
    <mu2>1</mu2>
    <minDepth>0.0005</minDepth>
    <fdir1>1 0 0</fdir1>
  </gazebo>
  <link name="pressure_sole_right_met1">
    <collision>
      <origin rpy="0 0 0" xyz="-0.032125 -0.0125 0"/>
      <geometry>
        <box size="0.06075 0.025 0.001"/>
      </geometry>
    </collision>
  </link>
  <gazebo reference="pressure_sole_right_met1">
    <sensor name="pressure_sole_met1_sensor" type="contact">
      <always_on>true</always_on>
      <contact>
        <collision>ankle_plate_right_fixed_joint_lump__pressure_sole_right_met1_collision_4</collision>
      </contact>
      <plugin filename="libgazebo_ros_bumper.so" name="pressure_sole_plugin_met1">
        <bumperTopicName>march/sensor/right_pressure_sole_met1</bumperTopicName>
        <frameName>world</frameName>
      </plugin>
    </sensor>
  </gazebo>
  <gazebo reference="pressure_sole_right_met1">
    <mu1>1</mu1>
    <mu2>1</mu2>
    <minDepth>0.0005</minDepth>
    <fdir1>1 0 0</fdir1>
  </gazebo>
  <joint name="pressure_sole_right_met1_joint" type="fixed">
    <parent link="foot_right"/>
    <child link="pressure_sole_right_met1"/>
    <origin rpy="0 0 0" xyz="0 0 -0.025"/>
  </joint>
  <gazebo reference="pressure_sole_right">
    <mu1>1</mu1>
    <mu2>1</mu2>
    <minDepth>0.0005</minDepth>
    <fdir1>1 0 0</fdir1>
  </gazebo>
  <link name="pressure_sole_right_met3">
    <collision>
      <origin rpy="0 0 0" xyz="-0.09287499999999999 -0.0125 0"/>
      <geometry>
        <box size="0.06075 0.025 0.001"/>
      </geometry>
    </collision>
  </link>
  <gazebo reference="pressure_sole_right_met3">
    <sensor name="pressure_sole_met3_sensor" type="contact">
      <always_on>true</always_on>
      <contact>
        <collision>ankle_plate_right_fixed_joint_lump__pressure_sole_right_met3_collision_5</collision>
      </contact>
      <plugin filename="libgazebo_ros_bumper.so" name="pressure_sole_plugin_met3">
        <bumperTopicName>march/sensor/right_pressure_sole_met3</bumperTopicName>
        <frameName>world</frameName>
      </plugin>
    </sensor>
  </gazebo>
  <gazebo reference="pressure_sole_right_met3">
    <mu1>1</mu1>
    <mu2>1</mu2>
    <minDepth>0.0005</minDepth>
    <fdir1>1 0 0</fdir1>
  </gazebo>
  <joint name="pressure_sole_right_met3_joint" type="fixed">
    <parent link="foot_right"/>
    <child link="pressure_sole_right_met3"/>
    <origin rpy="0 0 0" xyz="0 0 -0.025"/>
  </joint>
  <gazebo reference="pressure_sole_right">
    <mu1>1</mu1>
    <mu2>1</mu2>
    <minDepth>0.0005</minDepth>
    <fdir1>1 0 0</fdir1>
  </gazebo>
  <link name="pressure_sole_right_met5">
    <collision>
      <origin rpy="0 0 0" xyz="-0.09287499999999999 0.0125 0"/>
      <geometry>
        <box size="0.06075 0.025 0.001"/>
      </geometry>
    </collision>
  </link>
  <gazebo reference="pressure_sole_right_met5">
    <sensor name="pressure_sole_met5_sensor" type="contact">
      <always_on>true</always_on>
      <contact>
        <collision>ankle_plate_right_fixed_joint_lump__pressure_sole_right_met5_collision_6</collision>
      </contact>
      <plugin filename="libgazebo_ros_bumper.so" name="pressure_sole_plugin_met5">
        <bumperTopicName>march/sensor/right_pressure_sole_met5</bumperTopicName>
        <frameName>world</frameName>
      </plugin>
    </sensor>
  </gazebo>
  <gazebo reference="pressure_sole_right_met5">
    <mu1>1</mu1>
    <mu2>1</mu2>
    <minDepth>0.0005</minDepth>
    <fdir1>1 0 0</fdir1>
  </gazebo>
  <joint name="pressure_sole_right_met5_joint" type="fixed">
    <parent link="foot_right"/>
    <child link="pressure_sole_right_met5"/>
    <origin rpy="0 0 0" xyz="0 0 -0.025"/>
  </joint>
  <gazebo reference="pressure_sole_right">
    <mu1>1</mu1>
    <mu2>1</mu2>
    <minDepth>0.0005</minDepth>
    <fdir1>1 0 0</fdir1>
  </gazebo>
  <link name="pressure_sole_right_toes">
    <collision>
      <origin rpy="0 0 0" xyz="-0.153625 0.0125 0"/>
      <geometry>
        <box size="0.06075 0.025 0.001"/>
      </geometry>
    </collision>
  </link>
  <gazebo reference="pressure_sole_right_toes">
    <sensor name="pressure_sole_toes_sensor" type="contact">
      <always_on>true</always_on>
      <contact>
        <collision>ankle_plate_right_fixed_joint_lump__pressure_sole_right_toes_collision_7</collision>
      </contact>
      <plugin filename="libgazebo_ros_bumper.so" name="pressure_sole_plugin_toes">
        <bumperTopicName>march/sensor/right_pressure_sole_toes</bumperTopicName>
        <frameName>world</frameName>
      </plugin>
    </sensor>
  </gazebo>
  <gazebo reference="pressure_sole_right_toes">
    <mu1>1</mu1>
    <mu2>1</mu2>
    <minDepth>0.0005</minDepth>
    <fdir1>1 0 0</fdir1>
  </gazebo>
  <joint name="pressure_sole_right_toes_joint" type="fixed">
    <parent link="foot_right"/>
    <child link="pressure_sole_right_toes"/>
    <origin rpy="0 0 0" xyz="0 0 -0.025"/>
  </joint>
  <gazebo reference="pressure_sole_right">
    <mu1>1</mu1>
    <mu2>1</mu2>
    <minDepth>0.0005</minDepth>
    <fdir1>1 0 0</fdir1>
  </gazebo>
  <link name="pressure_sole_right_hallux">
    <collision>
      <origin rpy="0 0 0" xyz="-0.153625 -0.0125 0"/>
      <geometry>
        <box size="0.06075 0.025 0.001"/>
      </geometry>
    </collision>
  </link>
  <gazebo reference="pressure_sole_right_hallux">
    <sensor name="pressure_sole_hallux_sensor" type="contact">
      <always_on>true</always_on>
      <contact>
        <collision>ankle_plate_right_fixed_joint_lump__pressure_sole_right_hallux_collision_3</collision>
      </contact>
      <plugin filename="libgazebo_ros_bumper.so" name="pressure_sole_plugin_hallux">
        <bumperTopicName>march/sensor/right_pressure_sole_hallux</bumperTopicName>
        <frameName>world</frameName>
      </plugin>
    </sensor>
  </gazebo>
  <gazebo reference="pressure_sole_right_hallux">
    <mu1>1</mu1>
    <mu2>1</mu2>
    <minDepth>0.0005</minDepth>
    <fdir1>1 0 0</fdir1>
  </gazebo>
  <joint name="pressure_sole_right_hallux_joint" type="fixed">
    <parent link="foot_right"/>
    <child link="pressure_sole_right_hallux"/>
    <origin rpy="0 0 0" xyz="0 0 -0.025"/>
  </joint>
  <gazebo reference="pressure_sole_right">
    <mu1>1</mu1>
    <mu2>1</mu2>
    <minDepth>0.0005</minDepth>
    <fdir1>1 0 0</fdir1>
  </gazebo>
  <link name="foot_right">
    <inertial>
      <origin rpy="0 0 0" xyz="-0.028926 0.0029160000000000297 0.07521199999999995"/>
      <mass value="0.789"/>
      <inertia ixx="0.00388523" ixy="-0.00209516" ixz="-0.00189858" iyy="0.00659119" iyz="-0.00168033" izz="0.00630322"/>
    </inertial>
    <collision>
      <origin rpy="0 0 0" xyz="-0.0625 0 0"/>
      <geometry>
        <box size="0.243 0.05 0.05"/>
      </geometry>
    </collision>
  </link>
  <!-- Joints -->
  <joint name="imu_joint" type="fixed">
    <parent link="world"/>
    <child link="imu_link"/>
  </joint>
  <joint name="hip" type="fixed">
    <parent link="imu_link"/>
    <child link="hip_base"/>
    <origin rpy="0 0 0" xyz="0 0 0"/>
  </joint>
  <joint name="left_hip_aa" type="revolute">
    <parent link="hip_base"/>
    <child link="hip_aa_frame_left_side"/>
    <origin rpy="0 0 0" xyz="0 -0.0725 0"/>
    <axis xyz="-1 0 0"/>
    <limit effort="30.0" lower="-0.15493205957644976" upper="0.21092235833427567" velocity="2.5"/>
    <safety_controller k_position="6.6430091259949355" k_velocity="28.775519491677287" soft_lower_limit="-0.1514414010724611" soft_upper_limit="0.207431699830287"/>
  </joint>
  <transmission name="left_hip_aa">
    <type>transmission_interface/SimpleTransmission</type>
    <joint name="left_hip_aa">
      <hardwareInterface>hardware_interface/EffortJointInterface</hardwareInterface>
    </joint>
    <actuator name="left_hip_aa_motor">
      <mechanicalReduction>
                    240
                </mechanicalReduction>
    </actuator>
  </transmission>
  <joint name="left_hip_angle" type="fixed">
    <parent link="hip_aa_frame_left_side"/>
    <child link="hip_aa_frame_left_front"/>
    <origin rpy="0 0 0" xyz="0 -0.1605 0"/>
  </joint>
  <joint name="left_hip_fe" type="revolute">
    <parent link="hip_aa_frame_left_front"/>
    <child link="upper_leg_left"/>
    <origin rpy="0 0 0" xyz="-0.151 0.0 0"/>
    <axis xyz="0 1 0"/>
    <limit effort="30.0" lower="-0.45605967877334436" upper="1.7328290396277701" velocity="3.0"/>
    <safety_controller k_position="3.3401714863487983" k_velocity="6.105877562284971" soft_lower_limit="-0.4211530937334578" soft_upper_limit="1.6979224545878835"/>
  </joint>
  <transmission name="left_hip_fe">
    <type>transmission_interface/SimpleTransmission</type>
    <joint name="left_hip_fe">
      <hardwareInterface>hardware_interface/EffortJointInterface</hardwareInterface>
    </joint>
    <actuator name="left_hip_fe_motor">
      <mechanicalReduction>
                    121.19999999999999
                </mechanicalReduction>
    </actuator>
  </transmission>
  <joint name="left_knee" type="revolute">
    <parent link="upper_leg_left"/>
    <child link="lower_leg_left"/>
    <origin rpy="0 0 0" xyz="0 0.03 -0.41"/>
    <axis xyz="0 -1 0"/>
    <limit effort="30.0" lower="-0.08939033356905467" upper="2.0034388301031743" velocity="3.5"/>
    <safety_controller k_position="9.656085595298899" k_velocity="23.06987607064259" soft_lower_limit="-0.054483748529168076" soft_upper_limit="1.9685322450632876"/>
  </joint>
  <transmission name="left_knee">
    <type>transmission_interface/SimpleTransmission</type>
    <joint name="left_knee">
      <hardwareInterface>hardware_interface/EffortJointInterface</hardwareInterface>
    </joint>
    <actuator name="left_knee_motor">
      <mechanicalReduction>
                    121.19999999999999
                </mechanicalReduction>
    </actuator>
  </transmission>
  <joint name="left_ankle" type="revolute">
    <parent link="lower_leg_left"/>
    <child link="ankle_plate_left"/>
    <origin rpy="0 0 0" xyz="0 0.08 -0.39"/>
    <axis xyz="0 1 0"/>
    <limit effort="30.0" lower="-0.6764855274575677" upper="0.14764565083399298" velocity="2.5"/>
    <safety_controller k_position="7.692354754168206" k_velocity="2.246279388462071" soft_lower_limit="-0.6415789424176811" soft_upper_limit="0.1441549923300043"/>
  </joint>
  <transmission name="left_ankle">
    <type>transmission_interface/SimpleTransmission</type>
    <joint name="left_ankle">
      <hardwareInterface>hardware_interface/EffortJointInterface</hardwareInterface>
    </joint>
    <actuator name="left_ankle_motor">
      <mechanicalReduction>
                    236
                </mechanicalReduction>
    </actuator>
  </transmission>
  <joint name="left_foot_angle" type="fixed">
    <parent link="ankle_plate_left"/>
    <child link="foot_left"/>
    <origin rpy="0 0 0" xyz="0 0 -0.09"/>
  </joint>
  <joint name="right_hip_aa" type="revolute">
    <parent link="hip_base"/>
    <child link="hip_aa_frame_right_side"/>
    <origin rpy="0 0 0" xyz="0 0.0725 0"/>
    <axis xyz="1 0 0"/>
    <limit effort="30.0" lower="-0.15493205957644976" upper="0.19174759848570513" velocity="2.5"/>
    <safety_controller k_position="6.6430091259949355" k_velocity="28.775519491677287" soft_lower_limit="-0.1514414010724611" soft_upper_limit="0.18825693998171647"/>
  </joint>
  <transmission name="right_hip_aa">
    <type>transmission_interface/SimpleTransmission</type>
    <joint name="right_hip_aa">
      <hardwareInterface>hardware_interface/EffortJointInterface</hardwareInterface>
    </joint>
    <actuator name="right_hip_aa_motor">
      <mechanicalReduction>
                    236
                </mechanicalReduction>
    </actuator>
  </transmission>
  <joint name="right_hip_angle" type="fixed">
    <parent link="hip_aa_frame_right_side"/>
    <child link="hip_aa_frame_right_front"/>
    <origin rpy="0 0 0" xyz="0 0.1605 0"/>
  </joint>
  <joint name="right_hip_fe" type="revolute">
    <parent link="hip_aa_frame_right_front"/>
    <child link="upper_leg_right"/>
    <origin rpy="0 0 0" xyz="-0.151 -0.0 0"/>
    <axis xyz="0 1 0"/>
    <limit effort="30.0" lower="-0.4366931713262881" upper="1.7860689587698166" velocity="3.0"/>
    <safety_controller k_position="3.3401714863487983" k_velocity="6.105877562284971" soft_lower_limit="-0.4017865862864015" soft_upper_limit="1.75116237372993"/>
  </joint>
  <transmission name="right_hip_fe">
    <type>transmission_interface/SimpleTransmission</type>
    <joint name="right_hip_fe">
      <hardwareInterface>hardware_interface/EffortJointInterface</hardwareInterface>
    </joint>
    <actuator name="right_hip_fe_motor">
      <mechanicalReduction>
                    121.19999999999999
                </mechanicalReduction>
    </actuator>
  </transmission>
  <joint name="right_knee" type="revolute">
    <parent link="upper_leg_right"/>
    <child link="lower_leg_right"/>
    <origin rpy="0 0 0" xyz="0 -0.03 -0.41"/>
    <axis xyz="0 -1 0"/>
    <limit effort="30.0" lower="-0.08992363157734304" upper="2.0082205358404113" velocity="3.5"/>
    <safety_controller k_position="9.656085595298899" k_velocity="23.06987607064259" soft_lower_limit="-0.05501704653745645" soft_upper_limit="1.9733139508005246"/>
  </joint>
  <transmission name="right_knee">
    <type>transmission_interface/SimpleTransmission</type>
    <joint name="right_knee">
      <hardwareInterface>hardware_interface/EffortJointInterface</hardwareInterface>
    </joint>
    <actuator name="right_knee_motor">
      <mechanicalReduction>
                    121.19999999999999
                </mechanicalReduction>
    </actuator>
  </transmission>
  <joint name="right_ankle" type="revolute">
    <parent link="lower_leg_right"/>
    <child link="ankle_plate_right"/>
    <origin rpy="0 0 0" xyz="0 -0.08 -0.39"/>
    <axis xyz="0 1 0"/>
    <limit effort="30.0" lower="-0.6538593108362546" upper="0.14342720366730746" velocity="2.5"/>
    <safety_controller k_position="7.692354754168206" k_velocity="2.246279388462071" soft_lower_limit="-0.618952725796368" soft_upper_limit="0.1399365451633188"/>
  </joint>
  <transmission name="right_ankle">
    <type>transmission_interface/SimpleTransmission</type>
    <joint name="right_ankle">
      <hardwareInterface>hardware_interface/EffortJointInterface</hardwareInterface>
    </joint>
    <actuator name="right_ankle_motor">
      <mechanicalReduction>
                    236
                </mechanicalReduction>
    </actuator>
  </transmission>
  <joint name="right_foot_angle" type="fixed">
    <parent link="ankle_plate_right"/>
    <child link="foot_right"/>
    <origin rpy="0 0 0" xyz="0 0 -0.09"/>
  </joint>
  <material name="camera_front_right_aluminum">
    <color rgba="0.5 0.5 0.5 1"/>
  </material>
  <!-- camera body, with origin at bottom screw mount -->
  <joint name="camera_front_right_joint" type="fixed">
    <origin rpy="0.0 1.064650843716541 3.141592653589793" xyz="-0.08 0.035 -0.05 "/>
    <parent link="upper_leg_right"/>
    <child link="camera_front_right_bottom_screw_frame"/>
  </joint>
  <link name="camera_front_right_bottom_screw_frame"/>
  <joint name="camera_front_right_link_joint" type="fixed">
    <origin rpy="0 0 0" xyz="0 0.0175 0.0125"/>
    <parent link="camera_front_right_bottom_screw_frame"/>
    <child link="camera_front_right_link"/>
  </joint>
  <link name="camera_front_right_link">
    <visual>
      <origin rpy="1.5707963267948966 0 1.5707963267948966" xyz="0.0149 -0.0175 0"/>
      <geometry>
        <!-- <box size="${d435_cam_width} ${d435_cam_height} ${d435_cam_depth}"/> -->
        <mesh filename="package://march_description/urdf/camera/_d435.dae"/>
      </geometry>
      <material name="camera_front_right_aluminum"/>
    </visual>
    <collision>
      <origin rpy="0 0 0" xyz="0 -0.0175 0"/>
      <geometry>
        <box size="0.02505 0.09 0.025"/>
      </geometry>
    </collision>
    <inertial>
      <!-- The following are not reliable values, and should not be used for modeling -->
      <mass value="0.564"/>
      <origin xyz="0 0 0"/>
      <inertia ixx="0.003881243" ixy="0.0" ixz="0.0" iyy="0.000498940" iyz="0.0" izz="0.003879257"/>
    </inertial>
  </link>
  <!-- camera depth joints and links -->
  <joint name="camera_front_right_depth_joint" type="fixed">
    <origin rpy="0 0 0" xyz="0 0 0"/>
    <parent link="camera_front_right_link"/>
    <child link="camera_front_right_depth_frame"/>
  </joint>
  <link name="camera_front_right_depth_frame"/>
  <joint name="camera_front_right_depth_optical_joint" type="fixed">
    <origin rpy="-1.5707963267948966 0 -1.5707963267948966" xyz="0 0 0"/>
    <parent link="camera_front_right_depth_frame"/>
    <child link="camera_front_right_depth_optical_frame"/>
  </joint>
  <link name="camera_front_right_depth_optical_frame"/>
  <!-- camera left IR joints and links -->
  <joint name="camera_front_right_left_ir_joint" type="fixed">
    <origin rpy="0 0 0" xyz="0 0.0 0"/>
    <parent link="camera_front_right_depth_frame"/>
    <child link="camera_front_right_left_ir_frame"/>
  </joint>
  <link name="camera_front_right_left_ir_frame"/>
  <joint name="camera_front_right_left_ir_optical_joint" type="fixed">
    <origin rpy="-1.5707963267948966 0 -1.5707963267948966" xyz="0 0 0"/>
    <parent link="camera_front_right_left_ir_frame"/>
    <child link="camera_front_right_left_ir_optical_frame"/>
  </joint>
  <link name="camera_front_right_left_ir_optical_frame"/>
  <!-- camera right IR joints and links -->
  <joint name="camera_front_right_right_ir_joint" type="fixed">
    <origin rpy="0 0 0" xyz="0 -0.05 0"/>
    <parent link="camera_front_right_depth_frame"/>
    <child link="camera_front_right_right_ir_frame"/>
  </joint>
  <link name="camera_front_right_right_ir_frame"/>
  <joint name="camera_front_right_right_ir_optical_joint" type="fixed">
    <origin rpy="-1.5707963267948966 0 -1.5707963267948966" xyz="0 0 0"/>
    <parent link="camera_front_right_right_ir_frame"/>
    <child link="camera_front_right_right_ir_optical_frame"/>
  </joint>
  <link name="camera_front_right_right_ir_optical_frame"/>
  <!-- camera color joints and links -->
  <joint name="camera_front_right_color_joint" type="fixed">
    <origin rpy="0 0 0" xyz="0 0.015 0"/>
    <parent link="camera_front_right_depth_frame"/>
    <child link="camera_front_right_color_frame"/>
  </joint>
  <link name="camera_front_right_color_frame"/>
  <joint name="camera_front_right_color_optical_joint" type="fixed">
    <origin rpy="-1.5707963267948966 0 -1.5707963267948966" xyz="0 0 0"/>
    <parent link="camera_front_right_color_frame"/>
    <child link="camera_front_right_color_optical_frame"/>
  </joint>
  <link name="camera_front_right_color_optical_frame"/>
  <link name="camera_front_right_imu_optical_frame"/>
  <joint name="camera_front_right_imu_optical_joint" type="fixed">
    <origin rpy="-1.5707963267948966 0 -1.5707963267948966" xyz="0 0 0"/>
    <parent link="camera_front_right_depth_frame"/>
    <child link="camera_front_right_imu_optical_frame"/>
  </joint>
  <material name="camera_front_left_aluminum">
    <color rgba="0.5 0.5 0.5 1"/>
  </material>
  <!-- camera body, with origin at bottom screw mount -->
  <joint name="camera_front_left_joint" type="fixed">
    <origin rpy="0.0 1.064650843716541 3.141592653589793" xyz="-0.08 -0.035 -0.05 "/>
    <parent link="upper_leg_left"/>
    <child link="camera_front_left_bottom_screw_frame"/>
  </joint>
  <link name="camera_front_left_bottom_screw_frame"/>
  <joint name="camera_front_left_link_joint" type="fixed">
    <origin rpy="0 0 0" xyz="0 0.0175 0.0125"/>
    <parent link="camera_front_left_bottom_screw_frame"/>
    <child link="camera_front_left_link"/>
  </joint>
  <link name="camera_front_left_link">
    <visual>
      <origin rpy="1.5707963267948966 0 1.5707963267948966" xyz="0.0149 -0.0175 0"/>
      <geometry>
        <!-- <box size="${d435_cam_width} ${d435_cam_height} ${d435_cam_depth}"/> -->
        <mesh filename="package://march_description/urdf/camera/_d435.dae"/>
      </geometry>
      <material name="camera_front_left_aluminum"/>
    </visual>
    <collision>
      <origin rpy="0 0 0" xyz="0 -0.0175 0"/>
      <geometry>
        <box size="0.02505 0.09 0.025"/>
      </geometry>
    </collision>
    <inertial>
      <!-- The following are not reliable values, and should not be used for modeling -->
      <mass value="0.564"/>
      <origin xyz="0 0 0"/>
      <inertia ixx="0.003881243" ixy="0.0" ixz="0.0" iyy="0.000498940" iyz="0.0" izz="0.003879257"/>
    </inertial>
  </link>
  <!-- camera depth joints and links -->
  <joint name="camera_front_left_depth_joint" type="fixed">
    <origin rpy="0 0 0" xyz="0 0 0"/>
    <parent link="camera_front_left_link"/>
    <child link="camera_front_left_depth_frame"/>
  </joint>
  <link name="camera_front_left_depth_frame"/>
  <joint name="camera_front_left_depth_optical_joint" type="fixed">
    <origin rpy="-1.5707963267948966 0 -1.5707963267948966" xyz="0 0 0"/>
    <parent link="camera_front_left_depth_frame"/>
    <child link="camera_front_left_depth_optical_frame"/>
  </joint>
  <link name="camera_front_left_depth_optical_frame"/>
  <!-- camera left IR joints and links -->
  <joint name="camera_front_left_left_ir_joint" type="fixed">
    <origin rpy="0 0 0" xyz="0 0.0 0"/>
    <parent link="camera_front_left_depth_frame"/>
    <child link="camera_front_left_left_ir_frame"/>
  </joint>
  <link name="camera_front_left_left_ir_frame"/>
  <joint name="camera_front_left_left_ir_optical_joint" type="fixed">
    <origin rpy="-1.5707963267948966 0 -1.5707963267948966" xyz="0 0 0"/>
    <parent link="camera_front_left_left_ir_frame"/>
    <child link="camera_front_left_left_ir_optical_frame"/>
  </joint>
  <link name="camera_front_left_left_ir_optical_frame"/>
  <!-- camera right IR joints and links -->
  <joint name="camera_front_left_right_ir_joint" type="fixed">
    <origin rpy="0 0 0" xyz="0 -0.05 0"/>
    <parent link="camera_front_left_depth_frame"/>
    <child link="camera_front_left_right_ir_frame"/>
  </joint>
  <link name="camera_front_left_right_ir_frame"/>
  <joint name="camera_front_left_right_ir_optical_joint" type="fixed">
    <origin rpy="-1.5707963267948966 0 -1.5707963267948966" xyz="0 0 0"/>
    <parent link="camera_front_left_right_ir_frame"/>
    <child link="camera_front_left_right_ir_optical_frame"/>
  </joint>
  <link name="camera_front_left_right_ir_optical_frame"/>
  <!-- camera color joints and links -->
  <joint name="camera_front_left_color_joint" type="fixed">
    <origin rpy="0 0 0" xyz="0 0.015 0"/>
    <parent link="camera_front_left_depth_frame"/>
    <child link="camera_front_left_color_frame"/>
  </joint>
  <link name="camera_front_left_color_frame"/>
  <joint name="camera_front_left_color_optical_joint" type="fixed">
    <origin rpy="-1.5707963267948966 0 -1.5707963267948966" xyz="0 0 0"/>
    <parent link="camera_front_left_color_frame"/>
    <child link="camera_front_left_color_optical_frame"/>
  </joint>
  <link name="camera_front_left_color_optical_frame"/>
  <link name="camera_front_left_imu_optical_frame"/>
  <joint name="camera_front_left_imu_optical_joint" type="fixed">
    <origin rpy="-1.5707963267948966 0 -1.5707963267948966" xyz="0 0 0"/>
    <parent link="camera_front_left_depth_frame"/>
    <child link="camera_front_left_imu_optical_frame"/>
  </joint>
  <material name="camera_back_aluminum">
    <color rgba="0.5 0.5 0.5 1"/>
  </material>
  <!-- camera body, with origin at bottom screw mount -->
  <joint name="camera_back_joint" type="fixed">
    <origin rpy="0 1.3089969389957472 0" xyz="0 0.06725 0"/>
    <parent link="hip_aa_frame_right_side"/>
    <child link="camera_back_bottom_screw_frame"/>
  </joint>
  <link name="camera_back_bottom_screw_frame"/>
  <joint name="camera_back_link_joint" type="fixed">
    <origin rpy="0 0 0" xyz="0 0.0175 0.0125"/>
    <parent link="camera_back_bottom_screw_frame"/>
    <child link="camera_back_link"/>
  </joint>
  <link name="camera_back_link">
    <visual>
      <origin rpy="1.5707963267948966 0 1.5707963267948966" xyz="0.0149 -0.0175 0"/>
      <geometry>
        <!-- <box size="${d435_cam_width} ${d435_cam_height} ${d435_cam_depth}"/> -->
        <mesh filename="package://march_description/urdf/camera/_d435.dae"/>
      </geometry>
      <material name="camera_back_aluminum"/>
    </visual>
    <collision>
      <origin rpy="0 0 0" xyz="0 -0.0175 0"/>
      <geometry>
        <box size="0.02505 0.09 0.025"/>
      </geometry>
    </collision>
    <inertial>
      <!-- The following are not reliable values, and should not be used for modeling -->
      <mass value="0.564"/>
      <origin xyz="0 0 0"/>
      <inertia ixx="0.003881243" ixy="0.0" ixz="0.0" iyy="0.000498940" iyz="0.0" izz="0.003879257"/>
    </inertial>
  </link>
  <!-- camera depth joints and links -->
  <joint name="camera_back_depth_joint" type="fixed">
    <origin rpy="0 0 0" xyz="0 0 0"/>
    <parent link="camera_back_link"/>
    <child link="camera_back_depth_frame"/>
  </joint>
  <link name="camera_back_depth_frame"/>
  <joint name="camera_back_depth_optical_joint" type="fixed">
    <origin rpy="-1.5707963267948966 0 -1.5707963267948966" xyz="0 0 0"/>
    <parent link="camera_back_depth_frame"/>
    <child link="camera_back_depth_optical_frame"/>
  </joint>
  <link name="camera_back_depth_optical_frame"/>
  <!-- camera left IR joints and links -->
  <joint name="camera_back_left_ir_joint" type="fixed">
    <origin rpy="0 0 0" xyz="0 0.0 0"/>
    <parent link="camera_back_depth_frame"/>
    <child link="camera_back_left_ir_frame"/>
  </joint>
  <link name="camera_back_left_ir_frame"/>
  <joint name="camera_back_left_ir_optical_joint" type="fixed">
    <origin rpy="-1.5707963267948966 0 -1.5707963267948966" xyz="0 0 0"/>
    <parent link="camera_back_left_ir_frame"/>
    <child link="camera_back_left_ir_optical_frame"/>
  </joint>
  <link name="camera_back_left_ir_optical_frame"/>
  <!-- camera right IR joints and links -->
  <joint name="camera_back_right_ir_joint" type="fixed">
    <origin rpy="0 0 0" xyz="0 -0.05 0"/>
    <parent link="camera_back_depth_frame"/>
    <child link="camera_back_right_ir_frame"/>
  </joint>
  <link name="camera_back_right_ir_frame"/>
  <joint name="camera_back_right_ir_optical_joint" type="fixed">
    <origin rpy="-1.5707963267948966 0 -1.5707963267948966" xyz="0 0 0"/>
    <parent link="camera_back_right_ir_frame"/>
    <child link="camera_back_right_ir_optical_frame"/>
  </joint>
  <link name="camera_back_right_ir_optical_frame"/>
  <!-- camera color joints and links -->
  <joint name="camera_back_color_joint" type="fixed">
    <origin rpy="0 0 0" xyz="0 0.015 0"/>
    <parent link="camera_back_depth_frame"/>
    <child link="camera_back_color_frame"/>
  </joint>
  <link name="camera_back_color_frame"/>
  <joint name="camera_back_color_optical_joint" type="fixed">
    <origin rpy="-1.5707963267948966 0 -1.5707963267948966" xyz="0 0 0"/>
    <parent link="camera_back_color_frame"/>
    <child link="camera_back_color_optical_frame"/>
  </joint>
  <link name="camera_back_color_optical_frame"/>
  <link name="camera_back_imu_optical_frame"/>
  <joint name="camera_back_imu_optical_joint" type="fixed">
    <origin rpy="-1.5707963267948966 0 -1.5707963267948966" xyz="0 0 0"/>
    <parent link="camera_back_depth_frame"/>
    <child link="camera_back_imu_optical_frame"/>
  </joint>
</robot>
