
<mujoco model="exoskeleton">
  <compiler meshdir="meshes" angle="degree" autolimits="true"/>
  <size nuser_actuator='1' nuser_sensor='1' nuser_geom='1'/>
  <option timestep='0.0005' iterations='50' solver='PGS' gravity='0 0 -9.81'/>
  <!-- Degree of Freedom: 27
       Actuators: 21
  -->
  <!-- Timestep is set to X because the high level control runs at X kHz -->

  <asset>
    <texture type="skybox" builtin="gradient" rgb1=".3 .5 .7" rgb2="0 0 0" width="512" height="512"/>
    <texture name="body" type="cube" builtin="flat" mark="cross" width="127" height="1278"
             rgb1="0.8 0.6 0.4" rgb2="0.8 0.6 0.4" markrgb="1 1 1" random="0.01"/>
    <texture name="grid" type="2d" builtin="checker" width="512" height="512" rgb1=".1 .2 .3" rgb2=".2 .3 .4"/>
    <material name="grid" texture="grid" texrepeat="1 1" texuniform="true" reflectance=".2"/>
    <material name="mujoco_orange" texture="body" texuniform="true" rgba="0.8 0.6 .4 1"/>
    <material name="march_grey" rgba=".87 .89 .91 1"/>
    <mesh name="backpack"    file="m8/Backpack.obj"/>
    <mesh name="L_foot"      file="m8/FootLeft.obj"/>
    <mesh name="L_hip"       file="m8/HipLeft.obj"/>
    <mesh name="L_thigh"     file="m8/UpperLegLeft.obj"/>
    <mesh name="L_shin"      file="m8/LowerLegLeft.obj"/>
    <mesh name="R_foot"     scale="1 -1 1"    file="m8/FootLeft.obj"/>
    <mesh name="R_hip"      scale="1 -1 1"    file="m8/HipLeft.obj"/>
    <mesh name="R_thigh"    scale="1 -1 1"    file="m8/UpperLegLeft.obj"/>
    <mesh name="R_shin"     scale="1 -1 1"    file="m8/LowerLegLeft.obj"/>
  </asset>

  <default>
    <site group="5"/>
    <motor ctrlrange="-1 1" ctrllimited="true"/>
    <geom contype="0" conaffinity="0" condim="1" solref="0.005 1"/>
    <equality solref="0.005 1"/>
    <default class="exoskeleton">
      <geom material="march_grey" group="2"/>
    </default>
    <default class="collision">
      <geom contype="1" group="3" type="capsule"/>
      <default class="L_collision">
        <geom contype="2" conaffinity="4"/>
      </default>
      <default class="R_collision">
        <geom contype="4" conaffinity="2"/>
      </default>
    </default>
    <default class="ballast">
      <geom contype="0" material="mujoco_orange" conaffinity="0" group="2" type="capsule" density="985"/>
    </default>
    <default class="HAA_joint">
      <joint damping="${joints/HAA/max_torque / ./max_angvel}"
             frictionloss="${joints/HAA/frictionloss}" stiffness="0"/>
    </default>
    <default class="ADPF_joint">
      <joint damping="${joints/ADPF/max_torque / ./max_angvel}"
             frictionloss="${joints/ADPF/frictionloss}" stiffness="0"/>
    </default>
    <default class="rotational_joint">
      <joint damping="${joints/HFE/max_torque / ./max_angvel}"
             frictionloss="${joints/HFE/frictionloss}" stiffness="0"/>
    </default>
  </default>

  <visual>
    <map force="0.1" zfar="30"/>
    <rgba haze="0.15 0.25 0.35 1"/>
    <quality shadowsize="4096"/>
    <global offwidth="800" offheight="800"/>
  </visual>

  <worldbody>
    <geom name="floor" size="0 0 .05" type="plane" material="grid" conaffinity="15" condim="3"/>
    <light name="spotlight" mode="targetbodycom" target="backpack"
           diffuse=".8 .8 .8" specular="0.3 0.3 0.3" pos="0 -20 4" cutoff="10"/>

    <body name="backpack"
          pos="${phys/backpack/origin/x ./y ./z}"
          childclass="exoskeleton">
      <light name="top" pos="0 0 2" mode="trackcom"/>
      <camera name="diag" pos="3 -2.5 1" xyaxes="1 1 0 0 1 2" mode="trackcom"/>
      <camera name="right" pos="0 -3 1" xyaxes="1 0 0 0 1 2" mode="trackcom"/>
      <site name='imu_backpack' size='0.01' pos="${sensors/imus/backpack/pos/x ./y ./z}"/>
      <inertial pos="${phys/backpack/com/x ./y ./z}" mass="${phys/backpack/mass}"
                fullinertia="${phys/backpack/inertia/xx ./yy ./zz ./xy ./xz ./yz}"/>
      <freejoint/>
      <geom type="mesh" mesh="backpack" />
      <geom name="backpack" type="box"
            size="${phys/backpack/geom/size/x ./y ./z}"
            pos="${phys/backpack/geom/pos/x ./y ./z}" class="collision"/>
      <geom name="pilot_torso" fromto=".147 0 .056 .190 0 .500" size=".161" class="ballast"/>
        <site name="imu_torso" size='0.01' pos="${sensors/imus/torso/pos/x ./y ./z}"/>

      <!--  LEFT LEG -->
      <body name="L_hip" pos="${phys/L_hip/origin/x ./y ./z}">
        <inertial pos="${phys/L_hip/com/x ./y ./z}" mass="${phys/L_hip/mass}"
                  fullinertia="${phys/L_hip/inertia/xx ./yy ./zz ./xy ./xz ./yz}"/>
        <joint name="L_HAA" axis="-1 0 0" range="${joints/HAA/limits/min ./max}" class="HAA_joint"/>
        <geom type="mesh" mesh="L_hip" />
        <geom name="L_hip" fromto="0 0 0 ${phys/L_UL/origin/x ./y ./z}"
              size="${phys/L_hip/geom/size}" class="L_collision"/>
        <site name="tor_L_HAA" size="0.01" pos="0 0 0"/>

        <body name="L_UL" pos="${phys/L_UL/origin/x ./y ./z}">
        <inertial pos="${phys/L_UL/com/x ./y ./z}" mass="${phys/L_UL/mass}"
                  fullinertia="${phys/L_UL/inertia/xx ./yy ./zz ./xy ./xz ./yz}"/>
          <joint name="L_HFE" axis="0 -1 0" range="${joints/HFE/limits/min ./max}" class="rotational_joint"/>
          <geom type="mesh" mesh="L_thigh" pos="0 .013 0" />
          <geom name="L_UL" fromto="0 0 0 ${phys/L_LL/origin/x ./y ./z}"
              size="${phys/L_UL/geom/size}" class="L_collision"/>
          <geom name="L_pilot_thigh" fromto="0 -.166 -.05 0 -.149 -.423" size=".069" class="ballast"/>
          <site name="tor_L_HFE" size="0.01" pos="0 0 0"/>

          <body name="L_LL" pos="${phys/L_LL/origin/x ./y ./z}">
            <inertial pos="${phys/L_LL/com/x ./y ./z}" mass="${phys/L_LL/mass}"
                  fullinertia="${phys/L_LL/inertia/xx ./yy ./zz ./xy ./xz ./yz}"/>
            <joint name="L_KFE" axis="0 1 0" range="${joints/KFE/limits/min ./max}" class="rotational_joint"/>
            <geom type="mesh" mesh="L_shin"/>
            <geom name="L_LL" fromto="0 0 0 ${phys/L_foot/origin/x ./y ./z}"
              size="${phys/L_LL/geom/size}" class="L_collision"/>
            <geom name="L_pilot_shin" fromto="0 -.116 0 0 -.124 -.399"  size=".047" class="ballast"/>
            <site name="tor_L_KFE" size="0.01" pos="0 0 0"/>

            <body name="L_foot" pos="${phys/L_foot/origin/x ./y ./z}">
              <inertial pos="${phys/L_foot/com/x ./y ./z}" mass="${phys/L_foot/mass}"
                  fullinertia="${phys/L_foot/inertia/xx ./yy ./zz ./xy ./xz ./yz}"/>
              <joint name="L_ADPF" axis="0 -1 0" range="${joints/ADPF/limits/min ./max}" class="ADPF_joint"/>
              <geom type="mesh" mesh="L_foot"/>
              <site name="tor_L_ADPF" size="0.01" pos="0 0 0"/>

              <!-- The L_foot geometry models a footplate which extends past the pressure pads on the soles-->
              <geom name="L_foot" type="box" size="${phys/L_foot/geom/size/x ./y ./z}"
                  pos="${phys/L_foot/geom/pos/x ./y ./z}"  class="L_collision"
                  friction="${phys/L_foot/friction}"/>

              <!-- Pressure sole  -->
             <body name="pres_L_0" pos="${phys/L_foot/pads/L_0/pos/x ./y phys/L_foot/pads/global/z}">
                <geom name="pres_L_0" type="sphere" pos="0 0 0"
                      size="${phys/L_foot/pads/global/size}" class="L_collision"  friction="${phys/L_foot/friction}"/>
                <site name="pres_L_0"/>
              </body>
              <body name="pres_L_1" pos="${phys/L_foot/pads/L_1/pos/x ./y phys/L_foot/pads/global/z}">
                <geom name="pres_L_1" type="sphere" pos="0 0 0"
                      size="${phys/L_foot/pads/global/size}" class="L_collision"  friction="${phys/L_foot/friction}"/>
                <site name="pres_L_1"/>
              </body>
              <body name="pres_L_2" pos="${phys/L_foot/pads/L_2/pos/x ./y phys/L_foot/pads/global/z}">
                <geom name="pres_L_2" type="sphere" pos="0 0 0"
                      size="${phys/L_foot/pads/global/size}" class="L_collision"  friction="${phys/L_foot/friction}"/>
                <site name="pres_L_2"/>
              </body>
              <body name="pres_L_3" pos="${phys/L_foot/pads/L_3/pos/x ./y phys/L_foot/pads/global/z}">
                <geom name="pres_L_3" type="sphere" pos="0 0 0"
                      size="${phys/L_foot/pads/global/size}" class="L_collision"  friction="${phys/L_foot/friction}"/>
                <site name="pres_L_3"/>
              </body>
              <body name="pres_L_4" pos="${phys/L_foot/pads/L_4/pos/x ./y phys/L_foot/pads/global/z}">
                <geom name="pres_L_4" type="sphere" pos="0 0 0"
                      size="${phys/L_foot/pads/global/size}" class="L_collision"  friction="${phys/L_foot/friction}"/>
                <site name="pres_L_4"/>
              </body>
              <body name="pres_L_5" pos="${phys/L_foot/pads/L_5/pos/x ./y phys/L_foot/pads/global/z}">
                <geom name="pres_L_5" type="sphere" pos="0 0 0"
                      size="${phys/L_foot/pads/global/size}" class="L_collision"  friction="${phys/L_foot/friction}"/>
                <site name="pres_L_5"/>
              </body>
              <body name="pres_L_6" pos="${phys/L_foot/pads/L_6/pos/x ./y phys/L_foot/pads/global/z}">
                <geom name="pres_L_6" type="sphere" pos="0 0 0"
                      size="${phys/L_foot/pads/global/size}" class="L_collision"  friction="${phys/L_foot/friction}"/>
                <site name="pres_L_6"/>
              </body>
              <body name="pres_L_7" pos="${phys/L_foot/pads/L_7/pos/x ./y phys/L_foot/pads/global/z}">
                <geom name="pres_L_7" type="sphere" pos="0 0 0"
                      size="${phys/L_foot/pads/global/size}" class="L_collision"  friction="${phys/L_foot/friction}"/>
                <site name="pres_L_7"/>
              </body>
            </body>
          </body>
        </body>
      </body>

      <!--  RIGHT LEG -->
      <body name="R_hip" pos="${phys/L_hip/origin/x -./y ./z}">
        <inertial pos="${phys/L_hip/com/x -./y ./z}" mass="${phys/L_hip/mass}"
                  fullinertia="${phys/L_hip/inertia/xx ./yy ./zz -./xy ./xz -./yz}"/>
        <joint name="R_HAA" axis="1 0 0" range="${joints/HAA/limits/min ./max}" class="HAA_joint"/>
        <geom type="mesh" mesh="R_hip" />
        <geom name="R_hip" fromto="0 0 0 ${phys/L_UL/origin/x -./y ./z}"
              size="${phys/L_hip/geom/size}" class="R_collision"/>
        <site name="tor_R_HAA" size="0.01" pos="0 0 0"/>

        <body name="R_UL" pos="${phys/L_UL/origin/x -./y ./z}">
          <inertial pos="${phys/L_UL/com/x -./y ./z}" mass="${phys/L_UL/mass}"
                  fullinertia="${phys/L_UL/inertia/xx ./yy ./zz -./xy ./xz -./yz}"/>
          <joint name="R_HFE" axis="0 -1 0" range="${joints/HFE/limits/min ./max}" class="rotational_joint"/>
          <geom type="mesh" mesh="R_thigh"/>
          <geom name="R_UL" fromto="0 0 0 ${phys/L_LL/origin/x -./y ./z}"
              size="${phys/L_UL/geom/size}" class="R_collision"/>
          <geom name="R_pilot_thigh" fromto="0 .166 -.05 0 .149 -.423" size=".069" class="ballast"/>
          <site name="tor_R_HFE" size="0.01" pos="0 0 0"/>

          <body name="R_LL" pos="${phys/L_LL/origin/x -./y ./z}">
            <inertial pos="${phys/L_LL/com/x -./y ./z}" mass="${phys/L_LL/mass}"
                  fullinertia="${phys/L_LL/inertia/xx ./yy ./zz -./xy ./xz -./yz}"/>
            <joint name="R_KFE" axis="0 1 0" range="${joints/KFE/limits/min ./max}" class="rotational_joint"/>
            <geom type="mesh" mesh="R_shin"/>
            <geom name="R_LL" fromto="0 0 0 ${phys/L_foot/origin/x -./y ./z}"
              size="${phys/L_LL/geom/size}" class="R_collision"/>
            <geom name="R_pilot_shin" fromto="0 .116 0 0 .124 -.399"  size=".047" class="ballast"/>
            <site name="tor_R_KFE" size="0.01" pos="0 0 0"/>

            <body name="R_foot" pos="${phys/L_foot/origin/x -./y ./z}">
              <inertial pos="${phys/L_foot/com/x -./y ./z}" mass="${phys/L_foot/mass}"
                  fullinertia="${phys/L_foot/inertia/xx ./yy ./zz -./xy ./xz -./yz}"/>
              <joint name="R_ADPF" axis="0 -1 0" range="${joints/ADPF/limits/min ./max}" class="ADPF_joint"/>
              <geom type="mesh" mesh="R_foot"/>
              <site name="tor_R_ADPF" size="0.01" pos="0 0 0"/>

              <!-- The R_foot geometry models a footplate which extends past the pressure pads on the soles-->
              <geom name="R_foot" type="box" size="${phys/L_foot/geom/size/x ./y ./z}"
                  pos="${phys/L_foot/geom/pos/x -./y ./z}"  class="R_collision"
                  friction="${phys/L_foot/friction}"/>

                  <!-- Pressure sole  -->
              <body name="pres_R_0" pos="${phys/L_foot/pads/L_0/pos/x -./y phys/L_foot/pads/global/z}">
                <geom name="pres_R_0" type="sphere" pos="0 0 0"
                      size="${phys/L_foot/pads/global/size}" class="L_collision"  friction="${phys/L_foot/friction}"/>
                <site name="pres_R_0"/>
              </body>
              <body name="pres_R_1" pos="${phys/L_foot/pads/L_1/pos/x -./y phys/L_foot/pads/global/z}">
                <geom name="pres_R_1" type="sphere" pos="0 0 0"
                      size="${phys/L_foot/pads/global/size}" class="L_collision"  friction="${phys/L_foot/friction}"/>
                <site name="pres_R_1"/>
              </body>
              <body name="pres_R_2" pos="${phys/L_foot/pads/L_2/pos/x -./y phys/L_foot/pads/global/z}">
                <geom name="pres_R_2" type="sphere" pos="0 0 0"
                      size="${phys/L_foot/pads/global/size}" class="L_collision"  friction="${phys/L_foot/friction}"/>
                <site name="pres_R_2"/>
              </body>
              <body name="pres_R_3" pos="${phys/L_foot/pads/L_3/pos/x -./y phys/L_foot/pads/global/z}">
                <geom name="pres_R_3" type="sphere" pos="0 0 0"
                      size="${phys/L_foot/pads/global/size}" class="L_collision"  friction="${phys/L_foot/friction}"/>
                <site name="pres_R_3"/>
              </body>
              <body name="pres_R_4" pos="${phys/L_foot/pads/L_4/pos/x -./y phys/L_foot/pads/global/z}">
                <geom name="pres_R_4" type="sphere" pos="0 0 0"
                      size="${phys/L_foot/pads/global/size}" class="L_collision"  friction="${phys/L_foot/friction}"/>
                <site name="pres_R_4"/>
              </body>
              <body name="pres_R_5" pos="${phys/L_foot/pads/L_5/pos/x -./y phys/L_foot/pads/global/z}">
                <geom name="pres_R_5" type="sphere" pos="0 0 0"
                      size="${phys/L_foot/pads/global/size}" class="L_collision"  friction="${phys/L_foot/friction}"/>
                <site name="pres_R_5"/>
              </body>
              <body name="pres_R_6" pos="${phys/L_foot/pads/L_6/pos/x -./y phys/L_foot/pads/global/z}">
                <geom name="pres_R_6" type="sphere" pos="0 0 0"
                      size="${phys/L_foot/pads/global/size}" class="L_collision"  friction="${phys/L_foot/friction}"/>
                <site name="pres_R_6"/>
              </body>
              <body name="pres_R_7" pos="${phys/L_foot/pads/L_7/pos/x -./y phys/L_foot/pads/global/z}">
                <geom name="pres_R_7" type="sphere" pos="0 0 0"
                      size="${phys/L_foot/pads/global/size}" class="L_collision"  friction="${phys/L_foot/friction}"/>
                <site name="pres_R_7"/>
              </body>
            </body>
          </body>
        </body>
      </body>

    </body>
  </worldbody>

  <actuator>
    <!-- User parameter is the maximum no-load motor RPM -->
    <motor name="L_ADPF"    gear="${joints/ADPF/max_torque}"  joint="L_ADPF"  />
    <motor name="L_HAA"     gear="${joints/HAA/max_torque}"  joint="L_HAA"  />
    <motor name="L_HFE"     gear="${joints/HFE/max_torque}" joint="L_HFE"   />
    <motor name="L_KFE"     gear="${joints/KFE/max_torque}"  joint="L_KFE"   />
    <motor name="R_ADPF"    gear="${joints/ADPF/max_torque}"  joint="R_ADPF"  />
    <motor name="R_HAA"     gear="${joints/HAA/max_torque}"  joint="R_HAA"  />
    <motor name="R_HFE"     gear="${joints/HFE/max_torque}" joint="R_HFE"   />
    <motor name="R_KFE"     gear="${joints/KFE/max_torque}"  joint="R_KFE" />
  </actuator>

  <sensor>
    <!-- User parameter is the number of absolute encoder bits -->
    <!-- encodersoutput position; connected to the actuator -->
    <jointpos name="L_ADPF_pos_output" joint="L_ADPF" user="18" noise="000"/>
    <jointpos name="L_HAA_pos_output" joint="L_HAA" user="18" noise="000"/>
    <jointpos name="L_HFE_pos_output" joint="L_HFE" user="18" noise="000"/>
    <jointpos name="L_KFE_pos_output" joint="L_KFE" user="18" noise="000"/>
    <jointpos name="R_ADPF_output" joint="R_ADPF" user="18" noise="000"/>
    <jointpos name="R_HAA_output" joint="R_HAA" user="18" noise="000"/>
    <jointpos name="R_HFE_output" joint="R_HFE" user="18" noise="000"/>
    <jointpos name="R_KFE_output" joint="R_KFE" user="18" noise="000"/>
    <!-- encodersoutput velocity; connected to the actuator -->
    <jointvel name="L_ADPF_vel_output" joint="L_ADPF" user="18" noise="000"/>
    <jointvel name="L_HAA_vel_output" joint="L_HAA" user="18" noise="000"/>
    <jointvel name="L_HFE_vel_output" joint="L_HFE" user="18" noise="000"/>
    <jointvel name="L_KFE_vel_output" joint="L_KFE" user="18" noise="000"/>
    <jointvel name="R_ADPF_vel_output" joint="R_ADPF" user="18" noise="000"/> 
    <jointvel name="R_HAA_vel_output" joint="R_HAA" user="18" noise="000"/>
    <jointvel name="R_HFE_vel_output" joint="R_HFE" user="18" noise="000"/>
    <jointvel name="R_KFE_vel_output" joint="R_KFE" user="18" noise="000"/>
    <!-- torque sensors; connected to the actuator-->

<!--    TODO: This could also be of the type actuatorvel -->
    <torque name="L_ADPF_tor_output" site="tor_L_ADPF" user="13" noise="000"/>
    <torque name="L_HAA_tor_output" site="tor_L_HAA" user="13" noise="000"/>
    <torque name="L_HFE_tor_output" site="tor_L_HFE" user="13" noise="000"/>
    <torque name="L_KFE_tor_output" site="tor_L_KFE" user="13" noise="000"/>
    <torque name="R_ADPF_tor_output" site="tor_R_ADPF" user="13" noise="000"/>
    <torque name="R_HAA_tor_output" site="tor_R_HAA" user="13" noise="000"/>
    <torque name="R_HFE_tor_output" site="tor_R_HFE" user="13" noise="000"/>
    <torque name="R_KFE_tor_output" site="tor_R_KFE" user="13" noise="000"/>

    <!-- pressure soles not finished yet -->
    <force name="L_pressuresole_1_output" site="pres_L_0" noise="000" cutoff="000"/>
    <force name="L_pressuresole_2_output" site="pres_L_1" noise="000" cutoff="000"/>
    <force name="L_pressuresole_3_output" site="pres_L_2" noise="000" cutoff="000"/>
    <force name="L_pressuresole_4_output" site="pres_L_3" noise="000" cutoff="000"/>
    <force name="L_pressuresole_5_output" site="pres_L_4" noise="000" cutoff="000"/>
    <force name="L_pressuresole_6_output" site="pres_L_5" noise="000" cutoff="000"/>
    <force name="L_pressuresole_7_output" site="pres_L_6" noise="000" cutoff="000"/>
    <force name="L_pressuresole_8_output" site="pres_L_7" noise="000" cutoff="000"/>

    <force name="R_pressuresole_1_output" site="pres_R_0" noise="000" cutoff="000"/>
    <force name="R_pressuresole_2_output" site="pres_R_1" noise="000" cutoff="000"/>
    <force name="R_pressuresole_3_output" site="pres_R_2" noise="000" cutoff="000"/>
    <force name="R_pressuresole_4_output" site="pres_R_3" noise="000" cutoff="000"/>
    <force name="R_pressuresole_5_output" site="pres_R_4" noise="000" cutoff="000"/>
    <force name="R_pressuresole_6_output" site="pres_R_5" noise="000" cutoff="000"/>
    <force name="R_pressuresole_7_output" site="pres_R_6" noise="000" cutoff="000"/>
    <force name="R_pressuresole_8_output" site="pres_R_7" noise="000" cutoff="000"/>

    <!-- Noise & cutoff must be determined -->
    <framequat name='backpack_orientation' objtype='site' objname='imu_backpack'/>
    <gyro name='vel_imu_backpack' site='imu_backpack' noise='5e-4' cutoff='34.9'/>
    <accelerometer name='acc_imu_backpack' site='imu_backpack' noise='1e-2' cutoff='157'/>
    <magnetometer name='magnet_imu_backpack' site='imu_backpack'/>

    <framequat name='torso_orientation' objtype='site' objname='imu_torso'/>
    <gyro name='vel_imu_torso' site='imu_torso' noise='5e-4' cutoff='34.9'/>
    <accelerometer name='acc_imu_torso' site='imu_torso' noise='1e-2' cutoff='157'/>
    <magnetometer name='magnet_imu_torso' site='imu_torso'/>

  </sensor>
</mujoco>